Workbook
Name CPATStartYear: [1]Dashboard!$J$7

Sheet Settings
A1: CPAT industry kernel - Egypt, final v1.6
A3: Country code | B3: egy | C3: First component of every code; CPAT convention (egy.mit.<var>.<sector>.<fuel>.<type>.<scenario>)
A4: Price group for industry sectors | B4: ind | C4: C2 retail-price group the four sectors read (pow / res / ind / tra)
A5: Elasticity column | B5: Industries | C5: Column of the master elasticity table (Transport / Residential / Industries / Services)
A6: Base year | B6: 2022 | C6: MTInputs FirstYearCalculations; energy in the base year is read from Data_Energy, later years from the kernel
A7: Additional policy-induced efficiency (alpha+) | B7: =INDEX(MTInputs!$F$8:$F$415,MATCH("AdditionalEfficiencyIndustrial",MTInputs!$H$8:$H$415,0)) -> 0 | C7: Read from the MTInputs column by NameOfParameter; this is the only MTInputs dependency of the kernel rows
A8: Carbon price start year (info) | B8: =INDEX(MTInputs!$F$8:$F$415,MATCH("CPIntro",MTInputs!$H$8:$H$415,0)) -> 2026 | C8: For reference: the policy scenario new-policy wedge (nce) starts here
A9: Carbon price target (info) | B9: =INDEX(MTInputs!$F$8:$F$415,MATCH("CPLevelTarget",MTInputs!$H$8:$H$415,0)) -> 50 | C9: $/tCO2
A10: Policy bundle for scenario 2 (EGY) | B10: LEGACY | C10: Bundle run as policy scenario 2 (Scenarios section 2). LEGACY = CPAT default (regression vs v0.3/legacy). Check-sheet legacy comparisons are valid for LEGACY only.
A12: Kernel (every energy cell, year t >= 2023):
A13: F(t) = F(t-1) * (1+g)^(eY*delta) * (1+psi) * (p(t)/p(t-1))^eU * [ (s(t)/s(t-1))^eF / (1 + a + a+) ]^(1+eU)
A14: p = post-tax price (atp), s = shadow price (shp) = atp + sigma*ssc, g = post-policy GDP growth, delta = income-elasticity discount, psi = exogenous shock
A16: Sheets
A17: Manual inputs | C17: Legacy 'Manual inputs' Process Emissions section (rows 18-47, same positions): CBAM process coverage switches, product emission factors, half-elasticities.
A18: Scenarios | C18: EGY: carbon price paths, policy bundles 1A-3C (+LEGACY), active-bundle series mirrored into Data_Prices by code, pass-through factors, interface contract between work streams.
A19: Mitigation_Industry | C19: Kernel sheet in the CPAT Mitigation layout (columns A-AI, years K-AI): 4 CBAM sectors x 2 scenarios, each scenario followed by the 156-row CBAM goods block (legacy Mitigation 5881-6036 / 12198-12353). All formulas; codes built from components.
A20: MTInputs | C20: The 415-row CPAT parameter column, copied unchanged (columns A-I of the MTInputs sheet).
A21: Data_Energy | C21: Base-year energy matrix, fuel x sector, ktoe (Mitigation B4 rows 583-602).
A22: Data_Prices | C22: Pre-tax price before new policies (pbc), new-policy wedge (nce), shadow price (shp), sector coverage (tcf), share of shadow price on efficiency (ssc); both scenarios. Plus carbon price (cptraj) and auctioned ETS price (etstraj) trajectories for the CBAM block. v0.4: scenario-2 cptraj/etstraj/nce read Scenarios; interface rows pptraj, encov, obrsh, obrrb, fundsh, fundsp.
A23: Data_Macro | C23: GDP growth, income-elasticity discount factor, exogenous shock; both scenarios.
A24: Data_Elast | C24: Master elasticity table (income, usage, efficiency, AEEI) by fuel group x sector group, plus the fuel-group map.
A25: Check | C25: Kernel output against the values stored in CPAT_1_0pre_456 for the same rows; max absolute and relative differences. v0.3: plus CBAM block rows vs legacy (rows from 583). v0.4: plus Scenarios regression section. v0.5: Task A identity section (row 1429). v0.6: Task B section (row 1443). v0.7: Task C section (row 1455). v0.8: Task K section (row 1464). v0.9: Task D section (row 1476). v0.10: Task H section (row 1489). v0.11: Task L section (row 1506). v0.12 (Stream 2 merged): Task F section (row 1520), Task I section (row 1552), Task J section (row 1667). v0.13: Task G section (row 1831). v0.14: Task M section (row 1861). v0.15: T1/T5 section (row 1881). v0.16: v0.16 section (row 1907). v0.17: carve-out section (row 1919).
A27: Version log
A28: v0.1 | C28: Initial kernel (egypt+mitigation).
A29: v0.2 | C29: Conformed to NORMS.md: MTInputs used/unused colouring, hidden MT/Dashboard placeholder columns, CPAT colours, title band. No formula changes.
A30: v0.3 | C30: TASK-1: CBAM goods / process emissions block (legacy Mitigation 12198-12353, 156 rows, cols A-AI) added after each scenario; 'Manual inputs' rows 18-47; cptraj/etstraj in Data_Prices; MTInputs F117:F121 linked to Manual inputs row 22. Carbon Tax/ETS rows now read the scenario trajectories (legacy: hard zeros, broken K refs). Legacy WIP bugs fixed: fuel emissions by sector M..AE hard-coded; aluminium fuel-ER relative ref; missing post-policy process total; product-price year header. Kernel rows unchanged (regression diff 0).
A31: v0.4 | B31: 2026-10-02 | C31: Task E: Scenarios sheet (price paths LEGACY/ZERO/FLAT20_2028/RAMP_EG3/RAMP50_2034; bundles LEGACY,1A,2A,2B,3A,3B,3C; selector Settings!B10). Scenario-2 cptraj/etstraj/nce now = active-bundle series (nce = cptraj x encov x factor). New interface rows pptraj/encov/obrsh/obrrb/fundsh/fundsp (both scenarios). CBAM block o4 = fundsp, o5 = fundsh x o155, o6 = obrrb; Additional ER rows o107-o114 read o4 instead of o5. Manual inputs E21 = bundle process flag. LEGACY: regression diff vs v0.3 ~1e-15 (floating point of cptraj x factor).
A32: v0.5 | B32: 2026-10-02 | C32: Task A: CBAM block output codes unique (cpef/cpep, emisf/emisp, emrf/emrp; combined emis/emr in spare rows o135/o136). Revenues fixed: o147-o154 = post-policy fuel CO2 x fuel inclusion + post-policy process x process inclusion (legacy: pre-policy process x fuel inclusion, no fuel revenue); split revf/revp in o137/o138, o155 = sum. Changed by design: scenario-2 revenue rows (LEGACY o155 2030: 1697.5 -> fuel only, process not covered); all other values identical to v0.4.
A33: v0.6 | B33: 2026-10-02 | C33: Task B: 4-way EF split (fc, fp, np, no) with coverage switches per bundle (Scenarios M:P, all 1; block o28). Price rows use covered EFs (fuel group fc+fp, process group np+no); process ER and revenues act on the covered share (o85-o92 I:J). Full process EF floored per category. Post-policy emissions by category in o13-o16 (emisfc/emisfp/emisnp/emisno.cbam.tot). All values identical to v0.5 with switches = 1.
A34: v0.7 | B34: 2026-10-02 | C34: Task C: CBAM process emissions (np + no) priced at pptraj (new block row o63) in the process price rows, process ER, revp, product revenues and np/no emissions; fuel CO2 stays on cptraj (o2). All values identical to v0.6 (every bundle uses the same energy and process path).
A35: v0.8 | B35: 2026-10-02 | C35: Task K: CBAM metrics in block spare rows: cbcov (o39), cbint (o40), cbintch (o41), EU-export-weighted cbintchx (o51) and cbcovx (o52). New rows only; no existing value changes.
A36: v0.9 | B36: 2026-10-02 | C36: Task D: IPCC-inferred process semi-elasticities by product and category (np, no) with technical potential ERmax (Manual inputs rows 53-60); block o118-o125 apply them per category. Selector Manual inputs E50 (IPCC default; ADHOC reproduces v0.8). Anchors are placeholders equal to the ad hoc values (results unchanged) pending the IPCC research report.
A37: v0.10 | B37: 2026-10-02 | C37: Task H: CBAM output responds to the carbon cost net of the output-based rebate, Q = Qbase x (1 + dp_net)^eps (Manual inputs rows 66-73, switch E63; eps placeholder -0.5). New codes cbqch, emrq, emrt; block o75-o82 redefined as the net cost increase. OFF (and the LEGACY bundle) reproduces v0.9.
A38: v0.11 | B38: 2026-10-02 | C38: Task L: CBAM obligations on EU exports (cbobl, cbobl0, cbobch, cbobchu in block o94/o105/o116/o127) with EU price (placeholder 100), CBAM phase-in factor and deduction convention (Manual inputs rows 75-82, selector E76 = FULL).
A39: v0.12 | B39: 2026-10-02 | C39: T2 merge: Stream 2 (branch v0.7 -> Stream2_v1/v2/v3) integrated into the mainline v0.11 by re-applying the branch steps (build_v0_12.py imports build_stream2_v1/v2/v3). Task F: new sheets Data_EF, Emissions_Industry (eco2 = ener x EF), MTInputs EmissionsFactCO2 / EFsAdjustmentNonAnnexI green; check (d) now conditions on the explicit price o2 + o3 (branch used o1, a cascade to the year row). Task I: new sheet Rebate_Industry (Fund-independent output-based rebate per t = MIN(obrrb x EU benchmark, carbon cost per t), sector rebate share, net prices atpn); kernel ener usage term reads atpn (1368 cells, asserted); ppin memo since Task H (v0.10) already deducts obrrb in the output response (basis covered EF; Task I basis EU benchmark -> CAVEATS). Task J: new sheet Fund_Industry (F = phi x pre-fund revenue rev0, shadow price s by 15 Newton rows, RATE|COST rule); process abatement rebuilt for the v0.9 per-category ERmax form (wm = Q x cov x EF x ERmax, wp = wm x e^-beta P, 16 rows np/no); block o5 = F, '+o4' inside the process price term of o118-o125 (np and no) and o15/o16 (440 block cells, asserted against v0.11); Data_Prices shp.<fuel>.ind.2 = s x pass-through, ssc.<sector>.2 = ssc_fund (260 cells); Scenarios fundsp row 49 = s. Check sections F (row 1520), I (row 1552), J (row 1667) store the pre-step values per bundle computed inside this build. Regression vs v0.11: all Check summaries 0 for every bundle; Mitigation_Industry identical to v0.11 for LEGACY, 1A, 2A, 2B, 3A (max |diff| 0); changed by design: 3B 873; 3C 1.9e+03. Sheets list above not extended (keeps row 25 fixed).
A40: v0.13 | B40: 2026-10-02 | C40: Task G: new sheet IPPU_Industry. CPAT IPPU baseline by gas and industrial energy CO2 stored (CPAT Mitigation rows 7566-7570, 6590); CPAT-method IPPU (all IPPU x industrial energy CO2 growth, kernel change only) vs kernel IPPU = block process np+no (o145) + fp counted as IPPU (ammonia feedstock flag) + non-block remainder (CPAT baseline - block baseline; IppuOther NONE holds it, CPAT scales it). Double-count correction row iprdc. Reconciliation of block fuel CO2 with Task F sector energy CO2 by sector (report only). Manual inputs rows 84-95 (switch E85, fp flags E88:E95). Check section row 1831. 2030, bundle 3A scenario 2: CPAT-method IPPU 85.3, kernel IPPU 84.7 MtCO2e (block 34.0, non-block 50.7), correction -0.52. Regression vs v0.12: all prior sheets identical for every bundle (max |diff| 0); new rows only.
A41: v0.14 | B41: 2026-10-02 | C41: Task M: new sheets CPAT_National (CPAT national outputs of runs EG1-EG4 from the TASK-2b csv, stored) and Table2_Industry (bundle -> run mapping; CPAT series of the mapped run; kernel series; Table 2 columns J K L M N O P Q R T U AR per year; live summary row + stored 2030 snapshot of all bundles vs rebuild v0.1 K). Composition in deltas: K = dGHG CPAT + IPPU replacement (Task G kernel IPPU) + industry energy replacement (kernel sectors + non-kernel industry scaled with the run for All sectors). P = gross (CPAT receipts adjusted / kernel sectors) + process revenue - rebates - fund. Q = CPAT deaths x dEnergy CO2 ratio. Check section row 1861. 2030 K: 1A -27.7, 2A -25.7, 2B -27.0, 3A -9.7, 3B -6.6, 3C -17.3. Regression vs v0.13: all prior sheets identical for every bundle (max |diff| 0); new sheets only.
A42: v0.15 | B42: 2026-10-02 | C42: T5: S1 emission factors H30:K37 = Egypt CBAM EF v0.1 (EGY_CBAM_EF_v0.1.xlsx; urea np 0 CBAM rule, M35 1.1256; AN no 0.9944 integrated HNO3 N2O, M36 0.8462); S:V memo restated. T1: Task D semi-elasticities applied (E50 IPCC; rows 53-60 ER at $100 = IPCC AR6 central, USD2019: DRI 0.3433, scrap 0.1810, BF 0.2803, clinker 0.3352, AN no 0.6179 (50 % abatement blend), Al 0.2164 np+no, ammonia/urea 0). Fuel ER (rows 40-47) and fund unchanged. Table 2 snapshot refilled; rebuild column = AdHoc rebuild v0.2. Check row 1881. 2030 K: 1A -29.8 (v0.14 -27.7), 2A -25.8 (v0.14 -25.7), 2B -27.1 (v0.14 -27.0), 3A -11.8 (v0.14 -9.7), 3B -8.6 (v0.14 -6.6), 3C -23.9 (v0.14 -17.3).
... A44: v0.17 | B44: 2026-10-02 | C44: Final Table 2: sheet CarveOut_Table2 = CBAM carve-out v0.3 in live formulas (active bundle) + stored 6-bundle snapshot; O on FULL, NOPHASE memo. No other formulas changed. Check row 1919. 2030 K: 1A -37.4, 2A -33.1, 2B -34.8, 3A -22.8, 3B -19.1, 3C -33.0.
A45: v1.0 | B45: 46299 | C45: Final release: v0.17 relabelled, no formula or value changes. Final Table 2 = sheet CarveOut_Table2 (CBAM carve-out). 2030 K: 1A -37.4, 2A -33.1, 2B -34.8, 3A -22.8, 3B -19.1, 3C -33.0.
...

Sheet Manual inputs
B1: CPAT Manual inputs
B2: Replicates the legacy 'Manual inputs' tab at the same row/column positions. Only the Process Emissions section (rows 18-47, used by the CBAM block) is ported; other rows are left blank so legacy references port 1:1.
B3: Change only green cells. Row 22 feeds MTInputs F117:F121 (as in legacy).
A18: . | B18: Process Emissions
B19: Non-Fuel Process Emissions Coverage (CBAM goods only) for ETS and Carbon Tax
H20: mining & chemicals | I20: iron and steel | J20: non-ferrous metals | K20: machinery | L20: cement
D21: Include non-fuel process emissions in ETS/CT? (legacy Dashboard!G20; v0.4: set by the active bundle, Scenarios) | E21: =Scenarios!$G$27=1 -> FALSE | H21: TRUE | I21: TRUE | J21: TRUE | L21: TRUE
H22: =AND($E$21,'Manual inputs'!H21) -> FALSE | I22: =AND($E$21,'Manual inputs'!I21) -> FALSE | J22: =AND($E$21,'Manual inputs'!J21) -> FALSE | K22: FALSE | L22: =AND($E$21,'Manual inputs'!L21) -> FALSE
S27: S:V memo (v0.15): implied GJ/t = S1 EF x 1000 / tCO2 per TJ (not read by formulas).
B28: Emission Factors | H28: SCOPE 1 (tCO₂e/t, NH₃ integrated) | O28: SCOPE 2 + TOTALS | S28: EF INPUTS | W28: LATEST MAY 2026 EU DEFAULTS + BENCHMARKS | AD28: CONFIDENCE
D29: Product | E29: Unit | F29: CN codes | G29: Route | H29: S1.fc | I29: S1.fp | J29: S1.np | K29: S1.no | L29: S1 own | M29: Embed NH₃ | N29: S1 incl NH₃ | O29: S2 | P29: S2 in CBAM scope? | Q29: S1+S2 total | R29: CBAM- equiv | S29: fc GJ/t | T29: fc EF | U29: fp GJ/t | V29: fp EF | W29: EU def base | X29: mark up | Y29: EU def 2026 | Z29: EU bench | AA29: Gap vs def | AB29: Gap vs bench | AC29: Latest EU regulatory note (May 2026) | AD29: S1.fc / S1.fp confidence | AE29: S1.np / S1.no confidence
D30: DRI-EAF steel | E30: t crude steel | F30: 7207 10 (D); 7207 12 (D); 7208/7209 flat (partial); 7214 rebar | G30: Midrex NG shaft furnace + EAF | H30: 0.17797725 | I30: 0.39301352 | J30: 0.03790102 | K30: 0 | L30: =SUM(H30:K30) -> 0.60889179 | M30: 0 | N30: =L30+M30 -> 0.60889179 | O30: 0.25 | P30: 0 | Q30: =N30+O30 -> 0.85889179 | R30: =N30+O30*P30 -> 0.60889179 | S30: 3.172 | T30: 56.1 | U30: 7.006 | V30: 56.1 | W30: 1.82 | X30: 0.1 | Y30: =W30*(1+X30) -> 2.002 | Z30: 0.481 | AA30: =R30-Y30 -> -1.3931082 | AB30: =R30-Z30 -> 0.12789179 | AC30: DRI-EAF. Default base 1.820 ×1.10 markup = 2.002 (2026). Benchmark 0.481 (final IR 2025/2620). CAUTION: CBAM default matrix for HRC CN 7208 may assign only BF-BOF route (4.454) — 'DRI default vacancy' risk for flat products. | AD30: v0.15 EF: Egypt CBAM EF v0.1 (egypt+mitigation/EmissionFactors/EGY_CBAM_EF_v0.1.xlsx Products; EGY_CBAM_EF_Methodology_v0.1.md). Prior: S1.fc: Est: Midrex heat:reductant ratio 5:24 GJ/t NG. Total EF Auth (WSA 2023 / S1.fp: Est: Midrex standard ratio; IPCC 2006 Vol2 2C1; WSA 2023. Total Auth; | AE30: v0.15 EF: Egypt CBAM EF v0.1 (egypt+mitigation/EmissionFactors/EGY_CBAM_EF_v0.1.xlsx Products; EGY_CBAM_EF_Methodology_v0.1.md). Prior: S1.np: Auth: IPCC 2006 2C1 — DRI process CO2 = 0 / S1.no: Auth: IPCC 2006 2C1
D31: Scrap-EAF steel | E31: t crude steel | F31: 7206 10; 7207 10 (E); 7214 rebar; 7208 HRC (E-route); 7216 sections | G31: Scrap-EAF | H31: 0.04488 | I31: 0 | J31: 0.04398115 | K31: 0 | L31: =SUM(H31:K31) -> 0.08886115 | M31: 0 | N31: =L31+M31 -> 0.08886115 | O31: 0.25 | P31: 0 | Q31: =N31+O31 -> 0.33886115 | R31: =N31+O31*P31 -> 0.08886115 | S31: 0.8 | T31: 56.1 | U31: 0 | V31: 0 | W31: 0.72 | X31: 0.1 | Y31: =W31*(1+X31) -> 0.792 | Z31: 0.072 | AA31: =R31-Y31 -> -0.70313885 | AB31: =R31-Z31 -> 0.01686115 | AC31: Scrap-EAF. Default base 0.720 ×1.10 = 0.792 (2026). Benchmark 0.072 (final, scrap route). | AD31: v0.15 EF: Egypt CBAM EF v0.1 (egypt+mitigation/EmissionFactors/EGY_CBAM_EF_v0.1.xlsx Products; EGY_CBAM_EF_Methodology_v0.1.md). Prior: S1.fc: Est: IEA Egypt sector average; WSA 2023 scrap-EAF range 2-3 GJ/t. Tota / S1.fp: Auth: no reductant in scrap melting process | AE31: v0.15 EF: Egypt CBAM EF v0.1 (egypt+mitigation/EmissionFactors/EGY_CBAM_EF_v0.1.xlsx Products; EGY_CBAM_EF_Methodology_v0.1.md). Prior: S1.np: Est: IPCC 2006 Vol2 2C1 default 0.01-0.02 tCO2/t for scrap-EAF / S1.no: Auth: IPCC 2006 2C1
D32: BF-BOF steel (reference) | E32: t crude steel | F32: 7206 10 (C); 7207 10 (C); 7209 CR (C-route); 7208 HRC (C-route) | G32: BF-BOF coal/coke | H32: 0.1683 | I32: 1.2566803 | J32: 0.05276542 | K32: 0 | L32: =SUM(H32:K32) -> 1.4777457 | M32: 0 | N32: =L32+M32 -> 1.4777457 | O32: 0.1875 | P32: 0 | Q32: =N32+O32 -> 1.6652457 | R32: =N32+O32*P32 -> 1.4777457 | S32: 1.751 | T32: 96.1 | U32: 13.077 | V32: 96.1 | W32: 2.8 | X32: 0.1 | Y32: =W32*(1+X32) -> 3.08 | Z32: 1.37 | AA32: =R32-Y32 -> -1.6022543 | AB32: =R32-Z32 -> 0.10774569 | AC32: BF-BOF reference. Default base 2.800 ×1.10 = 3.080 (2026). Benchmark 1.370 (final IR 2025/2620). | AD32: v0.15 EF: Egypt CBAM EF v0.1 (egypt+mitigation/EmissionFactors/EGY_CBAM_EF_v0.1.xlsx Products; EGY_CBAM_EF_Methodology_v0.1.md). Prior: S1.fc: Prox: WSA 2023 global BF-BOF average. No Egypt-specific data (no produ / S1.fp: Prox: WSA 2023 BF standard; IPCC 2006 Vol2 2C1. Split Est within proxy | AE32: v0.15 EF: Egypt CBAM EF v0.1 (egypt+mitigation/EmissionFactors/EGY_CBAM_EF_v0.1.xlsx Products; EGY_CBAM_EF_Methodology_v0.1.md). Prior: S1.np: Auth: IPCC 2006 Vol2 2C1 default 0.22-0.28 tCO2/t crude steel / S1.no: Auth: IPCC 2006 2C1
D33: Grey clinker (dry-process) | E33: t clinker | F33: 2523 10 (clinker); 2523 21; 2523 29 Portland cement | G33: Dry rotary kiln | H33: 0.3135685 | I33: 0 | J33: 0.53702616 | K33: 0 | L33: =SUM(H33:K33) -> 0.85059466 | M33: 0 | N33: =L33+M33 -> 0.85059466 | O33: 0.05625 | P33: 1 | Q33: =N33+O33 -> 0.90684466 | R33: =N33+O33*P33 -> 0.90684466 | S33: 3.263 | T33: 96.1 | U33: 0 | V33: 0 | W33: 1.58 | X33: 0.1 | Y33: =W33*(1+X33) -> 1.738 | Z33: 0.666 | AA33: =R33-Y33 -> -0.83115534 | AB33: =R33-Z33 -> 0.24084466 | AC33: Cement clinker. Default base 1.580 ×1.10 = 1.738 (2026). Benchmark 0.666 (col B). S2 IN CBAM scope. | AD33: v0.15 EF: Egypt CBAM EF v0.1 (egypt+mitigation/EmissionFactors/EGY_CBAM_EF_v0.1.xlsx Products; EGY_CBAM_EF_Methodology_v0.1.md). Prior: S1.fc: Est: IEA Egypt cement sector; CSI/GCCA GNR Egypt 2022. Total AukCoa / S1.fp: Auth: cement production has no chemical reductant fuel | AE33: v0.15 EF: Egypt CBAM EF v0.1 (egypt+mitigation/EmissionFactors/EGY_CBAM_EF_v0.1.xlsx Products; EGY_CBAM_EF_Methodology_v0.1.md). Prior: S1.np: Auth: IPCC 2006 2A1 stoichiometric constant (44/100 × fraction CaCO3 i / S1.no: Auth
D34: Ammonia (net merchant) | E34: t NH3 | F34: 2814 10 (anhydrous ammonia) | G34: Steam methane reforming (SMR) + Haber-Bosch synthesis | H34: 0.71247 | I34: 1.26225 | J34: 0 | K34: 0 | L34: =SUM(H34:K34) -> 1.97472 | M34: 0 | N34: =L34+M34 -> 1.97472 | O34: 0.0375 | P34: 1 | Q34: =N34+O34 -> 2.01222 | R34: =N34+O34*P34 -> 2.01222 | S34: 12.7 | T34: 56.1 | U34: 22.5 | V34: 56.1 | W34: 2.05 | X34: 0.01 | Y34: =W34*(1+X34) -> 2.0705 | Z34: 1.484 | AA34: =R34-Y34 -> -0.05828 | AB34: =R34-Z34 -> 0.52822 | AC34: Egypt ammonia 2026 default = 2.07 tCO2e/t (incl 1% fertiliser markup; Argus 17 Dec 2025). Benchmark 1.522 → 1.484 after 2.5% reduction in 2026. S2 IN CBAM scope. | AD34: v0.15 EF: Egypt CBAM EF v0.1 (egypt+mitigation/EmissionFactors/EGY_CBAM_EF_v0.1.xlsx Products; EGY_CBAM_EF_Methodology_v0.1.md). Prior: S1.fc: Est: IFA/EFMA BAT Vol.1; combustion ~6-8 GJ/t NH3. Total Auth (IFA sta / S1.fp: Est: IFA/EFMA BAT Vol.1 standard SMR ~24-28 GJ/t NH3. Total Auth; comb | AE34: v0.15 EF: Egypt CBAM EF v0.1 (egypt+mitigation/EmissionFactors/EGY_CBAM_EF_v0.1.xlsx Products; EGY_CBAM_EF_Methodology_v0.1.md). Prior: S1.np: Auth: NH3 synthesis has no carbon process emissions / S1.no: Auth
D35: Urea | E35: t urea | F35: 3102 10 (urea >= 45% N) | G35: Urea synthesis from captured CO2 + NH3 feedstock | H35: 0.1122 | I35: 0 | J35: 0 | K35: 0 | L35: =SUM(H35:K35) -> 0.1122 | M35: 1.1255904 | N35: =L35+M35 -> 1.2377904 | O35: 0.0375 | P35: 1 | Q35: =N35+O35 -> 1.2752904 | R35: =N35+O35*P35 -> 1.2752904 | S35: 2 | T35: 56.1 | U35: 0 | V35: 0 | W35: 1.39 | X35: 0.01 | Y35: =W35*(1+X35) -> 1.4039 | Z35: 0.902 | AA35: =R35-Y35 -> -0.1286096 | AB35: =R35-Z35 -> 0.3732904 | AC35: NH₃ INTEGRATED in headline. Egypt urea 2026 default = 1.404 tCO2e/t (incl 1% markup; Sandbag Feb 2026). Benchmark col B 0.902 (col A 0.053 for actual-data pathway). SEFA chain uses ammonia benchmark 1.522. S2 IN CBAM scope. | AD35: v0.15 EF: Egypt CBAM EF v0.1 (egypt+mitigation/EmissionFactors/EGY_CBAM_EF_v0.1.xlsx Products; EGY_CBAM_EF_Methodology_v0.1.md). Urea np = 0 (CBAM rule: urea-bound CO2 not deducted; prototype -0.733). Prior: S1.fc: Est: IFA/EFMA; small relative to NH3 chain. ~1.5-2.5 GJ/t urea typical / S1.fp: Auth: no additional reductant/feedstock in urea synthesis itself | AE35: v0.15 EF: Egypt CBAM EF v0.1 (egypt+mitigation/EmissionFactors/EGY_CBAM_EF_v0.1.xlsx Products; EGY_CBAM_EF_Methodology_v0.1.md). Urea np = 0 (CBAM rule: urea-bound CO2 not deducted; prototype -0.733). Prior: S1.np: Auth: IPCC 2006 Vol2 3G stoichiometric constant. 44/60 = 0.733 tCO2 ab / S1.no: Auth
D36: Ammonium nitrate | E36: t AN | F36: 3102 30 (AN >= 28% N); 3102 40 (CAN) | G36: Ostwald process (NH3 → HNO3) + neutralisation (HNO3 + NH3 → NH4NO3) | H36: 0.1122 | I36: 0 | J36: 0 | K36: 0.9944125 | L36: =SUM(H36:K36) -> 1.1066125 | M36: 0.8462122 | N36: =L36+M36 -> 1.9528247 | O36: 0.04375 | P36: 1 | Q36: =N36+O36 -> 1.9965747 | R36: =N36+O36*P36 -> 1.9965747 | S36: 2 | T36: 56.1 | U36: 0 | V36: 0 | W36: 2.64 | X36: 0.01 | Y36: =W36*(1+X36) -> 2.6664 | Z36: 0.302 | AA36: =R36-Y36 -> -0.6698253 | AB36: =R36-Z36 -> 1.6945747 | AC36: NH₃ INTEGRATED in headline. AN/CAN. Default base ~2.64 ×1.01 = 2.666 (2026, N2O-driven). Benchmark 0.302. S2 IN CBAM scope. Default value highly sensitive to assumed N2O abatement. | AD36: v0.15 EF: Egypt CBAM EF v0.1 (egypt+mitigation/EmissionFactors/EGY_CBAM_EF_v0.1.xlsx Products; EGY_CBAM_EF_Methodology_v0.1.md). AN no = integrated HNO3 N2O 0.79 x 1.2588 (kernel convention; EF workbook books it as precursor); 50 % N2O abatement assumed (VERIFY). Prior: S1.fc: Est: IFA/EFMA BAT Vol.3; 1.5-2.5 GJ/t AN typical. Total direct EF less / S1.fp: Auth: HNO3 and neutralisation have no reductant | AE36: v0.15 EF: Egypt CBAM EF v0.1 (egypt+mitigation/EmissionFactors/EGY_CBAM_EF_v0.1.xlsx Products; EGY_CBAM_EF_Methodology_v0.1.md). AN no = integrated HNO3 N2O 0.79 x 1.2588 (kernel convention; EF workbook books it as precursor); 50 % N2O abatement assumed (VERIFY). Prior: S1.np: Auth: AN chemistry (NH4NO3) contains no carbon / S1.no: Est: IPCC 2006 2B2; GWP AR6 AII.1.2. CRITICAL: range 0.21 (with high-e
D37: Primary aluminium | E37: t Al | F37: 7601 10 (unwrought primary); 7601 20 (alloys, semi-finished); 7604 (bars/rods); 7606 (sheet/plate) | G37: Hall-Héroult electrolysis + carbon anode prebaking | H37: 0.12342 | I37: 0 | J37: 1.623493 | K37: 0.774 | L37: =SUM(H37:K37) -> 2.520913 | M37: 0 | N37: =L37+M37 -> 2.520913 | O37: 6.75 | P37: 0 | Q37: =N37+O37 -> 9.270913 | R37: =N37+O37*P37 -> 2.520913 | S37: 1.582 | T37: 78 | U37: 0 | V37: 0 | W37: 2.06 | X37: 0.1 | Y37: =W37*(1+X37) -> 2.266 | Z37: 1.423 | AA37: =R37-Y37 -> 0.25491304 | AB37: =R37-Z37 -> 1.097913 | AC37: Primary aluminium. Default base 2.060 ×1.10 = 2.266 (2026). Benchmark 1.423. S2 NOT in CBAM scope (direct emissions only). | AD37: v0.15 EF: Egypt CBAM EF v0.1 (egypt+mitigation/EmissionFactors/EGY_CBAM_EF_v0.1.xlsx Products; EGY_CBAM_EF_Methodology_v0.1.md). Prior: S1.fc: Est: IAI 2023 smelter profile; 1.5-2.5 GJ/t range. Weighted EF 78 kgCO / S1.fp: Auth: Hall-Héroult is electrolytic; reduction is electrical not fuel-d | AE37: v0.15 EF: Egypt CBAM EF v0.1 (egypt+mitigation/EmissionFactors/EGY_CBAM_EF_v0.1.xlsx Products; EGY_CBAM_EF_Methodology_v0.1.md). Prior: S1.np: Auth: IPCC 2006 Vol2 2C3 default 1.5 tCO2/t Al for prebaked anodes. Ra / S1.no: Est: IAI 2023 Egypt country profile. Global prebaked average 0.38 tCO2
B38: Legacy ad hoc semi-elasticities (AdHocCalculations; one beta for np + no; no documented source). Used only when E50 = ADHOC, and by the fund placeholder (block o107-o114)
D39: Process | E39: Half Elasticity | F39: ER at $100 (%)
D40: DRI-EAF steel | E40: 0.0010536052 | F40: 0.1
D41: Scrap-EAF steel | E41: 0.00020202707 | F41: 0.02
D42: BF-BOF steel reference | E42: 0.00051293294 | F42: 0.05
D43: Grey clinker dry-process | E43: 0.00083381609 | F43: 0.08
D44: Ammonia net | E44: 0.0019845094 | F44: 0.18
D45: Urea | E45: 0 | F45: 0
D46: AN | E46: 0.010498221 | F46: 0.65
D47: Primary aluminium | E47: 0.00083381609 | F47: 0.08
B49: Process-emission semi-elasticities (Task D, v0.9): inferred from IPCC; used by CBAM block rows o118-o125
D50: Semi-elasticity set used by the block (IPCC / ADHOC) | E50: IPCC | F50: ADHOC = rows 40-47 with ERmax = 1 (reproduces v0.8)
D51: ER(P) = ERmax x (1 - exp(-beta x P)); beta = -ln(1 - ER*/ERmax)/P* from the anchor (P*, ER*); semi-elasticity at P = 0 = ERmax x beta. np = non-fuel process CO2, no = non-CO2 process (Manual inputs J, K). ERmax = technical potential by ~2035 with commercial technology; CCS and process change are excluded (no Egyptian CO2 storage or H2-DRI before 2035).
D52: Product | E52: np ERmax | F52: np anchor P* ($/t) | G52: np ER at P* | H52: np beta (1/$) | I52: no ERmax | J52: no anchor P* ($/t) | K52: no ER at P* | L52: no beta (1/$) | M52: np semi-el. at P=0 (%/$) | N52: no semi-el. at P=0 (%/$) | O52: np ER at $20 | P52: no ER at $20 | Q52: np lever and source | R52: no lever and source | S52: Confidence | T52: beta.np used | U52: ERmax.np used | V52: beta.no used | W52: ERmax.no used
D53: DRI-EAF steel | E53: 1 | F53: 122 | G53: 0.3433 | H53: =IF(OR(E53=0,G53=0),0,-LN(1-G53/E53)/F53) -> 0.0034469507 | I53: 0 | J53: 122 | K53: 0 | L53: =IF(OR(I53=0,K53=0),0,-LN(1-K53/I53)/J53) -> 0 | M53: =E53*H53 -> 0.0034469507 | N53: =I53*L53 -> 0 | O53: =E53*(1-EXP(-H53*20)) -> 0.066616398 | P53: =I53*(1-EXP(-L53*20)) -> 0 | Q53: IPCC AR6 WGIII Table 11.3/12.3 cost-bucket MACC, central (mean 2030 & long-run), USD2019; ER at $100 (Option A: ERmax 1, P* 122 = USD2019 100 deflated to USD2024, US GDP deflator ~1.22; v0.16). Derivation: egypt+mitigation/ProcessEmissions_CarbonPrice_Response; spec TASK-D v0.2. Lever: H2/NG-DRI, scrap share, CCS on shaft | R53: n/a (no ERmax 0) | S53: Medium | T53: =IF($E$50="ADHOC",$E$40,H53) -> 0.0034469507 | U53: =IF($E$50="ADHOC",1,E53) -> 1 | V53: =IF($E$50="ADHOC",$E$40,L53) -> 0 | W53: =IF($E$50="ADHOC",1,I53) -> 0
D54: Scrap-EAF steel | E54: 1 | F54: 122 | G54: 0.181 | H54: =IF(OR(E54=0,G54=0),0,-LN(1-G54/E54)/F54) -> 0.0016366491 | I54: 0 | J54: 122 | K54: 0 | L54: =IF(OR(I54=0,K54=0),0,-LN(1-K54/I54)/J54) -> 0 | M54: =E54*H54 -> 0.0016366491 | N54: =I54*L54 -> 0 | O54: =E54*(1-EXP(-H54*20)) -> 0.032203056 | P54: =I54*(1-EXP(-L54*20)) -> 0 | Q54: IPCC AR6 WGIII Table 11.3/12.3 cost-bucket MACC, central (mean 2030 & long-run), USD2019; ER at $100 (Option A: ERmax 1, P* 122 = USD2019 100 deflated to USD2024, US GDP deflator ~1.22; v0.16). Derivation: egypt+mitigation/ProcessEmissions_CarbonPrice_Response; spec TASK-D v0.2. Lever: electrode / carbon-input efficiency | R54: n/a (no ERmax 0) | S54: Low | T54: =IF($E$50="ADHOC",$E$41,H54) -> 0.0016366491 | U54: =IF($E$50="ADHOC",1,E54) -> 1 | V54: =IF($E$50="ADHOC",$E$41,L54) -> 0 | W54: =IF($E$50="ADHOC",1,I54) -> 0
D55: BF-BOF steel (reference) | E55: 1 | F55: 122 | G55: 0.2803 | H55: =IF(OR(E55=0,G55=0),0,-LN(1-G55/E55)/F55) -> 0.0026960723 | I55: 0 | J55: 122 | K55: 0 | L55: =IF(OR(I55=0,K55=0),0,-LN(1-K55/I55)/J55) -> 0 | M55: =E55*H55 -> 0.0026960723 | N55: =I55*L55 -> 0 | O55: =E55*(1-EXP(-H55*20)) -> 0.052493466 | P55: =I55*(1-EXP(-L55*20)) -> 0 | Q55: IPCC AR6 WGIII Table 11.3/12.3 cost-bucket MACC, central (mean 2030 & long-run), USD2019; ER at $100 (Option A: ERmax 1, P* 122 = USD2019 100 deflated to USD2024, US GDP deflator ~1.22; v0.16). Derivation: egypt+mitigation/ProcessEmissions_CarbonPrice_Response; spec TASK-D v0.2. Lever: top-gas recycling, DRI substitution, CCS | R55: n/a (no ERmax 0) | S55: Medium | T55: =IF($E$50="ADHOC",$E$42,H55) -> 0.0026960723 | U55: =IF($E$50="ADHOC",1,E55) -> 1 | V55: =IF($E$50="ADHOC",$E$42,L55) -> 0 | W55: =IF($E$50="ADHOC",1,I55) -> 0
D56: Grey clinker (dry-process) | E56: 1 | F56: 122 | G56: 0.3352 | H56: =IF(OR(E56=0,G56=0),0,-LN(1-G56/E56)/F56) -> 0.0033464675 | I56: 0 | J56: 122 | K56: 0 | L56: =IF(OR(I56=0,K56=0),0,-LN(1-K56/I56)/J56) -> 0 | M56: =E56*H56 -> 0.0033464675 | N56: =I56*L56 -> 0 | O56: =E56*(1-EXP(-H56*20)) -> 0.064738725 | P56: =I56*(1-EXP(-L56*20)) -> 0 | Q56: IPCC AR6 WGIII Table 11.3/12.3 cost-bucket MACC, central (mean 2030 & long-run), USD2019; ER at $100 (Option A: ERmax 1, P* 122 = USD2019 100 deflated to USD2024, US GDP deflator ~1.22; v0.16). Derivation: egypt+mitigation/ProcessEmissions_CarbonPrice_Response; spec TASK-D v0.2. Lever: clinker substitution (SCMs, LC3), CCS | R56: n/a (no ERmax 0) | S56: Medium | T56: =IF($E$50="ADHOC",$E$43,H56) -> 0.0033464675 | U56: =IF($E$50="ADHOC",1,E56) -> 1 | V56: =IF($E$50="ADHOC",$E$43,L56) -> 0 | W56: =IF($E$50="ADHOC",1,I56) -> 0
D57: Ammonia (net merchant) | E57: 0 | F57: 122 | G57: 0 | H57: =IF(OR(E57=0,G57=0),0,-LN(1-G57/E57)/F57) -> 0 | I57: 0 | J57: 122 | K57: 0 | L57: =IF(OR(I57=0,K57=0),0,-LN(1-K57/I57)/J57) -> 0 | M57: =E57*H57 -> 0 | N57: =I57*L57 -> 0 | O57: =E57*(1-EXP(-H57*20)) -> 0 | P57: =I57*(1-EXP(-L57*20)) -> 0 | Q57: n/a (np ERmax 0): none: np = 0 (SMR feedstock CO2 is fp; CCS / blue lever not routed to fp - caveat) | R57: n/a (no ERmax 0) | S57: Low | T57: =IF($E$50="ADHOC",$E$44,H57) -> 0 | U57: =IF($E$50="ADHOC",1,E57) -> 0 | V57: =IF($E$50="ADHOC",$E$44,L57) -> 0 | W57: =IF($E$50="ADHOC",1,I57) -> 0
D58: Urea | E58: 0 | F58: 122 | G58: 0 | H58: =IF(OR(E58=0,G58=0),0,-LN(1-G58/E58)/F58) -> 0 | I58: 0 | J58: 122 | K58: 0 | L58: =IF(OR(I58=0,K58=0),0,-LN(1-K58/I58)/J58) -> 0 | M58: =E58*H58 -> 0 | N58: =I58*L58 -> 0 | O58: =E58*(1-EXP(-H58*20)) -> 0 | P58: =I58*(1-EXP(-L58*20)) -> 0 | Q58: n/a (np ERmax 0): none: inherits ammonia (np = 0 under CBAM rule) | R58: n/a (no ERmax 0) | S58: Low | T58: =IF($E$50="ADHOC",$E$45,H58) -> 0 | U58: =IF($E$50="ADHOC",1,E58) -> 0 | V58: =IF($E$50="ADHOC",$E$45,L58) -> 0 | W58: =IF($E$50="ADHOC",1,I58) -> 0
D59: Ammonium nitrate | E59: 0 | F59: 122 | G59: 0 | H59: =IF(OR(E59=0,G59=0),0,-LN(1-G59/E59)/F59) -> 0 | I59: 1 | J59: 122 | K59: 0.6179 | L59: =IF(OR(I59=0,K59=0),0,-LN(1-K59/I59)/J59) -> 0.0078858436 | M59: =E59*H59 -> 0 | N59: =I59*L59 -> 0.0078858436 | O59: =E59*(1-EXP(-H59*20)) -> 0 | P59: =I59*(1-EXP(-L59*20)) -> 0.14590844 | Q59: n/a (np ERmax 0): - | R59: IPCC AR6 WGIII Table 11.3/12.3 cost-bucket MACC, central (mean 2030 & long-run), USD2019; ER at $100 (Option A: ERmax 1, P* 122 = USD2019 100 deflated to USD2024, US GDP deflator ~1.22; v0.16). Derivation: egypt+mitigation/ProcessEmissions_CarbonPrice_Response; spec TASK-D v0.2. Lever: tertiary N2O abatement in HNO3 (blend: unabated 0.7210 / abated 0.3292 at 50 % abated share, N2O-weighted) | S59: Medium | T59: =IF($E$50="ADHOC",$E$46,H59) -> 0 | U59: =IF($E$50="ADHOC",1,E59) -> 0 | V59: =IF($E$50="ADHOC",$E$46,L59) -> 0.0078858436 | W59: =IF($E$50="ADHOC",1,I59) -> 1
...

Sheet CPAT_National
B1: Fuel | C1: Sector | D1: Description | E1: Unit | F1: Source | G1: Input Code | H1: Output Code | I1: Note | J1: Helper | K1: 2021 | L1: 2022 | M1: 2023 | N1: 2024 | O1: 2025 | P1: 2026 | Q1: 2027 | R1: 2028 | S1: 2029 | T1: 2030 | U1: 2031 | V1: 2032 | W1: 2033 | X1: 2034 | Y1: 2035 | Z1: 2036 | AA1: 2037 | AB1: 2038 | AC1: 2039 | AD1: 2040 | AE1: 2041 | AF1: 2042 | AG1: 2043 | AH1: 2044 | AI1: 2045
B2: Main CPAT - Egypt: national outputs of the CPAT runs EG1-EG4 used by Task M (stored values)
B3: A. CPAT national outputs by run, linked by INDEX/MATCH to sheet CPAT_Results (key = CPAT code & "_" & run, year = row 5); EG1 = 1A/2A, EG2 = 2B, EG3 = 3A-3C, EG4 unused
B5: Key (code|run) | C5: Run | D5: Description | E5: Unit | F5: Source | H5: CPAT code | I5: Note | K5: 2021 | L5: 2022 | M5: 2023 | N5: 2024 | O5: 2025 | P5: 2026 | Q5: 2027 | R5: 2028 | S5: 2029 | T5: 2030 | U5: 2031 | V5: 2032 | W5: 2033 | X5: 2034 | Y5: 2035 | Z5: 2036 | AA5: 2037 | AB5: 2038 | AC5: 2039 | AD5: 2040 | AE5: 2041 | AF5: 2042 | AG5: 2043 | AH5: 2044 | AI5: 2045
B6: egy.air.ada.2464|EG1 | C6: EG1 | D6: Averted deaths by age group: 25 to 64 years | E6: deaths | F6: CPAT_Results (EG1) | H6: egy.air.ada.2464 | L6: =INDEX(CPAT_Results!$A:$AD,MATCH($H6&"_"&$C6,CPAT_Results!$F:$F,0),MATCH(L$5,CPAT_Results!$1:$1,0)) -> 0 | M6: =INDEX(CPAT_Results!$A:$AD,MATCH($H6&"_"&$C6,CPAT_Results!$F:$F,0),MATCH(M$5,CPAT_Results!$1:$1,0)) -> -1 | N6: =INDEX(CPAT_Results!$A:$AD,MATCH($H6&"_"&$C6,CPAT_Results!$F:$F,0),MATCH(N$5,CPAT_Results!$1:$1,0)) -> -1 | O6: =INDEX(CPAT_Results!$A:$AD,MATCH($H6&"_"&$C6,CPAT_Results!$F:$F,0),MATCH(O$5,CPAT_Results!$1:$1,0)) -> -1 | P6: =INDEX(CPAT_Results!$A:$AD,MATCH($H6&"_"&$C6,CPAT_Results!$F:$F,0),MATCH(P$5,CPAT_Results!$1:$1,0)) -> 802 | Q6: =INDEX(CPAT_Results!$A:$AD,MATCH($H6&"_"&$C6,CPAT_Results!$F:$F,0),MATCH(Q$5,CPAT_Results!$1:$1,0)) -> 673 | R6: =INDEX(CPAT_Results!$A:$AD,MATCH($H6&"_"&$C6,CPAT_Results!$F:$F,0),MATCH(R$5,CPAT_Results!$1:$1,0)) -> 626 | S6: =INDEX(CPAT_Results!$A:$AD,MATCH($H6&"_"&$C6,CPAT_Results!$F:$F,0),MATCH(S$5,CPAT_Results!$1:$1,0)) -> 582 | ... AE6: =INDEX(CPAT_Results!$A:$AD,MATCH($H6&"_"&$C6,CPAT_Results!$F:$F,0),MATCH(AE$5,CPAT_Results!$1:$1,0)) -> 0
B7: egy.air.ada.2464|EG2 | C7: EG2 | D7: Averted deaths by age group: 25 to 64 years | E7: deaths | F7: CPAT_Results (EG2) | H7: egy.air.ada.2464 | L7: =INDEX(CPAT_Results!$A:$AD,MATCH($H7&"_"&$C7,CPAT_Results!$F:$F,0),MATCH(L$5,CPAT_Results!$1:$1,0)) -> 0 | M7: =INDEX(CPAT_Results!$A:$AD,MATCH($H7&"_"&$C7,CPAT_Results!$F:$F,0),MATCH(M$5,CPAT_Results!$1:$1,0)) -> 0 | N7: =INDEX(CPAT_Results!$A:$AD,MATCH($H7&"_"&$C7,CPAT_Results!$F:$F,0),MATCH(N$5,CPAT_Results!$1:$1,0)) -> 0 | O7: =INDEX(CPAT_Results!$A:$AD,MATCH($H7&"_"&$C7,CPAT_Results!$F:$F,0),MATCH(O$5,CPAT_Results!$1:$1,0)) -> 0 | P7: =INDEX(CPAT_Results!$A:$AD,MATCH($H7&"_"&$C7,CPAT_Results!$F:$F,0),MATCH(P$5,CPAT_Results!$1:$1,0)) -> 0 | Q7: =INDEX(CPAT_Results!$A:$AD,MATCH($H7&"_"&$C7,CPAT_Results!$F:$F,0),MATCH(Q$5,CPAT_Results!$1:$1,0)) -> 0 | R7: =INDEX(CPAT_Results!$A:$AD,MATCH($H7&"_"&$C7,CPAT_Results!$F:$F,0),MATCH(R$5,CPAT_Results!$1:$1,0)) -> 0 | S7: =INDEX(CPAT_Results!$A:$AD,MATCH($H7&"_"&$C7,CPAT_Results!$F:$F,0),MATCH(S$5,CPAT_Results!$1:$1,0)) -> 29 | ... AE7: =INDEX(CPAT_Results!$A:$AD,MATCH($H7&"_"&$C7,CPAT_Results!$F:$F,0),MATCH(AE$5,CPAT_Results!$1:$1,0)) -> 0
B8: egy.air.ada.2464|EG3 | C8: EG3 | D8: Averted deaths by age group: 25 to 64 years | E8: deaths | F8: CPAT_Results (EG3) | H8: egy.air.ada.2464 | L8: =INDEX(CPAT_Results!$A:$AD,MATCH($H8&"_"&$C8,CPAT_Results!$F:$F,0),MATCH(L$5,CPAT_Results!$1:$1,0)) -> 0 | M8: =INDEX(CPAT_Results!$A:$AD,MATCH($H8&"_"&$C8,CPAT_Results!$F:$F,0),MATCH(M$5,CPAT_Results!$1:$1,0)) -> 1 | N8: =INDEX(CPAT_Results!$A:$AD,MATCH($H8&"_"&$C8,CPAT_Results!$F:$F,0),MATCH(N$5,CPAT_Results!$1:$1,0)) -> 1 | O8: =INDEX(CPAT_Results!$A:$AD,MATCH($H8&"_"&$C8,CPAT_Results!$F:$F,0),MATCH(O$5,CPAT_Results!$1:$1,0)) -> 1 | P8: =INDEX(CPAT_Results!$A:$AD,MATCH($H8&"_"&$C8,CPAT_Results!$F:$F,0),MATCH(P$5,CPAT_Results!$1:$1,0)) -> 223 | Q8: =INDEX(CPAT_Results!$A:$AD,MATCH($H8&"_"&$C8,CPAT_Results!$F:$F,0),MATCH(Q$5,CPAT_Results!$1:$1,0)) -> 84 | R8: =INDEX(CPAT_Results!$A:$AD,MATCH($H8&"_"&$C8,CPAT_Results!$F:$F,0),MATCH(R$5,CPAT_Results!$1:$1,0)) -> 113 | S8: =INDEX(CPAT_Results!$A:$AD,MATCH($H8&"_"&$C8,CPAT_Results!$F:$F,0),MATCH(S$5,CPAT_Results!$1:$1,0)) -> 183 | ... AE8: =INDEX(CPAT_Results!$A:$AD,MATCH($H8&"_"&$C8,CPAT_Results!$F:$F,0),MATCH(AE$5,CPAT_Results!$1:$1,0)) -> 0
B9: egy.air.ada.2464|EG4 | C9: EG4 | D9: Averted deaths by age group: 25 to 64 years | E9: deaths | F9: CPAT_Results (EG4) | H9: egy.air.ada.2464 | L9: =INDEX(CPAT_Results!$A:$AD,MATCH($H9&"_"&$C9,CPAT_Results!$F:$F,0),MATCH(L$5,CPAT_Results!$1:$1,0)) -> 0 | M9: =INDEX(CPAT_Results!$A:$AD,MATCH($H9&"_"&$C9,CPAT_Results!$F:$F,0),MATCH(M$5,CPAT_Results!$1:$1,0)) -> 0 | N9: =INDEX(CPAT_Results!$A:$AD,MATCH($H9&"_"&$C9,CPAT_Results!$F:$F,0),MATCH(N$5,CPAT_Results!$1:$1,0)) -> 0 | O9: =INDEX(CPAT_Results!$A:$AD,MATCH($H9&"_"&$C9,CPAT_Results!$F:$F,0),MATCH(O$5,CPAT_Results!$1:$1,0)) -> 0 | P9: =INDEX(CPAT_Results!$A:$AD,MATCH($H9&"_"&$C9,CPAT_Results!$F:$F,0),MATCH(P$5,CPAT_Results!$1:$1,0)) -> 0 | Q9: =INDEX(CPAT_Results!$A:$AD,MATCH($H9&"_"&$C9,CPAT_Results!$F:$F,0),MATCH(Q$5,CPAT_Results!$1:$1,0)) -> 0 | R9: =INDEX(CPAT_Results!$A:$AD,MATCH($H9&"_"&$C9,CPAT_Results!$F:$F,0),MATCH(R$5,CPAT_Results!$1:$1,0)) -> 2 | S9: =INDEX(CPAT_Results!$A:$AD,MATCH($H9&"_"&$C9,CPAT_Results!$F:$F,0),MATCH(S$5,CPAT_Results!$1:$1,0)) -> 6 | ... AE9: =INDEX(CPAT_Results!$A:$AD,MATCH($H9&"_"&$C9,CPAT_Results!$F:$F,0),MATCH(AE$5,CPAT_Results!$1:$1,0)) -> 0
B10: egy.air.ada.65|EG1 | C10: EG1 | D10: Averted deaths by age group: 65+ years | E10: deaths | F10: CPAT_Results (EG1) | H10: egy.air.ada.65 | L10: =INDEX(CPAT_Results!$A:$AD,MATCH($H10&"_"&$C10,CPAT_Results!$F:$F,0),MATCH(L$5,CPAT_Results!$1:$1,0)) -> 0 | M10: =INDEX(CPAT_Results!$A:$AD,MATCH($H10&"_"&$C10,CPAT_Results!$F:$F,0),MATCH(M$5,CPAT_Results!$1:$1,0)) -> -1 | N10: =INDEX(CPAT_Results!$A:$AD,MATCH($H10&"_"&$C10,CPAT_Results!$F:$F,0),MATCH(N$5,CPAT_Results!$1:$1,0)) -> -1 | O10: =INDEX(CPAT_Results!$A:$AD,MATCH($H10&"_"&$C10,CPAT_Results!$F:$F,0),MATCH(O$5,CPAT_Results!$1:$1,0)) -> -1 | P10: =INDEX(CPAT_Results!$A:$AD,MATCH($H10&"_"&$C10,CPAT_Results!$F:$F,0),MATCH(P$5,CPAT_Results!$1:$1,0)) -> 1410 | Q10: =INDEX(CPAT_Results!$A:$AD,MATCH($H10&"_"&$C10,CPAT_Results!$F:$F,0),MATCH(Q$5,CPAT_Results!$1:$1,0)) -> 1187 | R10: =INDEX(CPAT_Results!$A:$AD,MATCH($H10&"_"&$C10,CPAT_Results!$F:$F,0),MATCH(R$5,CPAT_Results!$1:$1,0)) -> 1105 | S10: =INDEX(CPAT_Results!$A:$AD,MATCH($H10&"_"&$C10,CPAT_Results!$F:$F,0),MATCH(S$5,CPAT_Results!$1:$1,0)) -> 1034 | ... AE10: =INDEX(CPAT_Results!$A:$AD,MATCH($H10&"_"&$C10,CPAT_Results!$F:$F,0),MATCH(AE$5,CPAT_Results!$1:$1,0)) -> 0
B11: egy.air.ada.65|EG2 | C11: EG2 | D11: Averted deaths by age group: 65+ years | E11: deaths | F11: CPAT_Results (EG2) | H11: egy.air.ada.65 | L11: =INDEX(CPAT_Results!$A:$AD,MATCH($H11&"_"&$C11,CPAT_Results!$F:$F,0),MATCH(L$5,CPAT_Results!$1:$1,0)) -> 0 | M11: =INDEX(CPAT_Results!$A:$AD,MATCH($H11&"_"&$C11,CPAT_Results!$F:$F,0),MATCH(M$5,CPAT_Results!$1:$1,0)) -> 0 | N11: =INDEX(CPAT_Results!$A:$AD,MATCH($H11&"_"&$C11,CPAT_Results!$F:$F,0),MATCH(N$5,CPAT_Results!$1:$1,0)) -> 0 | O11: =INDEX(CPAT_Results!$A:$AD,MATCH($H11&"_"&$C11,CPAT_Results!$F:$F,0),MATCH(O$5,CPAT_Results!$1:$1,0)) -> 0 | P11: =INDEX(CPAT_Results!$A:$AD,MATCH($H11&"_"&$C11,CPAT_Results!$F:$F,0),MATCH(P$5,CPAT_Results!$1:$1,0)) -> 0 | Q11: =INDEX(CPAT_Results!$A:$AD,MATCH($H11&"_"&$C11,CPAT_Results!$F:$F,0),MATCH(Q$5,CPAT_Results!$1:$1,0)) -> 0 | R11: =INDEX(CPAT_Results!$A:$AD,MATCH($H11&"_"&$C11,CPAT_Results!$F:$F,0),MATCH(R$5,CPAT_Results!$1:$1,0)) -> 0 | S11: =INDEX(CPAT_Results!$A:$AD,MATCH($H11&"_"&$C11,CPAT_Results!$F:$F,0),MATCH(S$5,CPAT_Results!$1:$1,0)) -> 53 | ... AE11: =INDEX(CPAT_Results!$A:$AD,MATCH($H11&"_"&$C11,CPAT_Results!$F:$F,0),MATCH(AE$5,CPAT_Results!$1:$1,0)) -> 0
B12: egy.air.ada.65|EG3 | C12: EG3 | D12: Averted deaths by age group: 65+ years | E12: deaths | F12: CPAT_Results (EG3) | H12: egy.air.ada.65 | L12: =INDEX(CPAT_Results!$A:$AD,MATCH($H12&"_"&$C12,CPAT_Results!$F:$F,0),MATCH(L$5,CPAT_Results!$1:$1,0)) -> 0 | M12: =INDEX(CPAT_Results!$A:$AD,MATCH($H12&"_"&$C12,CPAT_Results!$F:$F,0),MATCH(M$5,CPAT_Results!$1:$1,0)) -> 1 | N12: =INDEX(CPAT_Results!$A:$AD,MATCH($H12&"_"&$C12,CPAT_Results!$F:$F,0),MATCH(N$5,CPAT_Results!$1:$1,0)) -> 1 | O12: =INDEX(CPAT_Results!$A:$AD,MATCH($H12&"_"&$C12,CPAT_Results!$F:$F,0),MATCH(O$5,CPAT_Results!$1:$1,0)) -> 1 | P12: =INDEX(CPAT_Results!$A:$AD,MATCH($H12&"_"&$C12,CPAT_Results!$F:$F,0),MATCH(P$5,CPAT_Results!$1:$1,0)) -> 394 | Q12: =INDEX(CPAT_Results!$A:$AD,MATCH($H12&"_"&$C12,CPAT_Results!$F:$F,0),MATCH(Q$5,CPAT_Results!$1:$1,0)) -> 151 | R12: =INDEX(CPAT_Results!$A:$AD,MATCH($H12&"_"&$C12,CPAT_Results!$F:$F,0),MATCH(R$5,CPAT_Results!$1:$1,0)) -> 203 | S12: =INDEX(CPAT_Results!$A:$AD,MATCH($H12&"_"&$C12,CPAT_Results!$F:$F,0),MATCH(S$5,CPAT_Results!$1:$1,0)) -> 334 | ... AE12: =INDEX(CPAT_Results!$A:$AD,MATCH($H12&"_"&$C12,CPAT_Results!$F:$F,0),MATCH(AE$5,CPAT_Results!$1:$1,0)) -> 0
B13: egy.air.ada.65|EG4 | C13: EG4 | D13: Averted deaths by age group: 65+ years | E13: deaths | F13: CPAT_Results (EG4) | H13: egy.air.ada.65 | L13: =INDEX(CPAT_Results!$A:$AD,MATCH($H13&"_"&$C13,CPAT_Results!$F:$F,0),MATCH(L$5,CPAT_Results!$1:$1,0)) -> 0 | M13: =INDEX(CPAT_Results!$A:$AD,MATCH($H13&"_"&$C13,CPAT_Results!$F:$F,0),MATCH(M$5,CPAT_Results!$1:$1,0)) -> 0 | N13: =INDEX(CPAT_Results!$A:$AD,MATCH($H13&"_"&$C13,CPAT_Results!$F:$F,0),MATCH(N$5,CPAT_Results!$1:$1,0)) -> 0 | O13: =INDEX(CPAT_Results!$A:$AD,MATCH($H13&"_"&$C13,CPAT_Results!$F:$F,0),MATCH(O$5,CPAT_Results!$1:$1,0)) -> 0 | P13: =INDEX(CPAT_Results!$A:$AD,MATCH($H13&"_"&$C13,CPAT_Results!$F:$F,0),MATCH(P$5,CPAT_Results!$1:$1,0)) -> 0 | Q13: =INDEX(CPAT_Results!$A:$AD,MATCH($H13&"_"&$C13,CPAT_Results!$F:$F,0),MATCH(Q$5,CPAT_Results!$1:$1,0)) -> 0 | R13: =INDEX(CPAT_Results!$A:$AD,MATCH($H13&"_"&$C13,CPAT_Results!$F:$F,0),MATCH(R$5,CPAT_Results!$1:$1,0)) -> 4 | S13: =INDEX(CPAT_Results!$A:$AD,MATCH($H13&"_"&$C13,CPAT_Results!$F:$F,0),MATCH(S$5,CPAT_Results!$1:$1,0)) -> 10 | ... AE13: =INDEX(CPAT_Results!$A:$AD,MATCH($H13&"_"&$C13,CPAT_Results!$F:$F,0),MATCH(AE$5,CPAT_Results!$1:$1,0)) -> 0
B14: egy.air.ada.u24|EG1 | C14: EG1 | D14: Averted deaths by age group: under 24 years (including neonatal) | E14: deaths | F14: CPAT_Results (EG1) | H14: egy.air.ada.u24 | L14: =INDEX(CPAT_Results!$A:$AD,MATCH($H14&"_"&$C14,CPAT_Results!$F:$F,0),MATCH(L$5,CPAT_Results!$1:$1,0)) -> 0 | M14: =INDEX(CPAT_Results!$A:$AD,MATCH($H14&"_"&$C14,CPAT_Results!$F:$F,0),MATCH(M$5,CPAT_Results!$1:$1,0)) -> 0 | N14: =INDEX(CPAT_Results!$A:$AD,MATCH($H14&"_"&$C14,CPAT_Results!$F:$F,0),MATCH(N$5,CPAT_Results!$1:$1,0)) -> 0 | O14: =INDEX(CPAT_Results!$A:$AD,MATCH($H14&"_"&$C14,CPAT_Results!$F:$F,0),MATCH(O$5,CPAT_Results!$1:$1,0)) -> 0 | P14: =INDEX(CPAT_Results!$A:$AD,MATCH($H14&"_"&$C14,CPAT_Results!$F:$F,0),MATCH(P$5,CPAT_Results!$1:$1,0)) -> 132 | Q14: =INDEX(CPAT_Results!$A:$AD,MATCH($H14&"_"&$C14,CPAT_Results!$F:$F,0),MATCH(Q$5,CPAT_Results!$1:$1,0)) -> 110 | R14: =INDEX(CPAT_Results!$A:$AD,MATCH($H14&"_"&$C14,CPAT_Results!$F:$F,0),MATCH(R$5,CPAT_Results!$1:$1,0)) -> 102 | S14: =INDEX(CPAT_Results!$A:$AD,MATCH($H14&"_"&$C14,CPAT_Results!$F:$F,0),MATCH(S$5,CPAT_Results!$1:$1,0)) -> 93 | ... AE14: =INDEX(CPAT_Results!$A:$AD,MATCH($H14&"_"&$C14,CPAT_Results!$F:$F,0),MATCH(AE$5,CPAT_Results!$1:$1,0)) -> 0
B15: egy.air.ada.u24|EG2 | C15: EG2 | D15: Averted deaths by age group: under 24 years (including neonatal) | E15: deaths | F15: CPAT_Results (EG2) | H15: egy.air.ada.u24 | L15: =INDEX(CPAT_Results!$A:$AD,MATCH($H15&"_"&$C15,CPAT_Results!$F:$F,0),MATCH(L$5,CPAT_Results!$1:$1,0)) -> 0 | M15: =INDEX(CPAT_Results!$A:$AD,MATCH($H15&"_"&$C15,CPAT_Results!$F:$F,0),MATCH(M$5,CPAT_Results!$1:$1,0)) -> 0 | N15: =INDEX(CPAT_Results!$A:$AD,MATCH($H15&"_"&$C15,CPAT_Results!$F:$F,0),MATCH(N$5,CPAT_Results!$1:$1,0)) -> 0 | O15: =INDEX(CPAT_Results!$A:$AD,MATCH($H15&"_"&$C15,CPAT_Results!$F:$F,0),MATCH(O$5,CPAT_Results!$1:$1,0)) -> 0 | P15: =INDEX(CPAT_Results!$A:$AD,MATCH($H15&"_"&$C15,CPAT_Results!$F:$F,0),MATCH(P$5,CPAT_Results!$1:$1,0)) -> 0 | Q15: =INDEX(CPAT_Results!$A:$AD,MATCH($H15&"_"&$C15,CPAT_Results!$F:$F,0),MATCH(Q$5,CPAT_Results!$1:$1,0)) -> 0 | R15: =INDEX(CPAT_Results!$A:$AD,MATCH($H15&"_"&$C15,CPAT_Results!$F:$F,0),MATCH(R$5,CPAT_Results!$1:$1,0)) -> 0 | S15: =INDEX(CPAT_Results!$A:$AD,MATCH($H15&"_"&$C15,CPAT_Results!$F:$F,0),MATCH(S$5,CPAT_Results!$1:$1,0)) -> 4 | ... AE15: =INDEX(CPAT_Results!$A:$AD,MATCH($H15&"_"&$C15,CPAT_Results!$F:$F,0),MATCH(AE$5,CPAT_Results!$1:$1,0)) -> 0
B16: egy.air.ada.u24|EG3 | C16: EG3 | D16: Averted deaths by age group: under 24 years (including neonatal) | E16: deaths | F16: CPAT_Results (EG3) | H16: egy.air.ada.u24 | L16: =INDEX(CPAT_Results!$A:$AD,MATCH($H16&"_"&$C16,CPAT_Results!$F:$F,0),MATCH(L$5,CPAT_Results!$1:$1,0)) -> 0 | M16: =INDEX(CPAT_Results!$A:$AD,MATCH($H16&"_"&$C16,CPAT_Results!$F:$F,0),MATCH(M$5,CPAT_Results!$1:$1,0)) -> 0 | N16: =INDEX(CPAT_Results!$A:$AD,MATCH($H16&"_"&$C16,CPAT_Results!$F:$F,0),MATCH(N$5,CPAT_Results!$1:$1,0)) -> 0 | O16: =INDEX(CPAT_Results!$A:$AD,MATCH($H16&"_"&$C16,CPAT_Results!$F:$F,0),MATCH(O$5,CPAT_Results!$1:$1,0)) -> 0 | P16: =INDEX(CPAT_Results!$A:$AD,MATCH($H16&"_"&$C16,CPAT_Results!$F:$F,0),MATCH(P$5,CPAT_Results!$1:$1,0)) -> 36 | Q16: =INDEX(CPAT_Results!$A:$AD,MATCH($H16&"_"&$C16,CPAT_Results!$F:$F,0),MATCH(Q$5,CPAT_Results!$1:$1,0)) -> 13 | R16: =INDEX(CPAT_Results!$A:$AD,MATCH($H16&"_"&$C16,CPAT_Results!$F:$F,0),MATCH(R$5,CPAT_Results!$1:$1,0)) -> 17 | S16: =INDEX(CPAT_Results!$A:$AD,MATCH($H16&"_"&$C16,CPAT_Results!$F:$F,0),MATCH(S$5,CPAT_Results!$1:$1,0)) -> 28 | ... AE16: =INDEX(CPAT_Results!$A:$AD,MATCH($H16&"_"&$C16,CPAT_Results!$F:$F,0),MATCH(AE$5,CPAT_Results!$1:$1,0)) -> 0
B17: egy.air.ada.u24|EG4 | C17: EG4 | D17: Averted deaths by age group: under 24 years (including neonatal) | E17: deaths | F17: CPAT_Results (EG4) | H17: egy.air.ada.u24 | L17: =INDEX(CPAT_Results!$A:$AD,MATCH($H17&"_"&$C17,CPAT_Results!$F:$F,0),MATCH(L$5,CPAT_Results!$1:$1,0)) -> 0 | M17: =INDEX(CPAT_Results!$A:$AD,MATCH($H17&"_"&$C17,CPAT_Results!$F:$F,0),MATCH(M$5,CPAT_Results!$1:$1,0)) -> 0 | N17: =INDEX(CPAT_Results!$A:$AD,MATCH($H17&"_"&$C17,CPAT_Results!$F:$F,0),MATCH(N$5,CPAT_Results!$1:$1,0)) -> 0 | O17: =INDEX(CPAT_Results!$A:$AD,MATCH($H17&"_"&$C17,CPAT_Results!$F:$F,0),MATCH(O$5,CPAT_Results!$1:$1,0)) -> 0 | P17: =INDEX(CPAT_Results!$A:$AD,MATCH($H17&"_"&$C17,CPAT_Results!$F:$F,0),MATCH(P$5,CPAT_Results!$1:$1,0)) -> 0 | Q17: =INDEX(CPAT_Results!$A:$AD,MATCH($H17&"_"&$C17,CPAT_Results!$F:$F,0),MATCH(Q$5,CPAT_Results!$1:$1,0)) -> 0 | R17: =INDEX(CPAT_Results!$A:$AD,MATCH($H17&"_"&$C17,CPAT_Results!$F:$F,0),MATCH(R$5,CPAT_Results!$1:$1,0)) -> 0 | S17: =INDEX(CPAT_Results!$A:$AD,MATCH($H17&"_"&$C17,CPAT_Results!$F:$F,0),MATCH(S$5,CPAT_Results!$1:$1,0)) -> 1 | ... AE17: =INDEX(CPAT_Results!$A:$AD,MATCH($H17&"_"&$C17,CPAT_Results!$F:$F,0),MATCH(AE$5,CPAT_Results!$1:$1,0)) -> 0
... B133: egy.mit.wel.air.pct|EG4 | C133: EG4 | D133: Air pollution co-benefits (% GDP) | E133: MtCO2 | F133: CPAT_Results (EG4) | H133: egy.mit.wel.air.pct | L133: =INDEX(CPAT_Results!$A:$AD,MATCH($H133&"_"&$C133,CPAT_Results!$F:$F,0),MATCH(L$5,CPAT_Results!$1:$1,0)) -> 0 | M133: =INDEX(CPAT_Results!$A:$AD,MATCH($H133&"_"&$C133,CPAT_Results!$F:$F,0),MATCH(M$5,CPAT_Results!$1:$1,0)) -> 0 | N133: =INDEX(CPAT_Results!$A:$AD,MATCH($H133&"_"&$C133,CPAT_Results!$F:$F,0),MATCH(N$5,CPAT_Results!$1:$1,0)) -> 0 | O133: =INDEX(CPAT_Results!$A:$AD,MATCH($H133&"_"&$C133,CPAT_Results!$F:$F,0),MATCH(O$5,CPAT_Results!$1:$1,0)) -> 0 | P133: =INDEX(CPAT_Results!$A:$AD,MATCH($H133&"_"&$C133,CPAT_Results!$F:$F,0),MATCH(P$5,CPAT_Results!$1:$1,0)) -> 0 | Q133: =INDEX(CPAT_Results!$A:$AD,MATCH($H133&"_"&$C133,CPAT_Results!$F:$F,0),MATCH(Q$5,CPAT_Results!$1:$1,0)) -> 0 | R133: =INDEX(CPAT_Results!$A:$AD,MATCH($H133&"_"&$C133,CPAT_Results!$F:$F,0),MATCH(R$5,CPAT_Results!$1:$1,0)) -> 0 | S133: =INDEX(CPAT_Results!$A:$AD,MATCH($H133&"_"&$C133,CPAT_Results!$F:$F,0),MATCH(S$5,CPAT_Results!$1:$1,0)) -> 0 | ... AE133: =INDEX(CPAT_Results!$A:$AD,MATCH($H133&"_"&$C133,CPAT_Results!$F:$F,0),MATCH(AE$5,CPAT_Results!$1:$1,0)) -> 0
B135: Note: different data vintage from the CPAT values stored in the kernel (IPPU_Industry section A, CPAT_1_0pre_456 xlsb): 2030 baseline IPPU 85.97 vs 87.67, industrial energy CO2 88.97 vs 75.38 MtCO2. Task M uses deltas (policy - baseline) of a run only; levels of the two sources are never mixed.

Sheet CPAT_Results
A1: Include | B1: Country | C1: Scenario | D1: CPATIndicator | E1: CPATCode | F1: MTCode | G1: Tab | H1: Variable | I1: Unit | J1: SubScenario | K1: =CPATStartYear -> 2022 | L1: =K1+1 -> 2023 | M1: =L1+1 -> 2024 | N1: =M1+1 -> 2025 | O1: =N1+1 -> 2026 | P1: =O1+1 -> 2027 | Q1: =P1+1 -> 2028 | R1: =Q1+1 -> 2029 | S1: =R1+1 -> 2030 | ... AD1: =AC1+1 -> 2041
B2: Egypt | C2: EG1 | D2: Emissions coverage | E2: egy.mit.co2cov.2 | F2: egy.mit.co2cov.2_EG1 | G2: mit | H2: co2cov | I2: pc | J2: 2 | K2: 0 | L2: 0 | M2: 0 | N2: 0 | O2: 0.98816 | P2: 0.98744 | Q2: 0.98752 | R2: 0.98751 | S2: 0.98761 | T2: 0.9877 | U2: 0.98781 | V2: 0.98793 | W2: 0.98805 | X2: 0.98819 | Y2: 0.98832 | Z2: 0.98847 | AA2: 0.98863 | AB2: 0.9888 | AC2: 0.989 | AD2: 0.98917
B3: Egypt | C3: EG1 | D3: Carbon tax trajectory | E3: egy.mit.cptraj.2 | F3: egy.mit.cptraj.2_EG1 | G3: mit | H3: cptraj | I3: usdtco2 | J3: 2 | K3: 0 | L3: 0 | M3: 0 | N3: 0 | O3: 20 | P3: 20 | Q3: 20 | R3: 20 | S3: 20 | T3: 20 | U3: 20 | V3: 20 | W3: 20 | X3: 20 | Y3: 20 | Z3: 20 | AA3: 20 | AB3: 20 | AC3: 20 | AD3: 20
B4: Egypt | C4: EG1 | D4: Effective carbon tax trajectory | E4: egy.mit.eff.cptraj.2 | F4: egy.mit.eff.cptraj.2_EG1 | G4: mit | H4: effcptraj | I4: usdtco2 | J4: 2 | K4: 0 | L4: 0 | M4: 0 | N4: 0 | O4: 19.763 | P4: 19.749 | Q4: 19.75 | R4: 19.75 | S4: 19.752 | T4: 19.754 | U4: 19.756 | V4: 19.759 | W4: 19.761 | X4: 19.764 | Y4: 19.766 | Z4: 19.769 | AA4: 19.773 | AB4: 19.776 | AC4: 19.78 | AD4: 19.783
B5: Egypt | C5: EG1 | D5: ETS Trajector\y | E5: egy.mit.etstraj.2 | F5: egy.mit.etstraj.2_EG1 | G5: mit | H5: etstraj | I5: usdtco2 | J5: 2 | K5: 0 | L5: 0 | M5: 0 | N5: 0 | O5: 0 | P5: 0 | Q5: 0 | R5: 0 | S5: 0 | T5: 0 | U5: 0 | V5: 0 | W5: 0 | X5: 0 | Y5: 0 | Z5: 0 | AA5: 0 | AB5: 0 | AC5: 0 | AD5: 0
B6: Egypt | C6: EG1 | D6: Emissions covered by sector: power sector | E6: egy.mit.co2cov.pow.cont.2 | F6: egy.mit.co2cov.pow.cont.2_EG1 | G6: mit | H6: co2cov | I6: pc | J6: 2 | K6: 0 | L6: 0 | M6: 0 | N6: 0 | O6: 0.41588 | P6: 0.37477 | Q6: 0.37159 | R6: 0.36198 | S6: 0.35448 | T6: 0.34343 | U6: 0.33368 | V6: 0.32426 | W6: 0.31631 | X6: 0.30948 | Y6: 0.30392 | Z6: 0.29978 | AA6: 0.29711 | AB6: 0.29604 | AC6: 0.29677 | AD6: 0.29717
B7: Egypt | C7: EG1 | D7: Emissions covered, transport sector | E7: egy.mit.co2cov.tra.cont.2 | F7: egy.mit.co2cov.tra.cont.2_EG1 | G7: mit | H7: co2cov | I7: pc | J7: 2 | K7: 0 | L7: 0 | M7: 0 | N7: 0 | O7: 0.20507 | P7: 0.22498 | Q7: 0.23287 | R7: 0.24405 | S7: 0.2569 | T7: 0.27288 | U7: 0.28846 | V7: 0.30382 | W7: 0.31817 | X7: 0.33153 | Y7: 0.34377 | Z7: 0.35488 | AA7: 0.36487 | AB7: 0.37363 | AC7: 0.38103 | AD7: 0.38809
B8: Egypt | C8: EG1 | D8: Emissions covered, residential sector | E8: egy.mit.co2cov.res.cont.2 | F8: egy.mit.co2cov.res.cont.2_EG1 | G8: mit | H8: co2cov | I8: pc | J8: 2 | K8: 0 | L8: 0 | M8: 0 | N8: 0 | O8: 0.0811 | P8: 0.08261 | Q8: 0.07978 | R8: 0.07799 | S8: 0.07586 | T8: 0.07395 | U8: 0.0719 | V8: 0.06986 | W8: 0.06776 | X8: 0.06566 | Y8: 0.06356 | Z8: 0.0615 | AA8: 0.05942 | AB8: 0.05732 | AC8: 0.05519 | AD8: 0.05322
B9: Egypt | C9: EG1 | D9: Emissions covered, industry | E9: egy.mit.co2cov.ind.cont.2 | F9: egy.mit.co2cov.ind.cont.2_EG1 | G9: mit | H9: co2cov | I9: pc | J9: 2 | K9: 0 | L9: 0 | M9: 0 | N9: 0 | O9: 0.28621 | P9: 0.30519 | Q9: 0.3034 | R9: 0.30359 | S9: 0.30046 | T9: 0.29754 | U9: 0.29387 | V9: 0.29008 | W9: 0.28591 | X9: 0.28161 | Y9: 0.27716 | Z9: 0.27239 | AA9: 0.26731 | AB9: 0.2619 | AC9: 0.25609 | AD9: 0.25077
B10: Egypt | C10: EG1 | D10: Emissions covered, other energy use | E10: egy.mit.co2cov.oth.cont.2 | F10: egy.mit.co2cov.oth.cont.2_EG1 | G10: mit | H10: co2cov | I10: pc | J10: 2 | K10: 0 | L10: 0 | M10: 0 | N10: 0 | O10: 0 | P10: 0 | Q10: 0 | R10: 0 | S10: 0 | T10: 0 | U10: 0 | V10: 0 | W10: 0 | X10: 0 | Y10: 0 | Z10: 0 | AA10: 0 | AB10: 0 | AC10: 0 | AD10: 0
B11: Egypt | C11: EG1 | D11: Effect on GDP: Baseline GDP growth | E11: egy.mit.gdp.pre.pct.2 | F11: egy.mit.gdp.pre.pct.2_EG1 | G11: mit | H11: gdp | I11: pc | J11: 2 | K11: 0.06651 | L11: 0.0376 | M11: 0.02399 | N11: 0.04392 | O11: 0.0424 | P11: 0.04829 | Q11: 0.05535 | R11: 0.05227 | S11: 0.04842 | T11: 0.04789 | U11: 0.04736 | V11: 0.04682 | W11: 0.04629 | X11: 0.04576 | Y11: 0.04523 | Z11: 0.0447 | AA11: 0.04417 | AB11: 0.04364 | AC11: 0.0431 | AD11: 0.04257
B12: Egypt | C12: EG1 | D12: Effect on GDP: - Carbon tax | E12: egy.mit.gdp.exc.pct.2 | F12: egy.mit.gdp.exc.pct.2_EG1 | G12: mit | H12: gdp | I12: pc | J12: 2 | K12: 0 | L12: 0 | M12: 0 | N12: 0 | O12: -0.00455 | P12: -0.00726 | Q12: -0.00692 | R12: -0.00701 | S12: -0.00637 | T12: -0.00572 | U12: -0.0055 | V12: -0.00507 | W12: -0.00456 | X12: -0.00415 | Y12: -0.00396 | Z12: -0.00402 | AA12: -0.00409 | AB12: -0.00415 | AC12: -0.00403 | AD12: -0.00384
B13: Egypt | C13: EG1 | D13: Effect on GDP: Personal income tax | E13: egy.mit.gdp.pit.pct.2 | F13: egy.mit.gdp.pit.pct.2_EG1 | G13: mit | H13: gdp | I13: pc | J13: 2 | K13: 0 | L13: 0 | M13: 0 | N13: 0 | O13: 0.00092 | P13: 0.00107 | Q13: 0.00103 | R13: 0.00092 | S13: 0.00088 | T13: 0.00091 | U13: 0.00091 | V13: 0.00098 | W13: 0.00098 | X13: 0.00096 | Y13: 0.00095 | Z13: 0.00096 | AA13: 0.00099 | AB13: 0.00101 | AC13: 0.001 | AD13: 0.00098
... B21: Egypt | C21: EG1 | D21: Total revenues, % of GDP (policy) | E21: egy.mit.rev.new.pct.2 | F21: egy.mit.rev.new.pct.2_EG1 | G21: mit | H21: rev | I21: pc | J21: 2 | K21: -0.05845 | L21: -0.04678 | M21: -0.06658 | N21: -0.06182 | O21: -0.0499 | P21: -0.04387 | Q21: -0.04215 | R21: -0.04043 | S21: -0.03916 | T21: -0.03754 | U21: -0.03619 | V21: -0.03474 | W21: -0.03327 | X21: -0.03172 | Y21: -0.03002 | Z21: -0.02825 | AA21: -0.02636 | AB21: -0.02438 | AC21: -0.02263 | AD21: -0.02263
B22: Egypt | C22: EG1 | D22: Base erosion, % of GDP | E22: egy.mit.ers | F22: egy.mit.ers_EG1 | J22: 2 | K22: 0 | L22: 2.844543e-05 | M22: 2.4134132e-05 | N22: 2.2817555e-05 | O22: 0.0053636661 | P22: 0.0054115216 | Q22: 0.0047133669 | R22: 0.0045573619 | S22: 0.0044597548 | T22: 0.004534663 | U22: 0.0045964129 | V22: 0.0046718475 | W22: 0.0047194276 | X22: 0.0047563481 | Y22: 0.0047806517 | Z22: 0.0047817783 | AA22: 0.0047717964 | AB22: 0.0047494631 | AC22: 0.0047072887 | AD22: 0.0046640048
B23: Egypt | C23: EG1 | D23: Revenues - Carbon tax, % of GDP | E23: egy.mit.rcp | F23: egy.mit.rcp_EG1 | J23: 2 | K23: 0 | L23: 0 | M23: 0 | N23: 0 | O23: 0.0070282371 | P23: 0.0066914376 | Q23: 0.006691428 | R23: 0.0066205231 | S23: 0.0065941239 | T23: 0.0065572299 | U23: 0.0065423109 | V23: 0.0065358456 | W23: 0.0065449547 | X23: 0.0065665537 | Y23: 0.0065990759 | Z23: 0.0066460374 | AA23: 0.0067053353 | AB23: 0.0067782859 | AC23: 0.0068676131 | AD23: 0.0069502042
B24: Egypt | C24: EG1 | D24: Power sector carbon tax revenues | E24: egy.mit.rcp.pow | F24: egy.mit.rcp.pow_EG1 | J24: 2 | K24: 0 | L24: 0 | M24: 0 | N24: 0 | O24: 0.0029270922 | P24: 0.0025119838 | Q24: 0.0024906595 | R24: 0.0024005138 | S24: 0.002341282 | T24: 0.0022554069 | U24: 0.0021862333 | V24: 0.0021222911 | W24: 0.002073028 | X24: 0.0020347992 | Y24: 0.0020079946 | Z24: 0.0019946306 | AA24: 0.0019943886 | AB24: 0.0020086829 | AC24: 0.0020400658 | AD24: 0.0020672587
B25: Egypt | C25: EG1 | D25: Transport sector carbon tax revenues | E25: egy.mit.rcp.trs | F25: egy.mit.rcp.trs_EG1 | J25: 2 | K25: 0 | L25: 0 | M25: 0 | N25: 0 | O25: 0.0015159442 | P25: 0.0015801373 | Q25: 0.0016324432 | R25: 0.0016895292 | S25: 0.0017672912 | T25: 0.0018621026 | U25: 0.0019595348 | V25: 0.0020577283 | W25: 0.0021541125 | X25: 0.0022485125 | Y25: 0.0023399117 | Z25: 0.0024298037 | AA25: 0.0025177046 | AB25: 0.0026036397 | AC25: 0.0026877358 | AD25: 0.0027682159
B26: Egypt | C26: EG1 | D26: Buildings sector carbon tax revenues | E26: egy.mit.rcp.bld | F26: egy.mit.rcp.bld_EG1 | J26: 2 | K26: 0 | L26: 0 | M26: 0 | N26: 0 | O26: 0.00057080737 | P26: 0.00055370628 | Q26: 0.00053472521 | R26: 0.00051719763 | S26: 0.00050105953 | T26: 0.00048566665 | U26: 0.00047108621 | V26: 0.00045721944 | W26: 0.00044407029 | X26: 0.00043170054 | Y26: 0.00041997014 | Z26: 0.00040920311 | AA26: 0.00039886654 | AB26: 0.00038893228 | AC26: 0.0003793921 | AD26: 0.00037022679
B27: Egypt | C27: EG1 | D27: Industry sector carbon tax revenues | E27: egy.mit.rcp.ind | F27: egy.mit.rcp.ind_EG1 | J27: 2 | K27: 0 | L27: 0 | M27: 0 | N27: 0 | O27: 0.0020143933 | P27: 0.0020456102 | Q27: 0.0020336001 | R27: 0.0020132825 | S27: 0.0019844911 | T27: 0.0019540536 | U27: 0.0019254565 | V27: 0.0018986068 | W27: 0.0018737439 | X27: 0.0018515414 | Y27: 0.0018311995 | Z27: 0.0018123999 | AA27: 0.0017943756 | AB27: 0.0017770311 | AC27: 0.0017604194 | AD27: 0.0017445028
B28: Egypt | C28: EG1 | D28: Baseline ln(GDP per capita) | E28: egy.mit.ln.gdppc | F28: egy.mit.ln.gdppc_EG1 | G28: mit | H28: lngdppc | I28: unitless | J28: 1 | K28: 6.3 | L28: 6.34 | M28: 6.37 | N28: 6.41 | O28: 6.45 | P28: 6.5 | Q28: 6.55 | R28: 6.6 | S28: 6.65 | T28: 6.7 | U28: 6.74 | V28: 6.79 | W28: 6.83 | X28: 6.88 | Y28: 6.92 | Z28: 6.97 | AA28: 7.01 | AB28: 7.05 | AC28: 7.09 | AD28: 7.14
B29: Egypt | C29: EG1 | D29: Baseline GDP | E29: egy.mit.gdp.pre.lvl.1 | F29: egy.mit.gdp.pre.lvl.1_EG1 | G29: mit | H29: gdp | I29: usdbn | J29: 1 | K29: 546.97092 | L29: 567.53857 | M29: 581.15269 | N29: 606.67916 | O29: 632.40058 | P29: 662.94058 | Q29: 699.63644 | R29: 736.20368 | S29: 771.84975 | T29: 808.8116 | U29: 847.11364 | V29: 886.77935 | W29: 927.83114 | X29: 970.29029 | Y29: 1014.1768 | Z29: 1059.5094 | AA29: 1106.3053 | AB29: 1154.5801 | AC29: 1204.3479 | AD29: 1255.6209
B30: Egypt | C30: EG1 | D30: Post-policy GDP | E30: egy.mit.gdp.pst.lvl.2 | F30: egy.mit.gdp.pst.lvl.2_EG1 | G30: mit | H30: gdp | I30: usdbn | J30: 2 | K30: 546.97092 | L30: 567.53857 | M30: 581.15269 | N30: 606.67916 | O30: 632.40064 | P30: 663.30583 | Q30: 699.12177 | R30: 735.89129 | S30: 771.11883 | T30: 808.62015 | U30: 847.83187 | V30: 888.25231 | W30: 930.31798 | X30: 974.4035 | Y30: 1019.5241 | Z30: 1065.9639 | AA30: 1113.3315 | AB30: 1162.1247 | AC30: 1212.4927 | AD30: 1264.3711
B31: Egypt | C31: EG1 | D31: Population | E31: egy.mit.pop.mn | F31: egy.mit.pop.mn_EG1 | G31: mit | H31: pop | I31: mn | J31: 1 | K31: 103.6 | L31: 105.2 | M31: 106.6 | N31: 107.9 | O31: 110.058 | P31: 112.25916 | Q31: 114.50434 | R31: 116.79443 | S31: 120.29826 | T31: 125.11019 | U31: 130.1146 | V31: 135.31918 | W31: 140.73195 | X31: 146.36123 | Y31: 152.21568 | Z31: 158.3043 | AA31: 164.63647 | AB31: 171.22193 | AC31: 178.07081 | AD31: 185.19364
B32: Egypt | C32: EG1 | D32: Total GHG emissions, exc. LULUCF (baseline) | E32: egy.mit.ghg.tot.exc.1 | F32: egy.mit.ghg.tot.exc.1_EG1 | G32: mit | H32: emis | I32: mtco2e | J32: 1 | K32: 400.912 | L32: 412.105 | M32: 450.924 | N32: 467.515 | O32: 473.648 | P32: 484.763 | Q32: 501.104 | R32: 518.139 | S32: 535.623 | T32: 555.043 | U32: 576.999 | V32: 601.287 | W32: 626.831 | X32: 653.747 | Y32: 682.01 | Z32: 711.827 | AA32: 743.304 | AB32: 776.605 | AC32: 811.925 | AD32: 848.157
B33: Egypt | C33: EG1 | D33: Total GHG emissions, inc. LULUCF (baseline) | E33: egy.mit.ghg.tot.inc.1 | F33: egy.mit.ghg.tot.inc.1_EG1 | G33: mit | H33: emis | I33: mtco2e | J33: 1 | K33: 400.912 | L33: 412.105 | M33: 450.924 | N33: 467.515 | O33: 473.648 | P33: 484.763 | Q33: 501.104 | R33: 518.139 | S33: 535.623 | T33: 555.043 | U33: 576.999 | V33: 601.287 | W33: 626.831 | X33: 653.747 | Y33: 682.01 | Z33: 711.827 | AA33: 743.304 | AB33: 776.605 | AC33: 811.925 | AD33: 848.157
