Workbook
Name BaseYr: Inputs!$C$5
Name Bf: Example!$E$6
Name CBF: Inputs!$C$13
Name CPT_EG1: Inputs!$D$26
Name CPT_EG3: Inputs!$E$26
Name DEATHS_EG1: Inputs!$D$29
Name DEATHS_EG3: Inputs!$E$29
Name DREV_EG1: Inputs!$D$31
Name DREV_EG3: Inputs!$E$31
Name EFFCPT_EG1: Inputs!$D$27
Name EFFCPT_EG3: Inputs!$E$27
Name ENR0_EG1: Inputs!$D$22
Name ENR0_EG3: Inputs!$E$22
Name ENR1_EG1: Inputs!$D$23
Name ENR1_EG3: Inputs!$E$23
Name EpsF: Inputs!$C$9
Name EpsQ: Inputs!$C$10
Name EpsU: Inputs!$C$8
Name GHG0_EG1: Inputs!$D$18
Name GHG0_EG3: Inputs!$E$18
Name GHG1_EG1: Inputs!$D$19
Name GHG1_EG3: Inputs!$E$19
Name IND0_EG1: Inputs!$D$24
Name IND0_EG3: Inputs!$E$24
Name IND1_EG1: Inputs!$D$25
Name IND1_EG3: Inputs!$E$25
Name IPPU0_EG1: Inputs!$D$20
Name IPPU0_EG3: Inputs!$E$20
Name IPPU1_EG1: Inputs!$D$21
Name IPPU1_EG3: Inputs!$E$21
Name MORT_EG1: Inputs!$D$30
Name MORT_EG3: Inputs!$E$30
Name PEU: Inputs!$C$11
Name PStar: Inputs!$C$12
Name PT_ER: Inputs!$H$35:$H$42
Name PT_FuelFac: Inputs!$F$35:$F$42
Name PT_Growth: Inputs!$C$35:$C$42
Name PT_Name: Inputs!$A$35:$A$42
Name PT_P: Inputs!$E$35:$E$42
Name PT_ProcFac: Inputs!$G$35:$G$42
Name PT_Q0: Inputs!$B$35:$B$42
Name PT_X: Inputs!$D$35:$D$42
Name REVCTAX_EG1: Inputs!$D$28
Name REVCTAX_EG3: Inputs!$E$28
Name SigmaEff: Inputs!$C$7
Name Ssel: Inputs!$C$14
Name Tau: Inputs!$C$6
Name Yr: Inputs!$C$4

Sheet Example
A1: Worked example: ad hoc Table 2 rebuild v0.3 (REBUILD, NOPHASE, KappaMode=SCALE, 2030)
A2: One example per calculation level. Value = live formula; 'v0.3 value' = AdHocCalculations_Rebuild_v0.3 result (check). Last column: where the main version (CPAT_Industry_Kernel_Egypt_v0.15) differs; blank = same.
A4: Level | B4: Step | C4: Symbol | D4: Formula | E4: Value | F4: Unit | G4: v0.3 value | H4: Diff | I4: Main version (kernel v0.15)
A5: 0 Parameters | B5: Intensity share of fuel response | C5: s_int | D5: eps_F(1+eps_U)/(eps_U+eps_F(1+eps_U)) | E5: =EpsF*(1+EpsU)/(EpsU+EpsF*(1+EpsU)) -> 0.33333333 | G5: 0.33333333 | H5: =E5-G5 -> 0 | I5: Not used: kernel keeps fuel intensity fixed
A6: 0 Parameters | B6: Fuel-intensity semi-elasticity (EG1) | C6: b_f | D6: s_int*ln(IND1/IND0)/tau | E6: =E5*LN(IND1_EG1/IND0_EG1)/Tau -> -0.0024955979 | F6: per $/t | G6: -0.0024956 | H6: =E6-G6 -> 2.0637858e-09 | I6: Not used (x_f = 1)
A7: 0 Parameters | B7: Process semi-elasticity, clinker | C7: beta | D7: -ln(1-ER100)/P*, P* = 122 | E7: =-LN(1-INDEX(PT_ER,4))/PStar -> 0.0033464675 | F7: per $/t | G7: 0.0033465 | H7: =E7-G7 -> -3.2496386e-08 | I7: P* = 100 (USD2019, not deflated): beta = 0.00408
A8: 1 CPAT inputs (EG1) | B8: Change in total GHG | C8: dGHG | D8: GHG1 - GHG0 | E8: =GHG1_EG1-GHG0_EG1 -> -38.877 | F8: Mt | G8: -38.877 | H8: =E8-G8 -> 0
A9: 1 CPAT inputs (EG1) | B9: Change in IPPU | C9: dIPPU | D9: IPPU1 - IPPU0 | E9: =IPPU1_EG1-IPPU0_EG1 -> -11.955 | F9: Mt | G9: -11.955 | H9: =E9-G9 -> 0 | I9: Replaced by kernel's own IPPU delta
A10: 1 CPAT inputs (EG1) | B10: Change in industry energy CO2 | C10: dInd | D10: IND1 - IND0 | E10: =IND1_EG1-IND0_EG1 -> -12.373 | F10: Mt | G10: -12.373 | H10: =E10-G10 -> 0 | I10: Replaced by kernel's own industry delta
A11: 2 Product (clinker, 1A) | B11: Baseline output 2030 | C11: Qb | D11: Q0(1+g)^(Yr-2024) | E11: =Block!I9 -> 60753.588 | F11: kt
A12: 2 Product (clinker, 1A) | B12: Carbon cost per t (fuel + process) | C12: k_f + k_p | D12: tau*F + tau_p*G | E12: =Block!J9+Block!K9 -> 17.011893 | F12: $/t
A13: 2 Product (clinker, 1A) | B13: Relative price change | C13: dp | D13: (k_f+k_p-m)/P | E13: =Block!M9 -> 0.15465357
A14: 2 Product (clinker, 1A) | B14: Output after price response | C14: Q | D14: Qb(1+dp)^eps_Q | E14: =Block!N9 -> 56538.734 | F14: kt
A15: 2 Product (clinker, 1A) | B15: Fuel / process emissions at base intensity | C15: E_f + E_p | D15: Q(F+G)/1000 | E15: =Block!O9+Block!P9 -> 48.091545 | F15: Mt
A16: 2 Product (clinker, 1A) | B16: Fuel-intensity response | C16: ER_f | D16: E_f(exp(b_f(tau+sigma))-1) | E16: =Block!R9 -> -0.86315732 | F16: Mt | I16: 0 (fuel intensity fixed)
A17: 2 Product (clinker, 1A) | B17: Process-intensity response | C17: ER_p | D17: -E_p(1-exp(-beta(tau_p+sigma))) | E17: =Block!S9 -> -1.9656476 | F17: Mt | I17: Same form, larger beta (P* = 100)
A18: 2 Product (clinker, 1A) | B18: Output-channel process reduction | C18: emrq_proc | D18: E_p(1-(1+dp)^-eps_Q) | E18: =Block!V9 -> -2.2634869 | F18: Mt
A19: 2 Product (clinker, 1A) | B19: Domestic carbon revenue | C19: rev | D19: (E_f+ER_f)tau + (E_p+ER_p)tau_p | E19: =Block!W9+Block!X9 -> 905.25481 | F19: $m
A20: 2 Product (clinker, 1A) | B20: CBAM obligation per tonne | C20: obl | D20: max(0, CBF*P_EU*EI - S*max(0,d)) | E20: =Block!AB9 -> 64.044929 | F20: $/t | I20: Headline uses FULL (CBF = 0.485 in 2030); NOPHASE shown in brackets
A21: 3 Block (8 products, 1A) | B21: Block baseline emissions | C21: E_base | D21: sum Qb(F+G)/1000 | E21: =Block!AC14 -> 62.42361 | F21: Mt | G21: 62.4236 | H21: =E21-G21 -> 9.8908176e-06
A22: 3 Block (8 products, 1A) | B22: Sum process-intensity response | C22: sum ER_p | D22: sum ER_p | E22: =Block!S14 -> -2.1253756 | F22: Mt | G22: -2.1254 | H22: =E22-G22 -> 2.4406822e-05
A23: 3 Block (8 products, 1A) | B23: Sum output-channel process reduction | C23: sum emrq_proc | D23: sum emrq_proc | E23: =Block!V14 -> -2.2984641 | F23: Mt | G23: -2.2985 | H23: =E23-G23 -> 3.5904377e-05
A24: 3 Block (8 products, 1A) | B24: [N] CBAM intensity change | C24: cbintch | D24: sum E_post / sum(E_f+E_p) - 1 | E24: =Block!T14/(Block!O14+Block!P14)-1 -> -0.057934299 | G24: -0.0579 | H24: =E24-G24 -> -3.4298764e-05 | I24: -4.4% (no fuel-intensity channel)
A25: 3 Block (8 products, 1A) | B25: [O] CBAM obligation per unit change | C25: cbobchu | D25: sum X*obl / sum X*CBF*P_EU(F+G) - 1 | E25: =Block!AF14/Block!AG14-1 -> -0.24338141 | G25: -0.2434 | H25: =E25-G25 -> 1.8585251e-05 | I25: -43.3% FULL (-22.8% NOPHASE)
A26: 3 Block (8 products, 1A) | B26: [T] Block emissions change | C26: emrt/E_base | D26: (sum emrq + sum ER_f + sum ER_p)/E_base | E26: =(Block!U14+Block!R14+Block!S14)/Block!AC14 -> -0.11558776 | G26: -0.1156 | H26: =E26-G26 -> 1.2241159e-05
A27: 4 National (1A) | B27: [J] Coverage | C27: J | D27: (ENR0 + flag*E_p base)/GHG0 | E27: =(ENR0_EG1+Block!AE14)/GHG0_EG1 -> 0.63195774 | G27: 0.632 | H27: =E27-G27 -> -4.2255877e-05
A28: 4 National (1A) | B28: [K] Total reduction | C28: K | D28: dGHG - dIPPU + IPPU_other(0) + sum ER_p + sum emrq_proc | E28: =E8-E9+0+E22+E23 -> -31.34584 | F28: Mt | G28: -31.3458 | H28: =E28-G28 -> -3.9688801e-05 | I28: Composed as dGHG_CPAT + (dIPPU_kernel - dIPPU_CPAT) + (dInd_kernel - dInd_CPAT): -29.8
A29: 4 National (1A) | B29: [L] Reduction share | C29: L | D29: K / GHG0 | E29: =E28/GHG0_EG1 -> -0.052756919 | G29: -0.0528 | H29: =E29-G29 -> 4.3081465e-05
A30: 4 National (1A) | B30: [P] Net revenue | C30: P | D30: CPAT fuel receipts + sum rev_p/1000 - rebates | E30: =REVCTAX_EG1+Block!X14/1000-Block!Y14/1000 -> 6.8379529 | F30: $bn | G30: 6.838 | H30: =E30-G30 -> -4.7085438e-05 | I30: 6.87
A31: 4 National (1A) | B31: [Q] Deaths avoided | C31: Q | D31: CPAT deaths (own scenario) | E31: =DEATHS_EG1 -> 1564 | F31: # | G31: 1564 | H31: =E31-G31 -> 0 | I31: 1,441
A32: 4 National (1A) | B32: [AR] Delta net revenue | C32: AR | D32: CPAT dRev - (P_gross - P) | E32: =DREV_EG1-0 -> 10.43 | F32: $bn | G32: 10.43 | H32: =E32-G32 -> 0
A33: 5 Variant 3A (EG3) | B33: Priced share of industry energy CO2 | C33: kappa | D33: min(1, effcpt/cpt * ENR0/IND0) | E33: =MIN(1,EFFCPT_EG3/CPT_EG3*ENR0_EG3/IND0_EG3) -> 0.53737236 | G33: 0.5374 | H33: =E33-G33 -> -2.7639846e-05 | I33: No kappa/SCALE: kernel prices only its four sectors (coverage 8.6%)
A34: 5 Variant 3A (EG3) | B34: SCALE: adjusted industry delta | C34: dInd_adj | D34: dInd / kappa | E34: =(IND1_EG3-IND0_EG3)/E33 -> -15.912616 | F34: Mt | I34: n/a
A35: 5 Variant 3A (EG3) | B35: SCALE: adjusted IPPU delta | C35: dIPPU_adj | D35: dIPPU / kappa | E35: =(IPPU1_EG3-IPPU0_EG3)/E33 -> -15.374814 | F35: Mt | G35: -15.3748 | H35: =E35-G35 -> -1.3839754e-05 | I35: n/a
A36: 5 Variant 3A (EG3) | B36: SCALE: adjusted GHG delta | C36: dGHG_adj | D36: dGHG + (1/kappa-1)(dInd+dIPPU) | E36: =(GHG1_EG3-GHG0_EG3)+(1/E33-1)*((IND1_EG3-IND0_EG3)+(IPPU1_EG3-IPPU0_EG3)) -> -36.01643 | F36: Mt | G36: -36.0164 | H36: =E36-G36 -> -2.9809705e-05 | I36: n/a
A37: 5 Variant 3A (EG3) | B37: [J] Coverage (kappa = 1 under SCALE) | C37: J | D37: (IND0 + E_p base)/GHG0 | E37: =(IND0_EG3+Block!AE14)/GHG0_EG3 -> 0.20835351 | G37: 0.2084 | H37: =E37-G37 -> -4.6494495e-05 | I37: 8.6%
A38: 5 Variant 3A (EG3) | B38: [K] Total reduction | C38: K | D38: dGHG_adj - dIPPU_adj + sum ER_p + sum emrq_proc (1A block) | E38: =E36-E35+E22+E23 -> -25.065456 | F38: Mt | G38: -25.0655 | H38: =E38-G38 -> 4.4341248e-05 | I38: -11.8
A39: 5 Variant 3A (EG3) | B39: [Q] Deaths avoided | C39: Q | D39: CPAT deaths * dENR_adj/dENR | E39: =DEATHS_EG3*((ENR1_EG3-ENR0_EG3)+(1/E33-1)*(IND1_EG3-IND0_EG3))/(ENR1_EG3-ENR0_EG3) -> 850.34181 | F39: # | G39: 850.3418 | H39: =E39-G39 -> 1.2644293e-05 | I39: 278
A40: 5 Variant 3B (OBR) | B40: OBR correction | C40: D_obr | D40: -(1-s_int)*w*dInd_adj, w = E_f base/IND0 | E40: =-(1-E5)*MIN(1,Block!AD28/IND0_EG3)*E34 -> 3.2910509 | F40: Mt | G40: 3.2911 | H40: =E40-G40 -> -4.9106596e-05 | I40: Rebate capped by sector shares; no D_obr term
A41: 5 Variant 3B (OBR) | B41: [K] Total reduction | C41: K | D41: dGHG_adj - dIPPU_adj + sum ER_p + sum emrq_proc + D_obr | E41: =E36-E35+Block!S28+Block!V28+E40 -> -19.626285 | F41: Mt | G41: -19.6263 | H41: =E41-G41 -> 1.4804882e-05 | I41: -8.6
...

Sheet Inputs
A1: Inputs (copied from AdHoc rebuild v0.3 Inputs and CPAT Outputs, 2030)
A3: A. Switches and parameters
A4: Yr | B4: Reporting year | C4: 2030
A5: BaseYr | B5: Base year of product activity Q0 | C5: 2024
A6: Tau | B6: Carbon price tau (CPAT cptraj.2, EG1 and EG3, 2030) | C6: 20 | D6: $/t
A7: SigmaEff | B7: Fund shadow price sigma | C7: 20 | D7: $/t
A8: EpsU | B8: eps_U | C8: -0.5
A9: EpsF | B9: eps_F | C9: -0.5
A10: EpsQ | B10: Output price elasticity eps_Q | C10: -0.5
A11: PEU | B11: EU ETS price P_EU | C11: 100 | D11: $/t
A12: PStar | B12: IPCC anchor price P* (USD2019 100 deflated to USD2024) | C12: 122 | D12: $/t
A13: CBF | B13: CBAM phase-in factor (NOPHASE convention = 1) | C13: 1
A14: Ssel | B14: Deduction factor S (NOPHASE = 1) | C14: 1
A16: B. CPAT values, 2030
A17: Code | B17: CPAT code | C17: Label | D17: EG1 | E17: EG3 | F17: Unit
A18: GHG0 | B18: egy.mit.ghg.tot.inc.1 | C18: Total GHG incl. LULUCF, baseline | D18: 594.156 | E18: 594.156 | F18: Mt
A19: GHG1 | B19: egy.mit.ghg.tot.inc.2 | C19: Total GHG, policy | D19: 555.279 | E19: 572.614 | F19: Mt
A20: IPPU0 | B20: egy.mit.ghg.ipr.tot.1 | C20: IPPU GHG, baseline | D20: 85.97 | E20: 85.97 | F20: Mt
A21: IPPU1 | B21: egy.mit.ghg.ipr.tot.2 | C21: IPPU GHG, policy | D21: 74.015 | E21: 77.708 | F21: Mt
A22: ENR0 | B22: egy.mit.co2.enr.tot.1 | C22: Energy CO2, baseline | D22: 340.66 | E22: 340.66 | F22: Mt
A23: ENR1 | B23: egy.mit.co2.enr.tot.2 | C23: Energy CO2, policy | D23: 313.865 | E23: 327.453 | F23: Mt
A24: IND0 | B24: egy.mit.co2.ind.1 | C24: Industry energy CO2, baseline | D24: 88.973 | E24: 88.973 | F24: Mt
A25: IND1 | B25: egy.mit.co2.ind.2 | C25: Industry energy CO2, policy | D25: 76.6 | E25: 80.422 | F25: Mt
A26: CPT | B26: egy.mit.cptraj.2 | C26: Carbon price trajectory | D26: 20 | E26: 20 | F26: $/t
A27: EFFCPT | B27: egy.mit.eff.cptraj.2 | C27: Effective (coverage-weighted) carbon price | D27: 19.8 | E27: 2.807 | F27: $/t
A28: REVCTAX | B28: (sum) | C28: Carbon-tax receipts, six fuels (coa+die+gso+lpk+nga+oil .usd.2) | D28: 6.23 | E28: 0.93 | F28: $bn
A29: DEATHS | B29: (sum) | C29: Deaths avoided (ada.2464 + ada.65 + ada.u24) | D29: 1564 | E29: 546 | F29: #
... A31: DREV | B31: (sum) | C31: Delta net new revenue (rev.new.usd.2 - .1) | D31: 10.43 | E31: 2.69 | F31: $bn
A33: C. CBAM products (Q0 kt 2024, g, EU exports X kt, price P $/t, F = fc+fp, G = np+no tCO2e/t, ER at $100)
A34: Product | B34: Q0 | C34: g | D34: X | E34: P | F34: F | G34: G | H34: ER100
A35: DRI-EAF steel | B35: 5100 | C35: 0.044 | D35: 580 | E35: 750 | F35: 0.57099077 | G35: 0.03790102 | H35: 0.3433
A36: Scrap-EAF steel | B36: 4800 | C36: 0.044 | D36: 300 | E36: 680 | F36: 0.04488 | G36: 0.04398115 | H36: 0.181
A37: BF-BOF steel | B37: 0 | C37: 0 | D37: 0 | E37: 620 | F37: 1.4249803 | G37: 0.05276542 | H37: 0.2803
A38: Clinker | B38: 50000 | C38: 0.033 | D38: 800 | E38: 110 | F38: 0.3135685 | G38: 0.53702616 | H38: 0.3352
A39: Ammonia | B39: 1785 | C39: 0.022 | D39: 120 | E39: 450 | F39: 1.97472 | G39: 0 | H39: 0.2974
A40: Urea | B40: 2800 | C40: 0.022 | D40: 1600 | E40: 380 | F40: 0.1122 | G40: 0 | H40: 0.1158
A41: Ammonium nitrate | B41: 600 | C41: 0.022 | D41: 80 | E41: 320 | F41: 0.1122 | G41: 0.9944125 | H41: 0.6179
A42: Aluminium | B42: 300 | C42: 0.055 | D42: 167 | E42: 2400 | F42: 0.12342 | G42: 2.397493 | H42: 0.2164

Sheet Block
A1: CBAM block, all eight products, per bundle variant (Yr = 2030, NOPHASE)
A3: Bundle 1A (flag=1, theta=0, phi=0); 3A uses the 1A block
A4: flag | B4: 1 | C4: theta | D4: 0 | E4: phi | F4: 0 | G4: tau_p | H4: =Tau*B4 -> 20 | I4: OBR rate | J4: =D4*Tau -> 0 | K4: sigma_eff | L4: =F4*SigmaEff -> 0
A5: Product | B5: Q0 | C5: g | D5: X | E5: P | F5: F | G5: G | H5: beta | I5: Qb | J5: k_f | K5: k_p | L5: m (rebate/t) | M5: dp | N5: Q | O5: E_f | P5: E_p | Q5: x_f | R5: ER_f | S5: ER_p | T5: E_post | U5: emrq | V5: emrq_proc | W5: rev_f $m | X5: rev_p $m | Y5: rebate $m | Z5: EI | AA5: d | AB5: obl | AC5: E_base | AD5: E_f base | AE5: E_p base | AF5: X*obl | AG5: X*PEU*(F+G) | AH5: covered
A6: =INDEX(PT_Name,1) -> DRI-EAF steel | B6: =INDEX(PT_Q0,1) -> 5100 | C6: =INDEX(PT_Growth,1) -> 0.044 | D6: =INDEX(PT_X,1) -> 580 | E6: =INDEX(PT_P,1) -> 750 | F6: =INDEX(PT_FuelFac,1) -> 0.57099077 | G6: =INDEX(PT_ProcFac,1) -> 0.03790102 | H6: =-LN(1-INDEX(PT_ER,1))/PStar -> 0.0034469507 | I6: =B6*(1+C6)^(Yr-BaseYr) -> 6603.4846 | J6: =Tau*F6 -> 11.419815 | K6: =$H$4*G6 -> 0.7580204 | L6: =MIN($J$4,Tau)*F6+MIN($J$4,$H$4)*G6 -> 0 | M6: =(J6+K6-L6)/E6 -> 0.016237114 | N6: =I6*(1+M6)^EpsQ -> 6550.518 | O6: =N6*F6/1000 -> 3.7402853 | P6: =N6*G6/1000 -> 0.24827131 | Q6: =EXP(Bf*(Tau+$L$4)) -> 0.95131318 | R6: =O6*(Q6-1) -> -0.18210261 | S6: =-P6*(1-EXP(-H6*($H$4+$L$4))) -> -0.016538941 | T6: =O6+R6+P6+S6 -> 3.7899151 | U6: =(O6+P6)*(1-(1+M6)^(-EpsQ)) -> -0.032250937 | V6: =P6*(1-(1+M6)^(-EpsQ)) -> -0.0020074887 | W6: =(O6+R6)*Tau -> 71.163654 | X6: =(P6*(G6>0)+S6)*$H$4 -> 4.6346474 | Y6: =L6*N6/1000 -> 0 | Z6: =IF(N6>0,1000*T6/N6,0) -> 0.57856723 | AA6: =IF(N6>0,1000*(W6+X6)/N6-L6,0) -> 11.571345 | AB6: =MAX(0,CBF*PEU*Z6-Ssel*MAX(0,AA6)) -> 46.285379 | AC6: =I6*(F6+G6)/1000 -> 4.0208075 | AD6: =I6*F6/1000 -> 3.7705287 | AE6: =I6*G6/1000 -> 0.2502788 | AF6: =D6*AB6 -> 26845.52 | AG6: =D6*CBF*PEU*(F6+G6) -> 35315.724 | AH6: =O6+P6*(G6>0)*$B$4 -> 3.9885566
A7: =INDEX(PT_Name,2) -> Scrap-EAF steel | B7: =INDEX(PT_Q0,2) -> 4800 | C7: =INDEX(PT_Growth,2) -> 0.044 | D7: =INDEX(PT_X,2) -> 300 | E7: =INDEX(PT_P,2) -> 680 | F7: =INDEX(PT_FuelFac,2) -> 0.04488 | G7: =INDEX(PT_ProcFac,2) -> 0.04398115 | H7: =-LN(1-INDEX(PT_ER,2))/PStar -> 0.0016366491 | I7: =B7*(1+C7)^(Yr-BaseYr) -> 6215.0443 | J7: =Tau*F7 -> 0.8976 | K7: =$H$4*G7 -> 0.879623 | L7: =MIN($J$4,Tau)*F7+MIN($J$4,$H$4)*G7 -> 0 | M7: =(J7+K7-L7)/E7 -> 0.0026135632 | N7: =I7*(1+M7)^EpsQ -> 6206.9385 | O7: =N7*F7/1000 -> 0.2785674 | P7: =N7*G7/1000 -> 0.27298829 | Q7: =EXP(Bf*(Tau+$L$4)) -> 0.95131318 | R7: =O7*(Q7-1) -> -0.013562562 | S7: =-P7*(1-EXP(-H7*($H$4+$L$4))) -> -0.0087910574 | T7: =O7+R7+P7+S7 -> 0.52920207 | U7: =(O7+P7)*(1-(1+M7)^(-EpsQ)) -> -0.00072029251 | V7: =P7*(1-(1+M7)^(-EpsQ)) -> -0.0003565033 | W7: =(O7+R7)*Tau -> 5.3000967 | X7: =(P7*(G7>0)+S7)*$H$4 -> 5.2839447 | Y7: =L7*N7/1000 -> 0 | Z7: =IF(N7>0,1000*T7/N7,0) -> 0.085259758 | AA7: =IF(N7>0,1000*(W7+X7)/N7-L7,0) -> 1.7051952 | AB7: =MAX(0,CBF*PEU*Z7-Ssel*MAX(0,AA7)) -> 6.8207806 | AC7: =I7*(F7+G7)/1000 -> 0.55227598 | AD7: =I7*F7/1000 -> 0.27893119 | AE7: =I7*G7/1000 -> 0.2733448 | AF7: =D7*AB7 -> 2046.2342 | AG7: =D7*CBF*PEU*(F7+G7) -> 2665.8345 | AH7: =O7+P7*(G7>0)*$B$4 -> 0.55155569
A8: =INDEX(PT_Name,3) -> BF-BOF steel | B8: =INDEX(PT_Q0,3) -> 0 | C8: =INDEX(PT_Growth,3) -> 0 | D8: =INDEX(PT_X,3) -> 0 | E8: =INDEX(PT_P,3) -> 620 | F8: =INDEX(PT_FuelFac,3) -> 1.4249803 | G8: =INDEX(PT_ProcFac,3) -> 0.05276542 | H8: =-LN(1-INDEX(PT_ER,3))/PStar -> 0.0026960723 | I8: =B8*(1+C8)^(Yr-BaseYr) -> 0 | J8: =Tau*F8 -> 28.499605 | K8: =$H$4*G8 -> 1.0553084 | L8: =MIN($J$4,Tau)*F8+MIN($J$4,$H$4)*G8 -> 0 | M8: =(J8+K8-L8)/E8 -> 0.047669216 | N8: =I8*(1+M8)^EpsQ -> 0 | O8: =N8*F8/1000 -> 0 | P8: =N8*G8/1000 -> 0 | Q8: =EXP(Bf*(Tau+$L$4)) -> 0.95131318 | R8: =O8*(Q8-1) -> 0 | S8: =-P8*(1-EXP(-H8*($H$4+$L$4))) -> 0 | T8: =O8+R8+P8+S8 -> 0 | U8: =(O8+P8)*(1-(1+M8)^(-EpsQ)) -> 0 | V8: =P8*(1-(1+M8)^(-EpsQ)) -> 0 | W8: =(O8+R8)*Tau -> 0 | X8: =(P8*(G8>0)+S8)*$H$4 -> 0 | Y8: =L8*N8/1000 -> 0 | Z8: =IF(N8>0,1000*T8/N8,0) -> 0 | AA8: =IF(N8>0,1000*(W8+X8)/N8-L8,0) -> 0 | AB8: =MAX(0,CBF*PEU*Z8-Ssel*MAX(0,AA8)) -> 0 | AC8: =I8*(F8+G8)/1000 -> 0 | AD8: =I8*F8/1000 -> 0 | AE8: =I8*G8/1000 -> 0 | AF8: =D8*AB8 -> 0 | AG8: =D8*CBF*PEU*(F8+G8) -> 0 | AH8: =O8+P8*(G8>0)*$B$4 -> 0
A9: =INDEX(PT_Name,4) -> Clinker | B9: =INDEX(PT_Q0,4) -> 50000 | C9: =INDEX(PT_Growth,4) -> 0.033 | D9: =INDEX(PT_X,4) -> 800 | E9: =INDEX(PT_P,4) -> 110 | F9: =INDEX(PT_FuelFac,4) -> 0.3135685 | G9: =INDEX(PT_ProcFac,4) -> 0.53702616 | H9: =-LN(1-INDEX(PT_ER,4))/PStar -> 0.0033464675 | I9: =B9*(1+C9)^(Yr-BaseYr) -> 60753.588 | J9: =Tau*F9 -> 6.27137 | K9: =$H$4*G9 -> 10.740523 | L9: =MIN($J$4,Tau)*F9+MIN($J$4,$H$4)*G9 -> 0 | M9: =(J9+K9-L9)/E9 -> 0.15465357 | N9: =I9*(1+M9)^EpsQ -> 56538.734 | O9: =N9*F9/1000 -> 17.728766 | P9: =N9*G9/1000 -> 30.362779 | Q9: =EXP(Bf*(Tau+$L$4)) -> 0.95131318 | R9: =O9*(Q9-1) -> -0.86315732 | S9: =-P9*(1-EXP(-H9*($H$4+$L$4))) -> -1.9656476 | T9: =O9+R9+P9+S9 -> 45.26274 | U9: =(O9+P9)*(1-(1+M9)^(-EpsQ)) -> -3.5851323 | V9: =P9*(1-(1+M9)^(-EpsQ)) -> -2.2634869 | W9: =(O9+R9)*Tau -> 337.31218 | X9: =(P9*(G9>0)+S9)*$H$4 -> 567.94263 | Y9: =L9*N9/1000 -> 0 | Z9: =IF(N9>0,1000*T9/N9,0) -> 0.80056162 | AA9: =IF(N9>0,1000*(W9+X9)/N9-L9,0) -> 16.011232 | AB9: =MAX(0,CBF*PEU*Z9-Ssel*MAX(0,AA9)) -> 64.044929 | AC9: =I9*(F9+G9)/1000 -> 51.676678 | AD9: =I9*F9/1000 -> 19.050412 | AE9: =I9*G9/1000 -> 32.626266 | AF9: =D9*AB9 -> 51235.943 | AG9: =D9*CBF*PEU*(F9+G9) -> 68047.573 | AH9: =O9+P9*(G9>0)*$B$4 -> 48.091545
A10: =INDEX(PT_Name,5) -> Ammonia | B10: =INDEX(PT_Q0,5) -> 1785 | C10: =INDEX(PT_Growth,5) -> 0.022 | D10: =INDEX(PT_X,5) -> 120 | E10: =INDEX(PT_P,5) -> 450 | F10: =INDEX(PT_FuelFac,5) -> 1.97472 | G10: =INDEX(PT_ProcFac,5) -> 0 | H10: =-LN(1-INDEX(PT_ER,5))/PStar -> 0.0028931766 | I10: =B10*(1+C10)^(Yr-BaseYr) -> 2033.9656 | J10: =Tau*F10 -> 39.4944 | K10: =$H$4*G10 -> 0 | L10: =MIN($J$4,Tau)*F10+MIN($J$4,$H$4)*G10 -> 0 | M10: =(J10+K10-L10)/E10 -> 0.087765333 | N10: =I10*(1+M10)^EpsQ -> 1950.1858 | O10: =N10*F10/1000 -> 3.8510709 | P10: =N10*G10/1000 -> 0 | Q10: =EXP(Bf*(Tau+$L$4)) -> 0.95131318 | R10: =O10*(Q10-1) -> -0.18749641 | S10: =-P10*(1-EXP(-H10*($H$4+$L$4))) -> 0 | T10: =O10+R10+P10+S10 -> 3.6635745 | U10: =(O10+P10)*(1-(1+M10)^(-EpsQ)) -> -0.16544158 | V10: =P10*(1-(1+M10)^(-EpsQ)) -> 0 | W10: =(O10+R10)*Tau -> 73.27149 | X10: =(P10*(G10>0)+S10)*$H$4 -> 0 | Y10: =L10*N10/1000 -> 0 | Z10: =IF(N10>0,1000*T10/N10,0) -> 1.8785772 | AA10: =IF(N10>0,1000*(W10+X10)/N10-L10,0) -> 37.571543 | AB10: =MAX(0,CBF*PEU*Z10-Ssel*MAX(0,AA10)) -> 150.28617 | AC10: =I10*(F10+G10)/1000 -> 4.0165125 | AD10: =I10*F10/1000 -> 4.0165125 | AE10: =I10*G10/1000 -> 0 | AF10: =D10*AB10 -> 18034.341 | AG10: =D10*CBF*PEU*(F10+G10) -> 23696.64 | AH10: =O10+P10*(G10>0)*$B$4 -> 3.8510709
A11: =INDEX(PT_Name,6) -> Urea | B11: =INDEX(PT_Q0,6) -> 2800 | C11: =INDEX(PT_Growth,6) -> 0.022 | D11: =INDEX(PT_X,6) -> 1600 | E11: =INDEX(PT_P,6) -> 380 | F11: =INDEX(PT_FuelFac,6) -> 0.1122 | G11: =INDEX(PT_ProcFac,6) -> 0 | H11: =-LN(1-INDEX(PT_ER,6))/PStar -> 0.0010087869 | I11: =B11*(1+C11)^(Yr-BaseYr) -> 3190.5342 | J11: =Tau*F11 -> 2.244 | K11: =$H$4*G11 -> 0 | L11: =MIN($J$4,Tau)*F11+MIN($J$4,$H$4)*G11 -> 0 | M11: =(J11+K11-L11)/E11 -> 0.0059052632 | N11: =I11*(1+M11)^EpsQ -> 3181.1553 | O11: =N11*F11/1000 -> 0.35692562 | P11: =N11*G11/1000 -> 0 | Q11: =EXP(Bf*(Tau+$L$4)) -> 0.95131318 | R11: =O11*(Q11-1) -> -0.017377575 | S11: =-P11*(1-EXP(-H11*($H$4+$L$4))) -> 0 | T11: =O11+R11+P11+S11 -> 0.33954805 | U11: =(O11+P11)*(1-(1+M11)^(-EpsQ)) -> -0.0010523186 | V11: =P11*(1-(1+M11)^(-EpsQ)) -> 0 | W11: =(O11+R11)*Tau -> 6.7909609 | X11: =(P11*(G11>0)+S11)*$H$4 -> 0 | Y11: =L11*N11/1000 -> 0 | Z11: =IF(N11>0,1000*T11/N11,0) -> 0.10673734 | AA11: =IF(N11>0,1000*(W11+X11)/N11-L11,0) -> 2.1347468 | AB11: =MAX(0,CBF*PEU*Z11-Ssel*MAX(0,AA11)) -> 8.5389871 | AC11: =I11*(F11+G11)/1000 -> 0.35797794 | AD11: =I11*F11/1000 -> 0.35797794 | AE11: =I11*G11/1000 -> 0 | AF11: =D11*AB11 -> 13662.379 | AG11: =D11*CBF*PEU*(F11+G11) -> 17952 | AH11: =O11+P11*(G11>0)*$B$4 -> 0.35692562
A12: =INDEX(PT_Name,7) -> Ammonium nitrate | B12: =INDEX(PT_Q0,7) -> 600 | C12: =INDEX(PT_Growth,7) -> 0.022 | D12: =INDEX(PT_X,7) -> 80 | E12: =INDEX(PT_P,7) -> 320 | F12: =INDEX(PT_FuelFac,7) -> 0.1122 | G12: =INDEX(PT_ProcFac,7) -> 0.9944125 | H12: =-LN(1-INDEX(PT_ER,7))/PStar -> 0.0078858436 | I12: =B12*(1+C12)^(Yr-BaseYr) -> 683.6859 | J12: =Tau*F12 -> 2.244 | K12: =$H$4*G12 -> 19.88825 | L12: =MIN($J$4,Tau)*F12+MIN($J$4,$H$4)*G12 -> 0 | M12: =(J12+K12-L12)/E12 -> 0.069163281 | N12: =I12*(1+M12)^EpsQ -> 661.20268 | O12: =N12*F12/1000 -> 0.074186941 | P12: =N12*G12/1000 -> 0.65750821 | Q12: =EXP(Bf*(Tau+$L$4)) -> 0.95131318 | R12: =O12*(Q12-1) -> -0.0036119266 | S12: =-P12*(1-EXP(-H12*($H$4+$L$4))) -> -0.095935995 | T12: =O12+R12+P12+S12 -> 0.63214723 | U12: =(O12+P12)*(1-(1+M12)^(-EpsQ)) -> -0.024880211 | V12: =P12*(1-(1+M12)^(-EpsQ)) -> -0.022357594 | W12: =(O12+R12)*Tau -> 1.4115003 | X12: =(P12*(G12>0)+S12)*$H$4 -> 11.231444 | Y12: =L12*N12/1000 -> 0 | Z12: =IF(N12>0,1000*T12/N12,0) -> 0.95605667 | AA12: =IF(N12>0,1000*(W12+X12)/N12-L12,0) -> 19.121133 | AB12: =MAX(0,CBF*PEU*Z12-Ssel*MAX(0,AA12)) -> 76.484533 | AC12: =I12*(F12+G12)/1000 -> 0.75657537 | AD12: =I12*F12/1000 -> 0.076709558 | AE12: =I12*G12/1000 -> 0.67986581 | AF12: =D12*AB12 -> 6118.7627 | AG12: =D12*CBF*PEU*(F12+G12) -> 8852.9 | AH12: =O12+P12*(G12>0)*$B$4 -> 0.73169515
A13: =INDEX(PT_Name,8) -> Aluminium | B13: =INDEX(PT_Q0,8) -> 300 | C13: =INDEX(PT_Growth,8) -> 0.055 | D13: =INDEX(PT_X,8) -> 167 | E13: =INDEX(PT_P,8) -> 2400 | F13: =INDEX(PT_FuelFac,8) -> 0.12342 | G13: =INDEX(PT_ProcFac,8) -> 2.397493 | H13: =-LN(1-INDEX(PT_ER,8))/PStar -> 0.0019988245 | I13: =B13*(1+C13)^(Yr-BaseYr) -> 413.65284 | J13: =Tau*F13 -> 2.4684 | K13: =$H$4*G13 -> 47.949861 | L13: =MIN($J$4,Tau)*F13+MIN($J$4,$H$4)*G13 -> 0 | M13: =(J13+K13-L13)/E13 -> 0.021007609 | N13: =I13*(1+M13)^EpsQ -> 409.37519 | O13: =N13*F13/1000 -> 0.050525086 | P13: =N13*G13/1000 -> 0.98147418 | Q13: =EXP(Bf*(Tau+$L$4)) -> 0.95131318 | R13: =O13*(Q13-1) -> -0.002459906 | S13: =-P13*(1-EXP(-H13*($H$4+$L$4))) -> -0.038461984 | T13: =O13+R13+P13+S13 -> 0.99107738 | U13: =(O13+P13)*(1-(1+M13)^(-EpsQ)) -> -0.010783578 | V13: =P13*(1-(1+M13)^(-EpsQ)) -> -0.010255631 | W13: =(O13+R13)*Tau -> 0.96130361 | X13: =(P13*(G13>0)+S13)*$H$4 -> 18.860244 | Y13: =L13*N13/1000 -> 0 | Z13: =IF(N13>0,1000*T13/N13,0) -> 2.4209512 | AA13: =IF(N13>0,1000*(W13+X13)/N13-L13,0) -> 48.419024 | AB13: =MAX(0,CBF*PEU*Z13-Ssel*MAX(0,AA13)) -> 193.6761 | AC13: =I13*(F13+G13)/1000 -> 1.0427828 | AD13: =I13*F13/1000 -> 0.051053034 | AE13: =I13*G13/1000 -> 0.99172981 | AF13: =D13*AB13 -> 32343.908 | AG13: =D13*CBF*PEU*(F13+G13) -> 42099.248 | AH13: =O13+P13*(G13>0)*$B$4 -> 1.0319993
A14: Total | I14: =SUM(I6:I13) -> 79893.956 | N14: =SUM(N6:N13) -> 75498.11 | O14: =SUM(O6:O13) -> 26.080327 | P14: =SUM(P6:P13) -> 32.523021 | R14: =SUM(R6:R13) -> -1.2697683 | S14: =SUM(S6:S13) -> -2.1253756 | T14: =SUM(T6:T13) -> 55.208205 | U14: =SUM(U6:U13) -> -3.8202613 | V14: =SUM(V6:V13) -> -2.2984641 | W14: =SUM(W6:W13) -> 496.21118 | X14: =SUM(X6:X13) -> 607.95291 | Y14: =SUM(Y6:Y13) -> 0 | AC14: =SUM(AC6:AC13) -> 62.42361 | AD14: =SUM(AD6:AD13) -> 27.602124 | AE14: =SUM(AE6:AE13) -> 34.821485 | AF14: =SUM(AF6:AF13) -> 150287.09 | AG14: =SUM(AG6:AG13) -> 198629.92 | AH14: =SUM(AH6:AH13) -> 58.603349
A17: Bundle 3B (flag=1, theta=1, phi=0); 3A uses the 1A block
A18: flag | B18: 1 | C18: theta | D18: 1 | E18: phi | F18: 0 | G18: tau_p | H18: =Tau*B18 -> 20 | I18: OBR rate | J18: =D18*Tau -> 20 | K18: sigma_eff | L18: =F18*SigmaEff -> 0
A19: Product | B19: Q0 | C19: g | D19: X | E19: P | F19: F | G19: G | H19: beta | I19: Qb | J19: k_f | K19: k_p | L19: m (rebate/t) | M19: dp | N19: Q | O19: E_f | P19: E_p | Q19: x_f | R19: ER_f | S19: ER_p | T19: E_post | U19: emrq | V19: emrq_proc | W19: rev_f $m | X19: rev_p $m | Y19: rebate $m | Z19: EI | AA19: d | AB19: obl | AC19: E_base | AD19: E_f base | AE19: E_p base | AF19: X*obl | AG19: X*PEU*(F+G) | AH19: covered
A20: =INDEX(PT_Name,1) -> DRI-EAF steel | B20: =INDEX(PT_Q0,1) -> 5100 | C20: =INDEX(PT_Growth,1) -> 0.044 | D20: =INDEX(PT_X,1) -> 580 | E20: =INDEX(PT_P,1) -> 750 | F20: =INDEX(PT_FuelFac,1) -> 0.57099077 | G20: =INDEX(PT_ProcFac,1) -> 0.03790102 | H20: =-LN(1-INDEX(PT_ER,1))/PStar -> 0.0034469507 | I20: =B20*(1+C20)^(Yr-BaseYr) -> 6603.4846 | J20: =Tau*F20 -> 11.419815 | K20: =$H$18*G20 -> 0.7580204 | L20: =MIN($J$18,Tau)*F20+MIN($J$18,$H$18)*G20 -> 12.177836 | M20: =(J20+K20-L20)/E20 -> 0 | N20: =I20*(1+M20)^EpsQ -> 6603.4846 | O20: =N20*F20/1000 -> 3.7705287 | P20: =N20*G20/1000 -> 0.2502788 | Q20: =EXP(Bf*(Tau+$L$18)) -> 0.95131318 | R20: =O20*(Q20-1) -> -0.18357507 | S20: =-P20*(1-EXP(-H20*($H$18+$L$18))) -> -0.016672672 | T20: =O20+R20+P20+S20 -> 3.8205598 | U20: =(O20+P20)*(1-(1+M20)^(-EpsQ)) -> 0 | V20: =P20*(1-(1+M20)^(-EpsQ)) -> 0 | W20: =(O20+R20)*Tau -> 71.739073 | X20: =(P20*(G20>0)+S20)*$H$18 -> 4.6721226 | Y20: =L20*N20/1000 -> 80.416151 | Z20: =IF(N20>0,1000*T20/N20,0) -> 0.57856723 | AA20: =IF(N20>0,1000*(W20+X20)/N20-L20,0) -> -0.60649114 | AB20: =MAX(0,CBF*PEU*Z20-Ssel*MAX(0,AA20)) -> 57.856723 | AC20: =I20*(F20+G20)/1000 -> 4.0208075 | AD20: =I20*F20/1000 -> 3.7705287 | AE20: =I20*G20/1000 -> 0.2502788 | AF20: =D20*AB20 -> 33556.9 | AG20: =D20*CBF*PEU*(F20+G20) -> 35315.724 | AH20: =O20+P20*(G20>0)*$B$18 -> 4.0208075
A21: =INDEX(PT_Name,2) -> Scrap-EAF steel | B21: =INDEX(PT_Q0,2) -> 4800 | C21: =INDEX(PT_Growth,2) -> 0.044 | D21: =INDEX(PT_X,2) -> 300 | E21: =INDEX(PT_P,2) -> 680 | F21: =INDEX(PT_FuelFac,2) -> 0.04488 | G21: =INDEX(PT_ProcFac,2) -> 0.04398115 | H21: =-LN(1-INDEX(PT_ER,2))/PStar -> 0.0016366491 | I21: =B21*(1+C21)^(Yr-BaseYr) -> 6215.0443 | J21: =Tau*F21 -> 0.8976 | K21: =$H$18*G21 -> 0.879623 | L21: =MIN($J$18,Tau)*F21+MIN($J$18,$H$18)*G21 -> 1.777223 | M21: =(J21+K21-L21)/E21 -> 0 | N21: =I21*(1+M21)^EpsQ -> 6215.0443 | O21: =N21*F21/1000 -> 0.27893119 | P21: =N21*G21/1000 -> 0.2733448 | Q21: =EXP(Bf*(Tau+$L$18)) -> 0.95131318 | R21: =O21*(Q21-1) -> -0.013580274 | S21: =-P21*(1-EXP(-H21*($H$18+$L$18))) -> -0.0088025379 | T21: =O21+R21+P21+S21 -> 0.52989317 | U21: =(O21+P21)*(1-(1+M21)^(-EpsQ)) -> 0 | V21: =P21*(1-(1+M21)^(-EpsQ)) -> 0 | W21: =(O21+R21)*Tau -> 5.3070183 | X21: =(P21*(G21>0)+S21)*$H$18 -> 5.2908452 | Y21: =L21*N21/1000 -> 11.04552 | Z21: =IF(N21>0,1000*T21/N21,0) -> 0.085259758 | AA21: =IF(N21>0,1000*(W21+X21)/N21-L21,0) -> -0.072027843 | AB21: =MAX(0,CBF*PEU*Z21-Ssel*MAX(0,AA21)) -> 8.5259758 | AC21: =I21*(F21+G21)/1000 -> 0.55227598 | AD21: =I21*F21/1000 -> 0.27893119 | AE21: =I21*G21/1000 -> 0.2733448 | AF21: =D21*AB21 -> 2557.7927 | AG21: =D21*CBF*PEU*(F21+G21) -> 2665.8345 | AH21: =O21+P21*(G21>0)*$B$18 -> 0.55227598
A22: =INDEX(PT_Name,3) -> BF-BOF steel | B22: =INDEX(PT_Q0,3) -> 0 | C22: =INDEX(PT_Growth,3) -> 0 | D22: =INDEX(PT_X,3) -> 0 | E22: =INDEX(PT_P,3) -> 620 | F22: =INDEX(PT_FuelFac,3) -> 1.4249803 | G22: =INDEX(PT_ProcFac,3) -> 0.05276542 | H22: =-LN(1-INDEX(PT_ER,3))/PStar -> 0.0026960723 | I22: =B22*(1+C22)^(Yr-BaseYr) -> 0 | J22: =Tau*F22 -> 28.499605 | K22: =$H$18*G22 -> 1.0553084 | L22: =MIN($J$18,Tau)*F22+MIN($J$18,$H$18)*G22 -> 29.554914 | M22: =(J22+K22-L22)/E22 -> 0 | N22: =I22*(1+M22)^EpsQ -> 0 | O22: =N22*F22/1000 -> 0 | P22: =N22*G22/1000 -> 0 | Q22: =EXP(Bf*(Tau+$L$18)) -> 0.95131318 | R22: =O22*(Q22-1) -> 0 | S22: =-P22*(1-EXP(-H22*($H$18+$L$18))) -> 0 | T22: =O22+R22+P22+S22 -> 0 | U22: =(O22+P22)*(1-(1+M22)^(-EpsQ)) -> 0 | V22: =P22*(1-(1+M22)^(-EpsQ)) -> 0 | W22: =(O22+R22)*Tau -> 0 | X22: =(P22*(G22>0)+S22)*$H$18 -> 0 | Y22: =L22*N22/1000 -> 0 | Z22: =IF(N22>0,1000*T22/N22,0) -> 0 | AA22: =IF(N22>0,1000*(W22+X22)/N22-L22,0) -> 0 | AB22: =MAX(0,CBF*PEU*Z22-Ssel*MAX(0,AA22)) -> 0 | AC22: =I22*(F22+G22)/1000 -> 0 | AD22: =I22*F22/1000 -> 0 | AE22: =I22*G22/1000 -> 0 | AF22: =D22*AB22 -> 0 | AG22: =D22*CBF*PEU*(F22+G22) -> 0 | AH22: =O22+P22*(G22>0)*$B$18 -> 0
A23: =INDEX(PT_Name,4) -> Clinker | B23: =INDEX(PT_Q0,4) -> 50000 | C23: =INDEX(PT_Growth,4) -> 0.033 | D23: =INDEX(PT_X,4) -> 800 | E23: =INDEX(PT_P,4) -> 110 | F23: =INDEX(PT_FuelFac,4) -> 0.3135685 | G23: =INDEX(PT_ProcFac,4) -> 0.53702616 | H23: =-LN(1-INDEX(PT_ER,4))/PStar -> 0.0033464675 | I23: =B23*(1+C23)^(Yr-BaseYr) -> 60753.588 | J23: =Tau*F23 -> 6.27137 | K23: =$H$18*G23 -> 10.740523 | L23: =MIN($J$18,Tau)*F23+MIN($J$18,$H$18)*G23 -> 17.011893 | M23: =(J23+K23-L23)/E23 -> 0 | N23: =I23*(1+M23)^EpsQ -> 60753.588 | O23: =N23*F23/1000 -> 19.050412 | P23: =N23*G23/1000 -> 32.626266 | Q23: =EXP(Bf*(Tau+$L$18)) -> 0.95131318 | R23: =O23*(Q23-1) -> -0.92750404 | S23: =-P23*(1-EXP(-H23*($H$18+$L$18))) -> -2.1121829 | T23: =O23+R23+P23+S23 -> 48.636991 | U23: =(O23+P23)*(1-(1+M23)^(-EpsQ)) -> 0 | V23: =P23*(1-(1+M23)^(-EpsQ)) -> 0 | W23: =(O23+R23)*Tau -> 362.45815 | X23: =(P23*(G23>0)+S23)*$H$18 -> 610.28167 | Y23: =L23*N23/1000 -> 1033.5336 | Z23: =IF(N23>0,1000*T23/N23,0) -> 0.80056162 | AA23: =IF(N23>0,1000*(W23+X23)/N23-L23,0) -> -1.0006609 | AB23: =MAX(0,CBF*PEU*Z23-Ssel*MAX(0,AA23)) -> 80.056162 | AC23: =I23*(F23+G23)/1000 -> 51.676678 | AD23: =I23*F23/1000 -> 19.050412 | AE23: =I23*G23/1000 -> 32.626266 | AF23: =D23*AB23 -> 64044.929 | AG23: =D23*CBF*PEU*(F23+G23) -> 68047.573 | AH23: =O23+P23*(G23>0)*$B$18 -> 51.676678
A24: =INDEX(PT_Name,5) -> Ammonia | B24: =INDEX(PT_Q0,5) -> 1785 | C24: =INDEX(PT_Growth,5) -> 0.022 | D24: =INDEX(PT_X,5) -> 120 | E24: =INDEX(PT_P,5) -> 450 | F24: =INDEX(PT_FuelFac,5) -> 1.97472 | G24: =INDEX(PT_ProcFac,5) -> 0 | H24: =-LN(1-INDEX(PT_ER,5))/PStar -> 0.0028931766 | I24: =B24*(1+C24)^(Yr-BaseYr) -> 2033.9656 | J24: =Tau*F24 -> 39.4944 | K24: =$H$18*G24 -> 0 | L24: =MIN($J$18,Tau)*F24+MIN($J$18,$H$18)*G24 -> 39.4944 | M24: =(J24+K24-L24)/E24 -> 0 | N24: =I24*(1+M24)^EpsQ -> 2033.9656 | O24: =N24*F24/1000 -> 4.0165125 | P24: =N24*G24/1000 -> 0 | Q24: =EXP(Bf*(Tau+$L$18)) -> 0.95131318 | R24: =O24*(Q24-1) -> -0.19555124 | S24: =-P24*(1-EXP(-H24*($H$18+$L$18))) -> 0 | T24: =O24+R24+P24+S24 -> 3.8209612 | U24: =(O24+P24)*(1-(1+M24)^(-EpsQ)) -> 0 | V24: =P24*(1-(1+M24)^(-EpsQ)) -> 0 | W24: =(O24+R24)*Tau -> 76.419225 | X24: =(P24*(G24>0)+S24)*$H$18 -> 0 | Y24: =L24*N24/1000 -> 80.330249 | Z24: =IF(N24>0,1000*T24/N24,0) -> 1.8785772 | AA24: =IF(N24>0,1000*(W24+X24)/N24-L24,0) -> -1.9228569 | AB24: =MAX(0,CBF*PEU*Z24-Ssel*MAX(0,AA24)) -> 187.85772 | AC24: =I24*(F24+G24)/1000 -> 4.0165125 | AD24: =I24*F24/1000 -> 4.0165125 | AE24: =I24*G24/1000 -> 0 | AF24: =D24*AB24 -> 22542.926 | AG24: =D24*CBF*PEU*(F24+G24) -> 23696.64 | AH24: =O24+P24*(G24>0)*$B$18 -> 4.0165125
A25: =INDEX(PT_Name,6) -> Urea | B25: =INDEX(PT_Q0,6) -> 2800 | C25: =INDEX(PT_Growth,6) -> 0.022 | D25: =INDEX(PT_X,6) -> 1600 | E25: =INDEX(PT_P,6) -> 380 | F25: =INDEX(PT_FuelFac,6) -> 0.1122 | G25: =INDEX(PT_ProcFac,6) -> 0 | H25: =-LN(1-INDEX(PT_ER,6))/PStar -> 0.0010087869 | I25: =B25*(1+C25)^(Yr-BaseYr) -> 3190.5342 | J25: =Tau*F25 -> 2.244 | K25: =$H$18*G25 -> 0 | L25: =MIN($J$18,Tau)*F25+MIN($J$18,$H$18)*G25 -> 2.244 | M25: =(J25+K25-L25)/E25 -> 0 | N25: =I25*(1+M25)^EpsQ -> 3190.5342 | O25: =N25*F25/1000 -> 0.35797794 | P25: =N25*G25/1000 -> 0 | Q25: =EXP(Bf*(Tau+$L$18)) -> 0.95131318 | R25: =O25*(Q25-1) -> -0.017428809 | S25: =-P25*(1-EXP(-H25*($H$18+$L$18))) -> 0 | T25: =O25+R25+P25+S25 -> 0.34054913 | U25: =(O25+P25)*(1-(1+M25)^(-EpsQ)) -> 0 | V25: =P25*(1-(1+M25)^(-EpsQ)) -> 0 | W25: =(O25+R25)*Tau -> 6.8109826 | X25: =(P25*(G25>0)+S25)*$H$18 -> 0 | Y25: =L25*N25/1000 -> 7.1595588 | Z25: =IF(N25>0,1000*T25/N25,0) -> 0.10673734 | AA25: =IF(N25>0,1000*(W25+X25)/N25-L25,0) -> -0.10925323 | AB25: =MAX(0,CBF*PEU*Z25-Ssel*MAX(0,AA25)) -> 10.673734 | AC25: =I25*(F25+G25)/1000 -> 0.35797794 | AD25: =I25*F25/1000 -> 0.35797794 | AE25: =I25*G25/1000 -> 0 | AF25: =D25*AB25 -> 17077.974 | AG25: =D25*CBF*PEU*(F25+G25) -> 17952 | AH25: =O25+P25*(G25>0)*$B$18 -> 0.35797794
A26: =INDEX(PT_Name,7) -> Ammonium nitrate | B26: =INDEX(PT_Q0,7) -> 600 | C26: =INDEX(PT_Growth,7) -> 0.022 | D26: =INDEX(PT_X,7) -> 80 | E26: =INDEX(PT_P,7) -> 320 | F26: =INDEX(PT_FuelFac,7) -> 0.1122 | G26: =INDEX(PT_ProcFac,7) -> 0.9944125 | H26: =-LN(1-INDEX(PT_ER,7))/PStar -> 0.0078858436 | I26: =B26*(1+C26)^(Yr-BaseYr) -> 683.6859 | J26: =Tau*F26 -> 2.244 | K26: =$H$18*G26 -> 19.88825 | L26: =MIN($J$18,Tau)*F26+MIN($J$18,$H$18)*G26 -> 22.13225 | M26: =(J26+K26-L26)/E26 -> 0 | N26: =I26*(1+M26)^EpsQ -> 683.6859 | O26: =N26*F26/1000 -> 0.076709558 | P26: =N26*G26/1000 -> 0.67986581 | Q26: =EXP(Bf*(Tau+$L$18)) -> 0.95131318 | R26: =O26*(Q26-1) -> -0.0037347448 | S26: =-P26*(1-EXP(-H26*($H$18+$L$18))) -> -0.099198157 | T26: =O26+R26+P26+S26 -> 0.65364246 | U26: =(O26+P26)*(1-(1+M26)^(-EpsQ)) -> 0 | V26: =P26*(1-(1+M26)^(-EpsQ)) -> 0 | W26: =(O26+R26)*Tau -> 1.4594963 | X26: =(P26*(G26>0)+S26)*$H$18 -> 11.613353 | Y26: =L26*N26/1000 -> 15.131507 | Z26: =IF(N26>0,1000*T26/N26,0) -> 0.95605667 | AA26: =IF(N26>0,1000*(W26+X26)/N26-L26,0) -> -3.0111167 | AB26: =MAX(0,CBF*PEU*Z26-Ssel*MAX(0,AA26)) -> 95.605667 | AC26: =I26*(F26+G26)/1000 -> 0.75657537 | AD26: =I26*F26/1000 -> 0.076709558 | AE26: =I26*G26/1000 -> 0.67986581 | AF26: =D26*AB26 -> 7648.4533 | AG26: =D26*CBF*PEU*(F26+G26) -> 8852.9 | AH26: =O26+P26*(G26>0)*$B$18 -> 0.75657537
A27: =INDEX(PT_Name,8) -> Aluminium | B27: =INDEX(PT_Q0,8) -> 300 | C27: =INDEX(PT_Growth,8) -> 0.055 | D27: =INDEX(PT_X,8) -> 167 | E27: =INDEX(PT_P,8) -> 2400 | F27: =INDEX(PT_FuelFac,8) -> 0.12342 | G27: =INDEX(PT_ProcFac,8) -> 2.397493 | H27: =-LN(1-INDEX(PT_ER,8))/PStar -> 0.0019988245 | I27: =B27*(1+C27)^(Yr-BaseYr) -> 413.65284 | J27: =Tau*F27 -> 2.4684 | K27: =$H$18*G27 -> 47.949861 | L27: =MIN($J$18,Tau)*F27+MIN($J$18,$H$18)*G27 -> 50.418261 | M27: =(J27+K27-L27)/E27 -> 0 | N27: =I27*(1+M27)^EpsQ -> 413.65284 | O27: =N27*F27/1000 -> 0.051053034 | P27: =N27*G27/1000 -> 0.99172981 | Q27: =EXP(Bf*(Tau+$L$18)) -> 0.95131318 | R27: =O27*(Q27-1) -> -0.0024856101 | S27: =-P27*(1-EXP(-H27*($H$18+$L$18))) -> -0.038863881 | T27: =O27+R27+P27+S27 -> 1.0014334 | U27: =(O27+P27)*(1-(1+M27)^(-EpsQ)) -> 0 | V27: =P27*(1-(1+M27)^(-EpsQ)) -> 0 | W27: =(O27+R27)*Tau -> 0.97134847 | X27: =(P27*(G27>0)+S27)*$H$18 -> 19.057319 | Y27: =L27*N27/1000 -> 20.855657 | Z27: =IF(N27>0,1000*T27/N27,0) -> 2.4209512 | AA27: =IF(N27>0,1000*(W27+X27)/N27-L27,0) -> -1.9992364 | AB27: =MAX(0,CBF*PEU*Z27-Ssel*MAX(0,AA27)) -> 242.09512 | AC27: =I27*(F27+G27)/1000 -> 1.0427828 | AD27: =I27*F27/1000 -> 0.051053034 | AE27: =I27*G27/1000 -> 0.99172981 | AF27: =D27*AB27 -> 40429.885 | AG27: =D27*CBF*PEU*(F27+G27) -> 42099.248 | AH27: =O27+P27*(G27>0)*$B$18 -> 1.0427828
A28: Total | I28: =SUM(I20:I27) -> 79893.956 | N28: =SUM(N20:N27) -> 79893.956 | O28: =SUM(O20:O27) -> 27.602124 | P28: =SUM(P20:P27) -> 34.821485 | R28: =SUM(R20:R27) -> -1.3438598 | S28: =SUM(S20:S27) -> -2.2757201 | T28: =SUM(T20:T27) -> 58.80403 | U28: =SUM(U20:U27) -> 0 | V28: =SUM(V20:V27) -> 0 | W28: =SUM(W20:W27) -> 525.16529 | X28: =SUM(X20:X27) -> 650.91531 | Y28: =SUM(Y20:Y27) -> 1248.4722 | AC28: =SUM(AC20:AC27) -> 62.42361 | AD28: =SUM(AD20:AD27) -> 27.602124 | AE28: =SUM(AE20:AE27) -> 34.821485 | AF28: =SUM(AF20:AF27) -> 187858.86 | AG28: =SUM(AG20:AG27) -> 198629.92 | AH28: =SUM(AH20:AH27) -> 62.42361
A31: Bundle 3C (flag=1, theta=0, phi=1); 3A uses the 1A block
A32: flag | B32: 1 | C32: theta | D32: 0 | E32: phi | F32: 1 | G32: tau_p | H32: =Tau*B32 -> 20 | I32: OBR rate | J32: =D32*Tau -> 0 | K32: sigma_eff | L32: =F32*SigmaEff -> 20
A33: Product | B33: Q0 | C33: g | D33: X | E33: P | F33: F | G33: G | H33: beta | I33: Qb | J33: k_f | K33: k_p | L33: m (rebate/t) | M33: dp | N33: Q | O33: E_f | P33: E_p | Q33: x_f | R33: ER_f | S33: ER_p | T33: E_post | U33: emrq | V33: emrq_proc | W33: rev_f $m | X33: rev_p $m | Y33: rebate $m | Z33: EI | AA33: d | AB33: obl | AC33: E_base | AD33: E_f base | AE33: E_p base | AF33: X*obl | AG33: X*PEU*(F+G) | AH33: covered
A34: =INDEX(PT_Name,1) -> DRI-EAF steel | B34: =INDEX(PT_Q0,1) -> 5100 | C34: =INDEX(PT_Growth,1) -> 0.044 | D34: =INDEX(PT_X,1) -> 580 | E34: =INDEX(PT_P,1) -> 750 | F34: =INDEX(PT_FuelFac,1) -> 0.57099077 | G34: =INDEX(PT_ProcFac,1) -> 0.03790102 | H34: =-LN(1-INDEX(PT_ER,1))/PStar -> 0.0034469507 | I34: =B34*(1+C34)^(Yr-BaseYr) -> 6603.4846 | J34: =Tau*F34 -> 11.419815 | K34: =$H$32*G34 -> 0.7580204 | L34: =MIN($J$32,Tau)*F34+MIN($J$32,$H$32)*G34 -> 0 | M34: =(J34+K34-L34)/E34 -> 0.016237114 | N34: =I34*(1+M34)^EpsQ -> 6550.518 | O34: =N34*F34/1000 -> 3.7402853 | P34: =N34*G34/1000 -> 0.24827131 | Q34: =EXP(Bf*(Tau+$L$32)) -> 0.90499676 | R34: =O34*(Q34-1) -> -0.35533923 | S34: =-P34*(1-EXP(-H34*($H$32+$L$32))) -> -0.031976117 | T34: =O34+R34+P34+S34 -> 3.6012413 | U34: =(O34+P34)*(1-(1+M34)^(-EpsQ)) -> -0.032250937 | V34: =P34*(1-(1+M34)^(-EpsQ)) -> -0.0020074887 | W34: =(O34+R34)*Tau -> 67.698921 | X34: =(P34*(G34>0)+S34)*$H$32 -> 4.3259039 | Y34: =L34*N34/1000 -> 0 | Z34: =IF(N34>0,1000*T34/N34,0) -> 0.54976435 | AA34: =IF(N34>0,1000*(W34+X34)/N34-L34,0) -> 10.995287 | AB34: =MAX(0,CBF*PEU*Z34-Ssel*MAX(0,AA34)) -> 43.981148 | AC34: =I34*(F34+G34)/1000 -> 4.0208075 | AD34: =I34*F34/1000 -> 3.7705287 | AE34: =I34*G34/1000 -> 0.2502788 | AF34: =D34*AB34 -> 25509.066 | AG34: =D34*CBF*PEU*(F34+G34) -> 35315.724 | AH34: =O34+P34*(G34>0)*$B$32 -> 3.9885566
A35: =INDEX(PT_Name,2) -> Scrap-EAF steel | B35: =INDEX(PT_Q0,2) -> 4800 | C35: =INDEX(PT_Growth,2) -> 0.044 | D35: =INDEX(PT_X,2) -> 300 | E35: =INDEX(PT_P,2) -> 680 | F35: =INDEX(PT_FuelFac,2) -> 0.04488 | G35: =INDEX(PT_ProcFac,2) -> 0.04398115 | H35: =-LN(1-INDEX(PT_ER,2))/PStar -> 0.0016366491 | I35: =B35*(1+C35)^(Yr-BaseYr) -> 6215.0443 | J35: =Tau*F35 -> 0.8976 | K35: =$H$32*G35 -> 0.879623 | L35: =MIN($J$32,Tau)*F35+MIN($J$32,$H$32)*G35 -> 0 | M35: =(J35+K35-L35)/E35 -> 0.0026135632 | N35: =I35*(1+M35)^EpsQ -> 6206.9385 | O35: =N35*F35/1000 -> 0.2785674 | P35: =N35*G35/1000 -> 0.27298829 | Q35: =EXP(Bf*(Tau+$L$32)) -> 0.90499676 | R35: =O35*(Q35-1) -> -0.026464806 | S35: =-P35*(1-EXP(-H35*($H$32+$L$32))) -> -0.017299016 | T35: =O35+R35+P35+S35 -> 0.50779187 | U35: =(O35+P35)*(1-(1+M35)^(-EpsQ)) -> -0.00072029251 | V35: =P35*(1-(1+M35)^(-EpsQ)) -> -0.0003565033 | W35: =(O35+R35)*Tau -> 5.0420519 | X35: =(P35*(G35>0)+S35)*$H$32 -> 5.1137855 | Y35: =L35*N35/1000 -> 0 | Z35: =IF(N35>0,1000*T35/N35,0) -> 0.08181036 | AA35: =IF(N35>0,1000*(W35+X35)/N35-L35,0) -> 1.6362072 | AB35: =MAX(0,CBF*PEU*Z35-Ssel*MAX(0,AA35)) -> 6.5448288 | AC35: =I35*(F35+G35)/1000 -> 0.55227598 | AD35: =I35*F35/1000 -> 0.27893119 | AE35: =I35*G35/1000 -> 0.2733448 | AF35: =D35*AB35 -> 1963.4486 | AG35: =D35*CBF*PEU*(F35+G35) -> 2665.8345 | AH35: =O35+P35*(G35>0)*$B$32 -> 0.55155569
A36: =INDEX(PT_Name,3) -> BF-BOF steel | B36: =INDEX(PT_Q0,3) -> 0 | C36: =INDEX(PT_Growth,3) -> 0 | D36: =INDEX(PT_X,3) -> 0 | E36: =INDEX(PT_P,3) -> 620 | F36: =INDEX(PT_FuelFac,3) -> 1.4249803 | G36: =INDEX(PT_ProcFac,3) -> 0.05276542 | H36: =-LN(1-INDEX(PT_ER,3))/PStar -> 0.0026960723 | I36: =B36*(1+C36)^(Yr-BaseYr) -> 0 | J36: =Tau*F36 -> 28.499605 | K36: =$H$32*G36 -> 1.0553084 | L36: =MIN($J$32,Tau)*F36+MIN($J$32,$H$32)*G36 -> 0 | M36: =(J36+K36-L36)/E36 -> 0.047669216 | N36: =I36*(1+M36)^EpsQ -> 0 | O36: =N36*F36/1000 -> 0 | P36: =N36*G36/1000 -> 0 | Q36: =EXP(Bf*(Tau+$L$32)) -> 0.90499676 | R36: =O36*(Q36-1) -> 0 | S36: =-P36*(1-EXP(-H36*($H$32+$L$32))) -> 0 | T36: =O36+R36+P36+S36 -> 0 | U36: =(O36+P36)*(1-(1+M36)^(-EpsQ)) -> 0 | V36: =P36*(1-(1+M36)^(-EpsQ)) -> 0 | W36: =(O36+R36)*Tau -> 0 | X36: =(P36*(G36>0)+S36)*$H$32 -> 0 | Y36: =L36*N36/1000 -> 0 | Z36: =IF(N36>0,1000*T36/N36,0) -> 0 | AA36: =IF(N36>0,1000*(W36+X36)/N36-L36,0) -> 0 | AB36: =MAX(0,CBF*PEU*Z36-Ssel*MAX(0,AA36)) -> 0 | AC36: =I36*(F36+G36)/1000 -> 0 | AD36: =I36*F36/1000 -> 0 | AE36: =I36*G36/1000 -> 0 | AF36: =D36*AB36 -> 0 | AG36: =D36*CBF*PEU*(F36+G36) -> 0 | AH36: =O36+P36*(G36>0)*$B$32 -> 0
A37: =INDEX(PT_Name,4) -> Clinker | B37: =INDEX(PT_Q0,4) -> 50000 | C37: =INDEX(PT_Growth,4) -> 0.033 | D37: =INDEX(PT_X,4) -> 800 | E37: =INDEX(PT_P,4) -> 110 | F37: =INDEX(PT_FuelFac,4) -> 0.3135685 | G37: =INDEX(PT_ProcFac,4) -> 0.53702616 | H37: =-LN(1-INDEX(PT_ER,4))/PStar -> 0.0033464675 | I37: =B37*(1+C37)^(Yr-BaseYr) -> 60753.588 | J37: =Tau*F37 -> 6.27137 | K37: =$H$32*G37 -> 10.740523 | L37: =MIN($J$32,Tau)*F37+MIN($J$32,$H$32)*G37 -> 0 | M37: =(J37+K37-L37)/E37 -> 0.15465357 | N37: =I37*(1+M37)^EpsQ -> 56538.734 | O37: =N37*F37/1000 -> 17.728766 | P37: =N37*G37/1000 -> 30.362779 | Q37: =EXP(Bf*(Tau+$L$32)) -> 0.90499676 | R37: =O37*(Q37-1) -> -1.6842903 | S37: =-P37*(1-EXP(-H37*($H$32+$L$32))) -> -3.8040417 | T37: =O37+R37+P37+S37 -> 42.603213 | U37: =(O37+P37)*(1-(1+M37)^(-EpsQ)) -> -3.5851323 | V37: =P37*(1-(1+M37)^(-EpsQ)) -> -2.2634869 | W37: =(O37+R37)*Tau -> 320.88952 | X37: =(P37*(G37>0)+S37)*$H$32 -> 531.17475 | Y37: =L37*N37/1000 -> 0 | Z37: =IF(N37>0,1000*T37/N37,0) -> 0.75352259 | AA37: =IF(N37>0,1000*(W37+X37)/N37-L37,0) -> 15.070452 | AB37: =MAX(0,CBF*PEU*Z37-Ssel*MAX(0,AA37)) -> 60.281807 | AC37: =I37*(F37+G37)/1000 -> 51.676678 | AD37: =I37*F37/1000 -> 19.050412 | AE37: =I37*G37/1000 -> 32.626266 | AF37: =D37*AB37 -> 48225.446 | AG37: =D37*CBF*PEU*(F37+G37) -> 68047.573 | AH37: =O37+P37*(G37>0)*$B$32 -> 48.091545
A38: =INDEX(PT_Name,5) -> Ammonia | B38: =INDEX(PT_Q0,5) -> 1785 | C38: =INDEX(PT_Growth,5) -> 0.022 | D38: =INDEX(PT_X,5) -> 120 | E38: =INDEX(PT_P,5) -> 450 | F38: =INDEX(PT_FuelFac,5) -> 1.97472 | G38: =INDEX(PT_ProcFac,5) -> 0 | H38: =-LN(1-INDEX(PT_ER,5))/PStar -> 0.0028931766 | I38: =B38*(1+C38)^(Yr-BaseYr) -> 2033.9656 | J38: =Tau*F38 -> 39.4944 | K38: =$H$32*G38 -> 0 | L38: =MIN($J$32,Tau)*F38+MIN($J$32,$H$32)*G38 -> 0 | M38: =(J38+K38-L38)/E38 -> 0.087765333 | N38: =I38*(1+M38)^EpsQ -> 1950.1858 | O38: =N38*F38/1000 -> 3.8510709 | P38: =N38*G38/1000 -> 0 | Q38: =EXP(Bf*(Tau+$L$32)) -> 0.90499676 | R38: =O38*(Q38-1) -> -0.36586422 | S38: =-P38*(1-EXP(-H38*($H$32+$L$32))) -> 0 | T38: =O38+R38+P38+S38 -> 3.4852067 | U38: =(O38+P38)*(1-(1+M38)^(-EpsQ)) -> -0.16544158 | V38: =P38*(1-(1+M38)^(-EpsQ)) -> 0 | W38: =(O38+R38)*Tau -> 69.704133 | X38: =(P38*(G38>0)+S38)*$H$32 -> 0 | Y38: =L38*N38/1000 -> 0 | Z38: =IF(N38>0,1000*T38/N38,0) -> 1.7871152 | AA38: =IF(N38>0,1000*(W38+X38)/N38-L38,0) -> 35.742304 | AB38: =MAX(0,CBF*PEU*Z38-Ssel*MAX(0,AA38)) -> 142.96922 | AC38: =I38*(F38+G38)/1000 -> 4.0165125 | AD38: =I38*F38/1000 -> 4.0165125 | AE38: =I38*G38/1000 -> 0 | AF38: =D38*AB38 -> 17156.306 | AG38: =D38*CBF*PEU*(F38+G38) -> 23696.64 | AH38: =O38+P38*(G38>0)*$B$32 -> 3.8510709
A39: =INDEX(PT_Name,6) -> Urea | B39: =INDEX(PT_Q0,6) -> 2800 | C39: =INDEX(PT_Growth,6) -> 0.022 | D39: =INDEX(PT_X,6) -> 1600 | E39: =INDEX(PT_P,6) -> 380 | F39: =INDEX(PT_FuelFac,6) -> 0.1122 | G39: =INDEX(PT_ProcFac,6) -> 0 | H39: =-LN(1-INDEX(PT_ER,6))/PStar -> 0.0010087869 | I39: =B39*(1+C39)^(Yr-BaseYr) -> 3190.5342 | J39: =Tau*F39 -> 2.244 | K39: =$H$32*G39 -> 0 | L39: =MIN($J$32,Tau)*F39+MIN($J$32,$H$32)*G39 -> 0 | M39: =(J39+K39-L39)/E39 -> 0.0059052632 | N39: =I39*(1+M39)^EpsQ -> 3181.1553 | O39: =N39*F39/1000 -> 0.35692562 | P39: =N39*G39/1000 -> 0 | Q39: =EXP(Bf*(Tau+$L$32)) -> 0.90499676 | R39: =O39*(Q39-1) -> -0.033909091 | S39: =-P39*(1-EXP(-H39*($H$32+$L$32))) -> 0 | T39: =O39+R39+P39+S39 -> 0.32301653 | U39: =(O39+P39)*(1-(1+M39)^(-EpsQ)) -> -0.0010523186 | V39: =P39*(1-(1+M39)^(-EpsQ)) -> 0 | W39: =(O39+R39)*Tau -> 6.4603306 | X39: =(P39*(G39>0)+S39)*$H$32 -> 0 | Y39: =L39*N39/1000 -> 0 | Z39: =IF(N39>0,1000*T39/N39,0) -> 0.10154064 | AA39: =IF(N39>0,1000*(W39+X39)/N39-L39,0) -> 2.0308127 | AB39: =MAX(0,CBF*PEU*Z39-Ssel*MAX(0,AA39)) -> 8.1232509 | AC39: =I39*(F39+G39)/1000 -> 0.35797794 | AD39: =I39*F39/1000 -> 0.35797794 | AE39: =I39*G39/1000 -> 0 | AF39: =D39*AB39 -> 12997.201 | AG39: =D39*CBF*PEU*(F39+G39) -> 17952 | AH39: =O39+P39*(G39>0)*$B$32 -> 0.35692562
A40: =INDEX(PT_Name,7) -> Ammonium nitrate | B40: =INDEX(PT_Q0,7) -> 600 | C40: =INDEX(PT_Growth,7) -> 0.022 | D40: =INDEX(PT_X,7) -> 80 | E40: =INDEX(PT_P,7) -> 320 | F40: =INDEX(PT_FuelFac,7) -> 0.1122 | G40: =INDEX(PT_ProcFac,7) -> 0.9944125 | H40: =-LN(1-INDEX(PT_ER,7))/PStar -> 0.0078858436 | I40: =B40*(1+C40)^(Yr-BaseYr) -> 683.6859 | J40: =Tau*F40 -> 2.244 | K40: =$H$32*G40 -> 19.88825 | L40: =MIN($J$32,Tau)*F40+MIN($J$32,$H$32)*G40 -> 0 | M40: =(J40+K40-L40)/E40 -> 0.069163281 | N40: =I40*(1+M40)^EpsQ -> 661.20268 | O40: =N40*F40/1000 -> 0.074186941 | P40: =N40*G40/1000 -> 0.65750821 | Q40: =EXP(Bf*(Tau+$L$32)) -> 0.90499676 | R40: =O40*(Q40-1) -> -0.0070479999 | S40: =-P40*(1-EXP(-H40*($H$32+$L$32))) -> -0.17787412 | T40: =O40+R40+P40+S40 -> 0.54677304 | U40: =(O40+P40)*(1-(1+M40)^(-EpsQ)) -> -0.024880211 | V40: =P40*(1-(1+M40)^(-EpsQ)) -> -0.022357594 | W40: =(O40+R40)*Tau -> 1.3427788 | X40: =(P40*(G40>0)+S40)*$H$32 -> 9.5926819 | Y40: =L40*N40/1000 -> 0 | Z40: =IF(N40>0,1000*T40/N40,0) -> 0.82693711 | AA40: =IF(N40>0,1000*(W40+X40)/N40-L40,0) -> 16.538742 | AB40: =MAX(0,CBF*PEU*Z40-Ssel*MAX(0,AA40)) -> 66.154969 | AC40: =I40*(F40+G40)/1000 -> 0.75657537 | AD40: =I40*F40/1000 -> 0.076709558 | AE40: =I40*G40/1000 -> 0.67986581 | AF40: =D40*AB40 -> 5292.3975 | AG40: =D40*CBF*PEU*(F40+G40) -> 8852.9 | AH40: =O40+P40*(G40>0)*$B$32 -> 0.73169515
A41: =INDEX(PT_Name,8) -> Aluminium | B41: =INDEX(PT_Q0,8) -> 300 | C41: =INDEX(PT_Growth,8) -> 0.055 | D41: =INDEX(PT_X,8) -> 167 | E41: =INDEX(PT_P,8) -> 2400 | F41: =INDEX(PT_FuelFac,8) -> 0.12342 | G41: =INDEX(PT_ProcFac,8) -> 2.397493 | H41: =-LN(1-INDEX(PT_ER,8))/PStar -> 0.0019988245 | I41: =B41*(1+C41)^(Yr-BaseYr) -> 413.65284 | J41: =Tau*F41 -> 2.4684 | K41: =$H$32*G41 -> 47.949861 | L41: =MIN($J$32,Tau)*F41+MIN($J$32,$H$32)*G41 -> 0 | M41: =(J41+K41-L41)/E41 -> 0.021007609 | N41: =I41*(1+M41)^EpsQ -> 409.37519 | O41: =N41*F41/1000 -> 0.050525086 | P41: =N41*G41/1000 -> 0.98147418 | Q41: =EXP(Bf*(Tau+$L$32)) -> 0.90499676 | R41: =O41*(Q41-1) -> -0.004800047 | S41: =-P41*(1-EXP(-H41*($H$32+$L$32))) -> -0.07541672 | T41: =O41+R41+P41+S41 -> 0.9517825 | U41: =(O41+P41)*(1-(1+M41)^(-EpsQ)) -> -0.010783578 | V41: =P41*(1-(1+M41)^(-EpsQ)) -> -0.010255631 | W41: =(O41+R41)*Tau -> 0.91450079 | X41: =(P41*(G41>0)+S41)*$H$32 -> 18.121149 | Y41: =L41*N41/1000 -> 0 | Z41: =IF(N41>0,1000*T41/N41,0) -> 2.3249638 | AA41: =IF(N41>0,1000*(W41+X41)/N41-L41,0) -> 46.499276 | AB41: =MAX(0,CBF*PEU*Z41-Ssel*MAX(0,AA41)) -> 185.9971 | AC41: =I41*(F41+G41)/1000 -> 1.0427828 | AD41: =I41*F41/1000 -> 0.051053034 | AE41: =I41*G41/1000 -> 0.99172981 | AF41: =D41*AB41 -> 31061.516 | AG41: =D41*CBF*PEU*(F41+G41) -> 42099.248 | AH41: =O41+P41*(G41>0)*$B$32 -> 1.0319993
A42: Total | I42: =SUM(I34:I41) -> 79893.956 | N42: =SUM(N34:N41) -> 75498.11 | O42: =SUM(O34:O41) -> 26.080327 | P42: =SUM(P34:P41) -> 32.523021 | R42: =SUM(R34:R41) -> -2.4777156 | S42: =SUM(S34:S41) -> -4.1066077 | T42: =SUM(T34:T41) -> 52.019025 | U42: =SUM(U34:U41) -> -3.8202613 | V42: =SUM(V34:V41) -> -2.2984641 | W42: =SUM(W34:W41) -> 472.05223 | X42: =SUM(X34:X41) -> 568.32827 | Y42: =SUM(Y34:Y41) -> 0 | AC42: =SUM(AC34:AC41) -> 62.42361 | AD42: =SUM(AD34:AD41) -> 27.602124 | AE42: =SUM(AE34:AE41) -> 34.821485 | AF42: =SUM(AF34:AF41) -> 142205.38 | AG42: =SUM(AG34:AG41) -> 198629.92 | AH42: =SUM(AH34:AH41) -> 58.603349
