Workbook
Name BaseYr: Inputs!$D$37
Name BetaSet: Inputs!$D$10
Name Bf: Inputs!$D$33
Name BfScen: Inputs!$D$12
Name BT_Code: Inputs!$A$74:$A$79
Name BT_Flag: Inputs!$D$74:$D$79
Name BT_Phi: Inputs!$F$74:$F$79
Name BT_Recyc: Inputs!$H$74:$H$79
Name BT_Scen: Inputs!$B$74:$B$79
Name BT_Scope: Inputs!$C$74:$C$79
Name BT_Tau: Inputs!$G$74:$G$79
Name BT_Theta: Inputs!$E$74:$E$79
Name BT_Traj: Inputs!$I$74:$I$79
Name CBFsel: Inputs!$D$35
Name CBFyr: Inputs!$D$34
Name ChecksOverall: Checks!$D$23
Name Conv: Inputs!$D$7
Name CPO_Data: CPAT_Outputs!$E$4:$X$131
Name CPO_Keys: CPAT_Outputs!$C$4:$C$131
Name CPO_Years: CPAT_Outputs!$E$3:$X$3
Name CV_cptraj: Inputs!$C$49:$F$49
Name CV_deaths: Inputs!$C$64:$F$64
Name CV_denr: Inputs!$C$68:$F$68
Name CV_dghg: Inputs!$C$66:$F$66
Name CV_dind: Inputs!$C$69:$F$69
Name CV_dippu: Inputs!$C$67:$F$67
Name CV_drev: Inputs!$C$70:$F$70
Name CV_effcp: Inputs!$C$50:$F$50
Name CV_enr0: Inputs!$C$45:$F$45
Name CV_enr1: Inputs!$C$46:$F$46
Name CV_ghg0: Inputs!$C$41:$F$41
Name CV_ghg1: Inputs!$C$42:$F$42
Name CV_Hdr: Inputs!$C$40:$F$40
Name CV_ind0: Inputs!$C$47:$F$47
Name CV_ind1: Inputs!$C$48:$F$48
Name CV_ippu0: Inputs!$C$43:$F$43
Name CV_ippu1: Inputs!$C$44:$F$44
Name CV_kappa: Inputs!$C$65:$F$65
Name CV_mort: Inputs!$C$62:$F$62
Name CV_revctax: Inputs!$C$63:$F$63
Name CV_revnew0: Inputs!$C$51:$F$51
Name CV_revnew1: Inputs!$C$52:$F$52
Name EFSet: Inputs!$D$11
Name EpsF: Inputs!$D$20
Name EpsQ: Inputs!$D$22
Name EpsQ1: Inputs!$D$23
Name EpsQ2: Inputs!$D$24
Name EpsQ3: Inputs!$D$25
Name EpsQ4: Inputs!$D$26
Name EpsQ5: Inputs!$D$27
Name EpsQ6: Inputs!$D$28
Name EpsQ7: Inputs!$D$29
Name EpsQ8: Inputs!$D$30
Name EpsU: Inputs!$D$19
Name IppuOther: Inputs!$D$14
Name KappaMode: Inputs!$D$15
Name Mode: Inputs!$D$6
Name PEU: Inputs!$D$31
Name ProtoFail: Comparison!$D$208
Name ProtoPass: Comparison!$C$208

Sheet ReadMe
A1: AdHocCalculations - rebuild v0.5 (Egypt policy-options matrix, Table 2 of the results note)
A3: Purpose | B3: Transparent rebuild of AdHocCalculations.xlsb (PolicyMatrix tab) behind Table 2 of the Egypt results note. Every number on PolicyMatrix rows 7-12 is a formula reading Inputs / CPAT_Outputs / CBAM_Products / Results; nothing is typed.
A4: How to use | B4: Change assumptions ONLY on the Inputs tab (tan cells). Mode = REBUILD (default, coherent method) or PROTOTYPE (reproduces CPAT_Industry_Kernel_Egypt_v0.11 block exactly - verify on Comparison section 2 and Checks). Conv = CBAM convention for O (FULL default from v0.5). Yr = reporting year (2030 default).
A5: Sheets | B5: Inputs (all assumptions, switches, CPAT values for Yr, bundle table, product table, year vectors) | CPAT_Outputs (trimmed CPAT Outputs 2022-2041, 32 codes x 4 scenarios) | CBAM_Products (eight-product block per bundle, prototype v0.11 equations) | Results (engine: every metric by bundle, keyed) | PolicyMatrix (original layout, live) | Comparison (original / Table 2 / rebuilt / prototype) | Issues resolved (19 items) | Checks.
A6: Format changes vs original | B6: (1) Assumptions moved to Inputs (original had typed constants inside PolicyMatrix and a misaligned Inputs tab). (2) Columns AF-AQ redefined (yellow headers): the legacy half-elasticity block (AF-AP) is replaced by the K decomposition (AF-AM), export-weighted intensity change (AN), gross revenue (AO), rebates (AP) and O under FULL phase-in (AQ). (3) Rows 14-22 (non-modelled bundles) copied verbatim, grey, not recomputed. (4) Trajectory rows 26-29 rebuilt as contiguous years 2027-2034 in F-M, live from Inputs, plus a CBAM phase-in row. (5) Row 4 mode indicator added; C3 is a formula. (6) New sheets: CPAT_Outputs, CBAM_Products, Results, Comparison, Issues resolved, Checks. (7) GHG tab not rebuilt.
A7: Method differences vs original | B7: Single 2030 base (CPAT total GHG 594.2 Mt); coverage computed (kappa for partial industry runs); CBAM base bottom-up (62.42 Mt, eight products, Egypt CBAM EF v0.1); process response via beta and the output channel, CPAT's IPPU scaling removed; 1A on EG1; 3B from EG3 with explicit OBR output-channel correction; revenue = CPAT fuel receipts + block process revenue, net of rebates / fund; deaths rescaled by energy CO2 only; price start 2028; no untraceable constants; b_f calibrated on CPAT; O convention explicit.
A8: Method differences vs prototype v0.11 | B8: REBUILD mode adds: fuel-intensity channel xf = EXP(b_f (tau + fund)); IPCC-based process beta set (prototype set selectable); fund shadow price sigma on both channels; national totals from CPAT; OBR rebates in net revenue; kappa coverage; 3C differs from 3A. PROTOTYPE mode switches all of these off for the block.
A9: Provenance | B9: CPAT values: cpat_outputs_egypt_2022_2041.csv (CPAT Outputs sheet, Egypt EG1-EG4). Prototype: prototype_v0_11_results.json (run via Excel COM). Original: original_PolicyMatrix_cells.txt (verbatim dump). Builder: build_adhoc_rebuild_v0_5.py; verification: recalc_and_check_adhoc_v0_5.py (report recalc_and_check_adhoc_v0_5_report.txt). EFs: EmissionFactors/EGY_CBAM_EF_v0.1.xlsx. Methodology note (core equations, results, differences, open flags): MethodologyNote_v0.5.md / .docx.
A10: Colour code | B10: Tan = input; blue = key / identifier; green = computed; yellow = switch-dependent or review; grey = static copy.
A11: Version log | B11: v0.1 - first rebuild (openpyxl build, Excel COM verified). v0.2 - Egypt CBAM EF v0.1 (switch EFSet) and AN blended process ER100. v0.5 2026-10-04 - PStar = 122 USD2024 for IPCC beta sets, and KappaMode=SCALE default to approximate a full-coverage EG3 industry run pending a CPAT re-run. v0.5 - defaults Conv = FULL and ThetaOther = 1 (decisions 2026-10-04); no formula changes.

Sheet Inputs
A1: Inputs - all assumptions and switches (AdHoc Calculations rebuild v0.5)
A2: Edit only tan cells (switches) and light-green cells (inputs). Every other cell in the workbook is a formula. Defined names are listed in column E.
A4: A. Switches
A5: Switch | B5: Value (edit) | C5: Allowed values | D5: Effective (named) | E5: Name | F5: Notes
A6: Calculation mode | B6: REBUILD | C6: REBUILD, PROTOTYPE | D6: =UPPER(TRIM(B6)) -> REBUILD | E6: Mode | F6: REBUILD = coherent method (headline). PROTOTYPE = reproduce CPAT_Industry_Kernel_Egypt_v0.11 exactly (xf=1, prototype beta set, fund shadow price 0); verified cell by cell in Comparison section 2.
A7: CBAM obligation convention | B7: FULL | C7: FULL, NOPHASE, SCALED | D7: =UPPER(TRIM(B7)) -> FULL | E7: Conv | F7: FULL (default from v0.5): 2030 phase-in factor 0.485 on the obligation, full deduction of the carbon price paid. NOPHASE (memo; the default in v0.1-v0.3): full certificate price EUR/USD 100 with no phase-in, deduction of carbon price paid - the definition behind column O of the original (intensity + price credit). SCALED: phase-in on both obligation and deduction (prototype memo).
A8: Reporting year | B8: 2030 | C8: 2026 .. 2041 | D8: =B8 -> 2030 | E8: Yr | F8: All Table-2 metrics are for this year; CPAT values are looked up live for it.
A9: Fund shadow price sigma ($/tCO2) for bundle 3C | B9: 20 | C9: >= 0 | D9: =IF(Mode="PROTOTYPE",0,B9) -> 20 | E9: SigmaEff | F9: Abatement-fund payments modelled as a shadow price added to the carbon price in the fuel-intensity and process-intensity responses (TechNote: fund enters the efficiency term only). 0 in PROTOTYPE mode.
A10: Process half-elasticity (beta) set | B10: IPCC_CENTRAL | C10: IPCC_CENTRAL, IPCC_2030, IPCC_LONGRUN, PROTOTYPE | D10: =IF(Mode="PROTOTYPE","PROTOTYPE",UPPER(TRIM(B10))) -> IPCC_CENTRAL | E10: BetaSet | F10: beta_s = -LN(1-ER100_s)/100 from IPCC MACC bands (TASK-D drop-in). PROTOTYPE set forced in PROTOTYPE mode.
A11: Emission-factor set (fc, fp, np, no) | B11: EGY_EF_V01 | C11: EGY_EF_V01, PROTOTYPE | D11: =IF(Mode="PROTOTYPE","PROTOTYPE",UPPER(TRIM(B11))) -> EGY_EF_V01 | E11: EFSet | F11: EGY_EF_V01 = Egypt CBAM EF v0.1 (EmissionFactors/EGY_CBAM_EF_v0.1.xlsx; urea CBAM rule np = 0; AN integrated HNO3 N2O in no). PROTOTYPE = kernel v0.11 EFs (Inputs E, columns R:U); forced in PROTOTYPE mode.
A12: CPAT scenario used to calibrate the fuel-intensity semi-elasticity b_f | B12: EG1 | C12: EG1, EG2, EG3 | D12: =UPPER(TRIM(B12)) -> EG1 | E12: BfScen | F12: b_f = s_int * LN(ind.2/ind.1) / price (section B). EG1 is the economy-wide $20 run.
A13: OBR rebate (3B) also for non-CBAM priced industry? (0 = CBAM producers only) | B13: 1 | C13: 0, 1 | D13: =IF(Mode="PROTOTYPE",0,B13) -> 1 | E13: ThetaOther | F13: Default 1 from v0.5 (decision 2026-10-04); forced 0 in PROTOTYPE mode. Original 3B text says 'free allocation for CBAM producers'. 0 keeps revenue from non-CBAM industry (3B raises revenue); 1 rebates all covered industry (output channel removed everywhere, revenue ~0).
A14: Non-CBAM IPPU response to a fuel-only price | B14: NONE | C14: NONE, CPAT | D14: =UPPER(TRIM(B14)) -> NONE | E14: IppuOther | F14: CPAT scales all IPPU with industrial energy CO2 (MajorIssues #17). NONE removes it (process emissions respond only where priced or via output); CPAT keeps CPAT's scaling for the non-CBAM IPPU remainder.
A15: Coverage factor kappa / EG3 full-coverage approximation | B15: SCALE | C15: SCALE, AUTO, ONE | D15: =UPPER(TRIM(B15)) -> SCALE | E15: KappaMode | F15: SCALE (default): approximation of a full-coverage EG3 run (pending a CPAT re-run), scaling EG3 industry energy responses and fuel receipts by 1/kappa while coverage J uses kappa = 1. AUTO: expose CPAT's partial coverage. ONE: assume CPAT was already full coverage without scaling.
A17: B. Core parameters
A18: Parameter | B18: Value (edit) | C18: Unit | D18: Effective / derived (named) | E18: Name | F18: Source / notes
A19: Own-price elasticity of industrial output demand (eps_U) | B19: -0.5 | C19: - | D19: =B19 -> -0.5 | E19: EpsU | F19: TechNote App. A (CPAT industry fuel-demand split).
A20: Price elasticity of fuel intensity (eps_F) | B20: -0.5 | C20: - | D20: =B20 -> -0.5 | E20: EpsF | F20: TechNote App. A.
A21: Intensity share of the CPAT industrial fuel response s_int | B21: (derived) | C21: - | D21: =EpsF*(1+EpsU)/(EpsU+EpsF*(1+EpsU)) -> 0.33333333 | E21: SInt | F21: TechNote App. A: eps_F(1+eps_U)/(eps_U+eps_F(1+eps_U)); = 1/3 at -0.5/-0.5 (the '(2/3)/0.5' of K11 is the output share divided by |eps|). Output share = 1 - s_int.
A22: CBAM-product output response to cost pass-through (eps, prototype) | B22: -0.5 | C22: - | D22: =B22 -> -0.5 | E22: EpsQ | F22: Prototype v0.11 Manual inputs. Q = Q_base * (1 + dp)^eps with dp = net carbon cost / product price.
A23: Output response eps, DRI-EAF steel | B23: -0.4 | C23: - | D23: =IF(Mode="PROTOTYPE",EpsQ,B23) -> -0.4 | E23: EpsQ1 | F23: OutputElasticity_Note_v0.1 (PROTOTYPE mode: uniform EpsQ = -0.5).
A24: Output response eps, Scrap-EAF steel | B24: -0.4 | C24: - | D24: =IF(Mode="PROTOTYPE",EpsQ,B24) -> -0.4 | E24: EpsQ2 | F24: OutputElasticity_Note_v0.1 (PROTOTYPE mode: uniform EpsQ = -0.5).
A25: Output response eps, BF-BOF steel | B25: -0.4 | C25: - | D25: =IF(Mode="PROTOTYPE",EpsQ,B25) -> -0.4 | E25: EpsQ3 | F25: OutputElasticity_Note_v0.1 (PROTOTYPE mode: uniform EpsQ = -0.5).
A26: Output response eps, Clinker (cement) | B26: -0.1 | C26: - | D26: =IF(Mode="PROTOTYPE",EpsQ,B26) -> -0.1 | E26: EpsQ4 | F26: OutputElasticity_Note_v0.1 (PROTOTYPE mode: uniform EpsQ = -0.5).
A27: Output response eps, Ammonia | B27: -0.4 | C27: - | D27: =IF(Mode="PROTOTYPE",EpsQ,B27) -> -0.4 | E27: EpsQ5 | F27: OutputElasticity_Note_v0.1 (PROTOTYPE mode: uniform EpsQ = -0.5).
A28: Output response eps, Urea | B28: -0.4 | C28: - | D28: =IF(Mode="PROTOTYPE",EpsQ,B28) -> -0.4 | E28: EpsQ6 | F28: OutputElasticity_Note_v0.1 (PROTOTYPE mode: uniform EpsQ = -0.5).
A29: Output response eps, Ammonium nitrate | B29: -0.4 | C29: - | D29: =IF(Mode="PROTOTYPE",EpsQ,B29) -> -0.4 | E29: EpsQ7 | F29: OutputElasticity_Note_v0.1 (PROTOTYPE mode: uniform EpsQ = -0.5).
A30: Output response eps, Aluminium | B30: -0.5 | C30: - | D30: =IF(Mode="PROTOTYPE",EpsQ,B30) -> -0.5 | E30: EpsQ8 | F30: OutputElasticity_Note_v0.1 (PROTOTYPE mode: uniform EpsQ = -0.5).
A31: CBAM certificate price (EU ETS proxy) | B31: 100 | C31: $/tCO2 | D31: =B31 -> 100 | E31: PEU | F31: Prototype v0.11 (T79).
A32: IPCC process semi-elasticity anchor price P* (USD2024/tCO2) | B32: 122 | C32: $/tCO2 | D32: =B32 -> 122 | E32: PStar | F32: USD2019 100 deflated to USD2024 (US GDP deflator ≈ 1.22); Medium confidence. Used only for IPCC beta sets: beta = -LN(1-ER100)/P*. PROTOTYPE mode / BetaSet = PROTOTYPE keeps the old /100 divisor.
A33: Fuel-intensity semi-elasticity b_f (derived) | B33: (derived) | C33: 1/($/tCO2) | D33: =SInt*LN(INDEX(CV_ind1,MATCH(BfScen,CV_Hdr,0))/INDEX(CV_ind0,MATCH(BfScen,CV_Hdr,0)))/INDEX(CV_cptraj,MATCH(BfScen,CV_Hdr,0)) -> -0.0024955979 | E33: Bf | F33: Replaces the untraceable -0.549%/2 per $ of the original (AF7). Fuel intensity factor xf = EXP(b_f * (carbon price + fund shadow price)); EG1 gives -0.00250 (original -0.00274).
A34: CBAM phase-in factor in the reporting year (derived) | B34: (derived) | C34: - | D34: =INDEX(YV_CBF,MATCH(Yr,YV_Years,0)) -> 0.485 | E34: CBFyr | F34: From section F (EU CBAM definitive-period phase-in: 2.5% 2026 .. 100% 2034).
A35: Phase-in factor applied to the obligation under the selected convention | B35: (derived) | C35: - | D35: =IF(Conv="NOPHASE",1,CBFyr) -> 0.485 | E35: CBFsel | F35: NOPHASE -> 1; FULL / SCALED -> CBFyr.
A36: Scale applied to the carbon-price deduction under the selected convention | B36: (derived) | C36: - | D36: =IF(Conv="SCALED",CBFyr,1) -> 1 | E36: Ssel | F36: SCALED -> CBFyr; otherwise 1 (full deduction of the carbon price paid).
A37: Base year of the product activity data Q0 | B37: 2024 | C37: year | D37: =B37 -> 2024 | E37: BaseYr | F37: Prototype v0.11 Manual inputs.
A39: C. CPAT values in the reporting year (live lookups into CPAT_Outputs; nothing typed)
A40: Quantity | B40: CPAT code | C40: EG1 | D40: EG2 | E40: EG3 | F40: EG4 | G40: Unit | H40: Notes
A41: Total GHG incl. LULUCF - baseline | B41: egy.mit.ghg.tot.inc.1 | C41: =INDEX(CPO_Data,MATCH($B41&"|"&C$40,CPO_Keys,0),MATCH(Yr,CPO_Years,0)) -> 594.156 | D41: =INDEX(CPO_Data,MATCH($B41&"|"&D$40,CPO_Keys,0),MATCH(Yr,CPO_Years,0)) -> 594.156 | E41: =INDEX(CPO_Data,MATCH($B41&"|"&E$40,CPO_Keys,0),MATCH(Yr,CPO_Years,0)) -> 594.156 | F41: =INDEX(CPO_Data,MATCH($B41&"|"&F$40,CPO_Keys,0),MATCH(Yr,CPO_Years,0)) -> 594.156 | G41: MtCO2e
A42: Total GHG incl. LULUCF - policy | B42: egy.mit.ghg.tot.inc.2 | C42: =INDEX(CPO_Data,MATCH($B42&"|"&C$40,CPO_Keys,0),MATCH(Yr,CPO_Years,0)) -> 555.279 | D42: =INDEX(CPO_Data,MATCH($B42&"|"&D$40,CPO_Keys,0),MATCH(Yr,CPO_Years,0)) -> 553.154 | E42: =INDEX(CPO_Data,MATCH($B42&"|"&E$40,CPO_Keys,0),MATCH(Yr,CPO_Years,0)) -> 572.614 | F42: =INDEX(CPO_Data,MATCH($B42&"|"&F$40,CPO_Keys,0),MATCH(Yr,CPO_Years,0)) -> 584.539 | G42: MtCO2e
A43: IPPU GHG - baseline | B43: egy.mit.ghg.ipr.tot.1 | C43: =INDEX(CPO_Data,MATCH($B43&"|"&C$40,CPO_Keys,0),MATCH(Yr,CPO_Years,0)) -> 85.97 | D43: =INDEX(CPO_Data,MATCH($B43&"|"&D$40,CPO_Keys,0),MATCH(Yr,CPO_Years,0)) -> 85.97 | E43: =INDEX(CPO_Data,MATCH($B43&"|"&E$40,CPO_Keys,0),MATCH(Yr,CPO_Years,0)) -> 85.97 | F43: =INDEX(CPO_Data,MATCH($B43&"|"&F$40,CPO_Keys,0),MATCH(Yr,CPO_Years,0)) -> 85.97 | G43: MtCO2e
...

Sheet CPAT_Outputs
A1: CPAT_Outputs - trimmed CPAT 'Outputs' sheet (Egypt, scenarios EG1..EG4, 2022-2041)
A2: Provenance: CPAT Outputs sheet read via Excel COM (cpat_outputs_egypt_2022_2041.csv in this folder). Values are static data; the rest of the workbook reads them via INDEX/MATCH on the key column C (= code|scenario) and the year header. Mt for emissions, $bn for revenues, $/tCO2 for prices, deaths for air pollution.
A3: CPAT code | B3: Scenario | C3: Key (code|scenario) | D3: Label | E3: 2022 | F3: 2023 | G3: 2024 | H3: 2025 | I3: 2026 | J3: 2027 | K3: 2028 | L3: 2029 | M3: 2030 | N3: 2031 | O3: 2032 | P3: 2033 | Q3: 2034 | R3: 2035 | S3: 2036 | T3: 2037 | U3: 2038 | V3: 2039 | W3: 2040 | X3: 2041
A4: egy.mit.ghg.tot.inc.1 | B4: EG1 | C4: egy.mit.ghg.tot.inc.1|EG1 | D4: Total GHG emissions, inc. LULUCF (baseline) | E4: 400.912 | F4: 417.878 | G4: 450.28 | H4: 474.668 | I4: 488.837 | J4: 507.334 | K4: 531.747 | L4: 560.636 | M4: 594.156 | N4: 637.812 | O4: 701.794 | P4: 772.315 | Q4: 835.748 | R4: 906.166 | S4: 983.294 | T4: 1067.761 | U4: 1160.053 | V4: 1260.639 | W4: 1370.044 | X4: 1487.858
A5: egy.mit.ghg.tot.inc.1 | B5: EG2 | C5: egy.mit.ghg.tot.inc.1|EG2 | D5: Total GHG emissions, inc. LULUCF (baseline) | E5: 400.912 | F5: 417.878 | G5: 450.28 | H5: 474.668 | I5: 488.837 | J5: 507.334 | K5: 531.747 | L5: 560.636 | M5: 594.156 | N5: 637.812 | O5: 701.794 | P5: 772.315 | Q5: 835.748 | R5: 906.166 | S5: 983.294 | T5: 1067.761 | U5: 1160.053 | V5: 1260.639 | W5: 1370.044 | X5: 1487.858
A6: egy.mit.ghg.tot.inc.1 | B6: EG3 | C6: egy.mit.ghg.tot.inc.1|EG3 | D6: Total GHG emissions, inc. LULUCF (baseline) | E6: 400.912 | F6: 417.878 | G6: 450.28 | H6: 474.668 | I6: 488.837 | J6: 507.334 | K6: 531.747 | L6: 560.636 | M6: 594.156 | N6: 637.812 | O6: 701.794 | P6: 772.315 | Q6: 835.748 | R6: 906.166 | S6: 983.294 | T6: 1067.761 | U6: 1160.053 | V6: 1260.639 | W6: 1370.044 | X6: 1487.858
A7: egy.mit.ghg.tot.inc.1 | B7: EG4 | C7: egy.mit.ghg.tot.inc.1|EG4 | D7: Total GHG emissions, inc. LULUCF (baseline) | E7: 400.912 | F7: 417.878 | G7: 450.28 | H7: 474.668 | I7: 488.837 | J7: 507.334 | K7: 531.747 | L7: 560.636 | M7: 594.156 | N7: 637.812 | O7: 701.794 | P7: 772.315 | Q7: 835.748 | R7: 906.166 | S7: 983.294 | T7: 1067.761 | U7: 1160.053 | V7: 1260.639 | W7: 1370.044 | X7: 1487.858
A8: egy.mit.ghg.tot.inc.2 | B8: EG1 | C8: egy.mit.ghg.tot.inc.2|EG1 | D8: Total GHG emissions, inc. LULUCF (policy) | E8: 400.912 | F8: 417.779 | G8: 450.165 | H8: 474.557 | I8: 488.728 | J8: 507.156 | K8: 497.15 | L8: 517.963 | M8: 555.279 | N8: 598.301 | O8: 667.417 | P8: 723.178 | Q8: 784.768 | R8: 853.19 | S8: 928.765 | T8: 1012.007 | U8: 1103.439 | V8: 1203.523 | W8: 1312.661 | X8: 1430.405
A9: egy.mit.ghg.tot.inc.2 | B9: EG2 | C9: egy.mit.ghg.tot.inc.2|EG2 | D9: Total GHG emissions, inc. LULUCF (policy) | E9: 400.912 | F9: 417.779 | G9: 450.165 | H9: 474.557 | I9: 488.728 | J9: 507.156 | K9: 497.15 | L9: 516.832 | M9: 553.154 | N9: 594.932 | O9: 662.986 | P9: 718.691 | Q9: 779.162 | R9: 846.238 | S9: 920.219 | T9: 1001.454 | U9: 1090.415 | V9: 1187.592 | W9: 1293.482 | X9: 1407.72
A10: egy.mit.ghg.tot.inc.2 | B10: EG3 | C10: egy.mit.ghg.tot.inc.2|EG3 | D10: Total GHG emissions, inc. LULUCF (policy) | E10: 400.912 | F10: 417.874 | G10: 450.275 | H10: 474.663 | I10: 488.833 | J10: 507.294 | K10: 525.956 | L10: 546.53 | M10: 572.614 | N10: 607.838 | O10: 668.18 | P10: 713.418 | Q10: 765.05 | R10: 823.144 | S10: 887.994 | T10: 959.818 | U10: 1039.175 | V10: 1126.569 | W10: 1222.516 | X10: 1326.681
A11: egy.mit.ghg.tot.inc.2 | B11: EG4 | C11: egy.mit.ghg.tot.inc.2|EG4 | D11: Total GHG emissions, inc. LULUCF (policy) | E11: 400.912 | F11: 417.878 | G11: 450.28 | H11: 474.668 | I11: 488.837 | J11: 507.334 | K11: 531.747 | L11: 554.161 | M11: 584.539 | N11: 625.259 | O11: 679.525 | P11: 752.918 | Q11: 812.118 | R11: 877.489 | S11: 949.235 | T11: 1028.243 | U11: 1115.514 | V11: 1212.299 | W11: 1320.263 | X11: 1435.074
A12: egy.mit.ghg.ipr.tot.1 | B12: EG1 | C12: egy.mit.ghg.ipr.tot.1|EG1 | D12: Industrial processes GHG emissions (baseline) | E12: 52.2 | F12: 56.903 | G12: 67.485 | H12: 72.938 | I12: 75.02 | J12: 77.455 | K12: 80.412 | L12: 83.271 | M12: 85.97 | N12: 88.71 | O12: 91.479 | P12: 94.297 | Q12: 97.164 | R12: 100.08 | S12: 103.044 | T12: 106.056 | U12: 109.115 | V12: 112.221 | W12: 115.374 | X12: 118.573
A13: egy.mit.ghg.ipr.tot.1 | B13: EG2 | C13: egy.mit.ghg.ipr.tot.1|EG2 | D13: Industrial processes GHG emissions (baseline) | E13: 52.2 | F13: 56.903 | G13: 67.485 | H13: 72.938 | I13: 75.02 | J13: 77.455 | K13: 80.412 | L13: 83.271 | M13: 85.97 | N13: 88.71 | O13: 91.479 | P13: 94.297 | Q13: 97.164 | R13: 100.08 | S13: 103.044 | T13: 106.056 | U13: 109.115 | V13: 112.221 | W13: 115.374 | X13: 118.573
A14: egy.mit.ghg.ipr.tot.1 | B14: EG3 | C14: egy.mit.ghg.ipr.tot.1|EG3 | D14: Industrial processes GHG emissions (baseline) | E14: 52.2 | F14: 56.903 | G14: 67.485 | H14: 72.938 | I14: 75.02 | J14: 77.455 | K14: 80.412 | L14: 83.271 | M14: 85.97 | N14: 88.71 | O14: 91.479 | P14: 94.297 | Q14: 97.164 | R14: 100.08 | S14: 103.044 | T14: 106.056 | U14: 109.115 | V14: 112.221 | W14: 115.374 | X14: 118.573
... A131: egy.air.cad.net | B131: EG4 | C131: egy.air.cad.net|EG4 | D131: Cumulative averted deaths - net | E131: 0 | F131: 0 | G131: 0 | H131: 0 | I131: 0 | J131: 0 | K131: 0 | L131: 112 | M131: 326 | N131: 663 | O131: 2939 | P131: 5359 | Q131: 7484 | R131: 9984 | S131: 12409 | T131: 14737 | U131: 17281 | V131: 19710 | W131: 22213 | X131: 0

Sheet CBAM_Products
A1: CBAM_Products - product-level engine, one block per bundle (eight CBAM goods)
A2: Each block: row 1 scalars (from Inputs), rows 2-9 products, row 10 totals. Units: Q kt, emissions MtCO2(e), revenues and rebates $m, prices $/t, obligations $/t of product. Formulas are the prototype's (cost pass-through dp -> output Q = Qb(1+dp)^eps; process intensity via beta; CBAM obligation per tonne obl = MAX(0, CBF*P_EU*EI - S*MAX(0,d)) with d = carbon price paid net of rebate per tonne) plus the fuel-intensity factor xf (REBUILD only; = 1 in PROTOTYPE mode).
A4: Bundle 1A - Economy-wide fuel levy (EG1) + CBAM process emissions priced. Original used EG2 values (MajorIssues #3).
A5: Bundle | B5: tau: carbon price | C5: tau_p: process price | D5: obrrb: OBR rebate rate | E5: fundsp: fund shadow price | F5: incl_f | G5: incl_p | H5: xf: fuel-intensity factor | I5: CBF (selected conv.) | J5: P_EU | K5: S (selected conv.) | L5: CBF (FULL) | M5: CBF (NOPHASE) | N5: Year | O5: CPAT scenario | P5: b_f | Q5: beta set | R5: Mode
A6: 1A | B6: =INDEX(BT_Tau,MATCH($A$6,BT_Code,0)) -> 20 | C6: =B6*INDEX(BT_Flag,MATCH($A$6,BT_Code,0)) -> 20 | D6: =INDEX(BT_Theta,MATCH($A$6,BT_Code,0))*B6 -> 0 | E6: =INDEX(BT_Phi,MATCH($A$6,BT_Code,0))*SigmaEff -> 0 | F6: 1 | G6: =INDEX(BT_Flag,MATCH($A$6,BT_Code,0)) -> 1 | H6: =IF(Mode="PROTOTYPE",1,EXP(Bf*(F6*B6+E6))) -> 0.95131318 | I6: =CBFsel -> 0.485 | J6: =PEU -> 100 | K6: =Ssel -> 1 | L6: =CBFyr -> 0.485 | M6: 1 | N6: =Yr -> 2030 | O6: =INDEX(BT_Scen,MATCH($A$6,BT_Code,0)) -> EG1 | P6: =Bf -> -0.0024955979 | Q6: =BetaSet -> IPCC_CENTRAL | R6: =Mode -> REBUILD
A7: Product | B7: Q0 (kt) | C7: g | D7: X exports (kt) | E7: P ($/t) | F7: F (tCO2/t) | G7: G (tCO2e/t) | H7: beta | I7: Qb: baseline output | J7: kf: fuel cost $/t | K7: kp: process cost $/t | L7: m: rebate $/t | M7: dp: cost/price | N7: Q: output | O7: Ef: fuel emis. | P7: Ep: process emis. | Q7: ER_f: fuel-int. resp. | R7: ER_p: process-int. resp. | S7: post fuel | T7: post process | U7: post total | V7: emrq_i: output ch. | W7: emrq_proc_i | X7: J_i: process>0 | Y7: revf_i $m | Z7: revp_i $m | AA7: rev_i $m | AB7: rebate_i $m | AC7: EI: tCO2/t | AD7: d: net price paid $/t | AE7: obl (sel.) $/t | AF7: obl (FULL) $/t | AG7: obl (NOPHASE) $/t | AH7: cbobl_i $m | AI7: cbobl0_i $m | AJ7: w_den sel | AK7: w_den FULL | AL7: w_den NOPHASE | AM7: w_num sel | AN7: w_num FULL | AO7: w_num NOPHASE | AP7: X*post/Q | AQ7: X*(Ef+Ep)/Q | AR7: X*covered/Q | AS7: covered_i | AT7: Ebase_i | AU7: Efbase_i | AV7: Epbase_i
A8: =Inputs!$A$83 -> DRI-EAF steel | B8: =Inputs!$B$83 -> 5100 | C8: =Inputs!$C$83 -> 0.044 | D8: =Inputs!$D$83 -> 580 | E8: =Inputs!$E$83 -> 750 | F8: =Inputs!$J$83 -> 0.57099077 | G8: =Inputs!$K$83 -> 0.03790102 | H8: =Inputs!$Q$83 -> 0.0034469507 | I8: =B8*(1+C8)^($N$6-BaseYr) -> 6603.4846 | J8: =$F$6*$B$6*F8 -> 11.419815 | K8: =$G$6*$C$6*G8 -> 0.7580204 | L8: =MIN($D$6,$B$6)*$F$6*F8+MIN($D$6,$C$6)*$G$6*G8 -> 0 | M8: =IF(E8>0,(J8+K8-L8)/E8,0) -> 0.016237114 | N8: =I8*(1+M8)^EpsQ1 -> 6561.0772 | O8: =N8*F8/1000 -> 3.7463145 | P8: =N8*G8/1000 -> 0.24867152 | Q8: =O8*($H$6-1) -> -0.18239616 | R8: =-P8*(1-EXP(-H8*($G$6*$C$6+$E$6))) -> -0.016565601 | S8: =O8+Q8 -> 3.5639184 | T8: =P8+R8 -> 0.23210592 | U8: =S8+T8 -> 3.7960243 | V8: =(O8+P8)*(1-(1+M8)^(-EpsQ1)) -> -0.025821511 | W8: =P8*(1-(1+M8)^(-EpsQ1)) -> -0.0016072833 | X8: =IF(G8>0,1,0) -> 1 | Y8: =S8*$F$6*$B$6 -> 71.278367 | Z8: =(P8*X8+R8)*$G$6*$C$6 -> 4.6421183 | AA8: =Y8+Z8 -> 75.920486 | AB8: =L8*N8/1000 -> 0 | AC8: =IF(N8>0,U8*1000/N8,0) -> 0.57856723 | AD8: =IF(N8>0,AA8*1000/N8-L8,0) -> 11.571345 | AE8: =MAX(0,$I$6*$J$6*AC8-$K$6*MAX(0,AD8)) -> 16.489166 | AF8: =MAX(0,$L$6*$J$6*AC8-MAX(0,AD8)) -> 16.489166 | AG8: =MAX(0,$M$6*$J$6*AC8-MAX(0,AD8)) -> 46.285379 | AH8: =IF(B8>0,D8*N8/B8*AE8/1000,0) -> 12.303585 | AI8: =D8*(1+C8)^($N$6-BaseYr)*$I$6*$J$6*(F8+G8)/1000 -> 22.177513 | AJ8: =D8*$I$6*$J$6*(F8+G8) -> 17128.126 | AK8: =D8*$L$6*$J$6*(F8+G8) -> 17128.126 | AL8: =D8*$M$6*$J$6*(F8+G8) -> 35315.724 | AM8: =D8*AE8 -> 9563.7164 | AN8: =D8*AF8 -> 9563.7164 | AO8: =D8*AG8 -> 26845.52 | AP8: =IF(N8>0,D8*U8/N8,0) -> 0.335569 | AQ8: =IF(N8>0,D8*(O8+P8)/N8,0) -> 0.35315724 | AR8: =IF(N8>0,D8*AS8/N8,0) -> 0.35315724 | AS8: =O8*IF($F$6>0,1,0)+P8*X8*IF($G$6>0,1,0) -> 3.994986 | AT8: =I8*(F8+G8)/1000 -> 4.0208075 | AU8: =I8*F8/1000 -> 3.7705287 | AV8: =I8*G8/1000 -> 0.2502788
A9: =Inputs!$A$84 -> Scrap-EAF steel | B9: =Inputs!$B$84 -> 4800 | C9: =Inputs!$C$84 -> 0.044 | D9: =Inputs!$D$84 -> 300 | E9: =Inputs!$E$84 -> 680 | F9: =Inputs!$J$84 -> 0.04488 | G9: =Inputs!$K$84 -> 0.04398115 | H9: =Inputs!$Q$84 -> 0.0016366491 | I9: =B9*(1+C9)^($N$6-BaseYr) -> 6215.0443 | J9: =$F$6*$B$6*F9 -> 0.8976 | K9: =$G$6*$C$6*G9 -> 0.879623 | L9: =MIN($D$6,$B$6)*$F$6*F9+MIN($D$6,$C$6)*$G$6*G9 -> 0 | M9: =IF(E9>0,(J9+K9-L9)/E9,0) -> 0.0026135632 | N9: =I9*(1+M9)^EpsQ2 -> 6208.5588 | O9: =N9*F9/1000 -> 0.27864012 | P9: =N9*G9/1000 -> 0.27305956 | Q9: =O9*($H$6-1) -> -0.013566103 | R9: =-P9*(1-EXP(-H9*($G$6*$C$6+$E$6))) -> -0.0087933523 | S9: =O9+Q9 -> 0.26507402 | T9: =P9+R9 -> 0.2642662 | U9: =S9+T9 -> 0.52934022 | V9: =(O9+P9)*(1-(1+M9)^(-EpsQ2)) -> -0.0005763092 | W9: =P9*(1-(1+M9)^(-EpsQ2)) -> -0.00028523986 | X9: =IF(G9>0,1,0) -> 1 | Y9: =S9*$F$6*$B$6 -> 5.3014803 | Z9: =(P9*X9+R9)*$G$6*$C$6 -> 5.2853241 | AA9: =Y9+Z9 -> 10.586804 | AB9: =L9*N9/1000 -> 0 | AC9: =IF(N9>0,U9*1000/N9,0) -> 0.085259758 | AD9: =IF(N9>0,AA9*1000/N9-L9,0) -> 1.7051952 | AE9: =MAX(0,$I$6*$J$6*AC9-$K$6*MAX(0,AD9)) -> 2.4299031 | AF9: =MAX(0,$L$6*$J$6*AC9-MAX(0,AD9)) -> 2.4299031 | AG9: =MAX(0,$M$6*$J$6*AC9-MAX(0,AD9)) -> 6.8207806 | AH9: =IF(B9>0,D9*N9/B9*AE9/1000,0) -> 0.94288727 | AI9: =D9*(1+C9)^($N$6-BaseYr)*$I$6*$J$6*(F9+G9)/1000 -> 1.6740866 | AJ9: =D9*$I$6*$J$6*(F9+G9) -> 1292.9297 | AK9: =D9*$L$6*$J$6*(F9+G9) -> 1292.9297 | AL9: =D9*$M$6*$J$6*(F9+G9) -> 2665.8345 | AM9: =D9*AE9 -> 728.97093 | AN9: =D9*AF9 -> 728.97093 | AO9: =D9*AG9 -> 2046.2342 | AP9: =IF(N9>0,D9*U9/N9,0) -> 0.025577927 | AQ9: =IF(N9>0,D9*(O9+P9)/N9,0) -> 0.026658345 | AR9: =IF(N9>0,D9*AS9/N9,0) -> 0.026658345 | AS9: =O9*IF($F$6>0,1,0)+P9*X9*IF($G$6>0,1,0) -> 0.55169968 | AT9: =I9*(F9+G9)/1000 -> 0.55227598 | AU9: =I9*F9/1000 -> 0.27893119 | AV9: =I9*G9/1000 -> 0.2733448
A10: =Inputs!$A$85 -> BF-BOF steel | B10: =Inputs!$B$85 -> 0 | C10: =Inputs!$C$85 -> 0 | D10: =Inputs!$D$85 -> 0 | E10: =Inputs!$E$85 -> 620 | F10: =Inputs!$J$85 -> 1.4249803 | G10: =Inputs!$K$85 -> 0.05276542 | H10: =Inputs!$Q$85 -> 0.0026960723 | I10: =B10*(1+C10)^($N$6-BaseYr) -> 0 | J10: =$F$6*$B$6*F10 -> 28.499605 | K10: =$G$6*$C$6*G10 -> 1.0553084 | L10: =MIN($D$6,$B$6)*$F$6*F10+MIN($D$6,$C$6)*$G$6*G10 -> 0 | M10: =IF(E10>0,(J10+K10-L10)/E10,0) -> 0.047669216 | N10: =I10*(1+M10)^EpsQ3 -> 0 | O10: =N10*F10/1000 -> 0 | P10: =N10*G10/1000 -> 0 | Q10: =O10*($H$6-1) -> 0 | R10: =-P10*(1-EXP(-H10*($G$6*$C$6+$E$6))) -> 0 | S10: =O10+Q10 -> 0 | T10: =P10+R10 -> 0 | U10: =S10+T10 -> 0 | V10: =(O10+P10)*(1-(1+M10)^(-EpsQ3)) -> 0 | W10: =P10*(1-(1+M10)^(-EpsQ3)) -> 0 | X10: =IF(G10>0,1,0) -> 1 | Y10: =S10*$F$6*$B$6 -> 0 | Z10: =(P10*X10+R10)*$G$6*$C$6 -> 0 | AA10: =Y10+Z10 -> 0 | AB10: =L10*N10/1000 -> 0 | AC10: =IF(N10>0,U10*1000/N10,0) -> 0 | AD10: =IF(N10>0,AA10*1000/N10-L10,0) -> 0 | AE10: =MAX(0,$I$6*$J$6*AC10-$K$6*MAX(0,AD10)) -> 0 | AF10: =MAX(0,$L$6*$J$6*AC10-MAX(0,AD10)) -> 0 | AG10: =MAX(0,$M$6*$J$6*AC10-MAX(0,AD10)) -> 0 | AH10: =IF(B10>0,D10*N10/B10*AE10/1000,0) -> 0 | AI10: =D10*(1+C10)^($N$6-BaseYr)*$I$6*$J$6*(F10+G10)/1000 -> 0 | AJ10: =D10*$I$6*$J$6*(F10+G10) -> 0 | AK10: =D10*$L$6*$J$6*(F10+G10) -> 0 | AL10: =D10*$M$6*$J$6*(F10+G10) -> 0 | AM10: =D10*AE10 -> 0 | AN10: =D10*AF10 -> 0 | AO10: =D10*AG10 -> 0 | AP10: =IF(N10>0,D10*U10/N10,0) -> 0 | AQ10: =IF(N10>0,D10*(O10+P10)/N10,0) -> 0 | AR10: =IF(N10>0,D10*AS10/N10,0) -> 0 | AS10: =O10*IF($F$6>0,1,0)+P10*X10*IF($G$6>0,1,0) -> 0 | AT10: =I10*(F10+G10)/1000 -> 0 | AU10: =I10*F10/1000 -> 0 | AV10: =I10*G10/1000 -> 0
A11: =Inputs!$A$86 -> Clinker | B11: =Inputs!$B$86 -> 50000 | C11: =Inputs!$C$86 -> 0.033 | D11: =Inputs!$D$86 -> 800 | E11: =Inputs!$E$86 -> 110 | F11: =Inputs!$J$86 -> 0.3135685 | G11: =Inputs!$K$86 -> 0.53702616 | H11: =Inputs!$Q$86 -> 0.0033464675 | I11: =B11*(1+C11)^($N$6-BaseYr) -> 60753.588 | J11: =$F$6*$B$6*F11 -> 6.27137 | K11: =$G$6*$C$6*G11 -> 10.740523 | L11: =MIN($D$6,$B$6)*$F$6*F11+MIN($D$6,$C$6)*$G$6*G11 -> 0 | M11: =IF(E11>0,(J11+K11-L11)/E11,0) -> 0.15465357 | N11: =I11*(1+M11)^EpsQ4 -> 59886.201 | O11: =N11*F11/1000 -> 18.778426 | P11: =N11*G11/1000 -> 32.160457 | Q11: =O11*($H$6-1) -> -0.91426194 | R11: =-P11*(1-EXP(-H11*($G$6*$C$6+$E$6))) -> -2.0820269 | S11: =O11+Q11 -> 17.864164 | T11: =P11+R11 -> 30.07843 | U11: =S11+T11 -> 47.942594 | V11: =(O11+P11)*(1-(1+M11)^(-EpsQ4)) -> -0.73779503 | W11: =P11*(1-(1+M11)^(-EpsQ4)) -> -0.46580969 | X11: =IF(G11>0,1,0) -> 1 | Y11: =S11*$F$6*$B$6 -> 357.28329 | Z11: =(P11*X11+R11)*$G$6*$C$6 -> 601.56859 | AA11: =Y11+Z11 -> 958.85188 | AB11: =L11*N11/1000 -> 0 | AC11: =IF(N11>0,U11*1000/N11,0) -> 0.80056162 | AD11: =IF(N11>0,AA11*1000/N11-L11,0) -> 16.011232 | AE11: =MAX(0,$I$6*$J$6*AC11-$K$6*MAX(0,AD11)) -> 22.816006 | AF11: =MAX(0,$L$6*$J$6*AC11-MAX(0,AD11)) -> 22.816006 | AG11: =MAX(0,$M$6*$J$6*AC11-MAX(0,AD11)) -> 64.044929 | AH11: =IF(B11>0,D11*N11/B11*AE11/1000,0) -> 21.861823 | AI11: =D11*(1+C11)^($N$6-BaseYr)*$I$6*$J$6*(F11+G11)/1000 -> 40.101102 | AJ11: =D11*$I$6*$J$6*(F11+G11) -> 33003.073 | AK11: =D11*$L$6*$J$6*(F11+G11) -> 33003.073 | AL11: =D11*$M$6*$J$6*(F11+G11) -> 68047.573 | AM11: =D11*AE11 -> 18252.805 | AN11: =D11*AF11 -> 18252.805 | AO11: =D11*AG11 -> 51235.943 | AP11: =IF(N11>0,D11*U11/N11,0) -> 0.64044929 | AQ11: =IF(N11>0,D11*(O11+P11)/N11,0) -> 0.68047573 | AR11: =IF(N11>0,D11*AS11/N11,0) -> 0.68047573 | AS11: =O11*IF($F$6>0,1,0)+P11*X11*IF($G$6>0,1,0) -> 50.938883 | AT11: =I11*(F11+G11)/1000 -> 51.676678 | AU11: =I11*F11/1000 -> 19.050412 | AV11: =I11*G11/1000 -> 32.626266
A12: =Inputs!$A$87 -> Ammonia | B12: =Inputs!$B$87 -> 1785 | C12: =Inputs!$C$87 -> 0.022 | D12: =Inputs!$D$87 -> 120 | E12: =Inputs!$E$87 -> 450 | F12: =Inputs!$J$87 -> 1.97472 | G12: =Inputs!$K$87 -> 0 | H12: =Inputs!$Q$87 -> 0.0028931766 | I12: =B12*(1+C12)^($N$6-BaseYr) -> 2033.9656 | J12: =$F$6*$B$6*F12 -> 39.4944 | K12: =$G$6*$C$6*G12 -> 0 | L12: =MIN($D$6,$B$6)*$F$6*F12+MIN($D$6,$C$6)*$G$6*G12 -> 0 | M12: =IF(E12>0,(J12+K12-L12)/E12,0) -> 0.087765333 | N12: =I12*(1+M12)^EpsQ5 -> 1966.661 | O12: =N12*F12/1000 -> 3.8836048 | P12: =N12*G12/1000 -> 0 | Q12: =O12*($H$6-1) -> -0.18908039 | R12: =-P12*(1-EXP(-H12*($G$6*$C$6+$E$6))) -> 0 | S12: =O12+Q12 -> 3.6945245 | T12: =P12+R12 -> 0 | U12: =S12+T12 -> 3.6945245 | V12: =(O12+P12)*(1-(1+M12)^(-EpsQ5)) -> -0.13290763 | W12: =P12*(1-(1+M12)^(-EpsQ5)) -> 0 | X12: =IF(G12>0,1,0) -> 0 | Y12: =S12*$F$6*$B$6 -> 73.890489 | Z12: =(P12*X12+R12)*$G$6*$C$6 -> 0 | AA12: =Y12+Z12 -> 73.890489 | AB12: =L12*N12/1000 -> 0 | AC12: =IF(N12>0,U12*1000/N12,0) -> 1.8785772 | AD12: =IF(N12>0,AA12*1000/N12-L12,0) -> 37.571543 | AE12: =MAX(0,$I$6*$J$6*AC12-$K$6*MAX(0,AD12)) -> 53.539449 | AF12: =MAX(0,$L$6*$J$6*AC12-MAX(0,AD12)) -> 53.539449 | AG12: =MAX(0,$M$6*$J$6*AC12-MAX(0,AD12)) -> 150.28617 | AH12: =IF(B12>0,D12*N12/B12*AE12/1000,0) -> 7.0785847 | AI12: =D12*(1+C12)^($N$6-BaseYr)*$I$6*$J$6*(F12+G12)/1000 -> 13.095856 | AJ12: =D12*$I$6*$J$6*(F12+G12) -> 11492.87 | AK12: =D12*$L$6*$J$6*(F12+G12) -> 11492.87 | AL12: =D12*$M$6*$J$6*(F12+G12) -> 23696.64 | AM12: =D12*AE12 -> 6424.7339 | AN12: =D12*AF12 -> 6424.7339 | AO12: =D12*AG12 -> 18034.341 | AP12: =IF(N12>0,D12*U12/N12,0) -> 0.22542926 | AQ12: =IF(N12>0,D12*(O12+P12)/N12,0) -> 0.2369664 | AR12: =IF(N12>0,D12*AS12/N12,0) -> 0.2369664 | AS12: =O12*IF($F$6>0,1,0)+P12*X12*IF($G$6>0,1,0) -> 3.8836048 | AT12: =I12*(F12+G12)/1000 -> 4.0165125 | AU12: =I12*F12/1000 -> 4.0165125 | AV12: =I12*G12/1000 -> 0
A13: =Inputs!$A$88 -> Urea | B13: =Inputs!$B$88 -> 2800 | C13: =Inputs!$C$88 -> 0.022 | D13: =Inputs!$D$88 -> 1600 | E13: =Inputs!$E$88 -> 380 | F13: =Inputs!$J$88 -> 0.1122 | G13: =Inputs!$K$88 -> 0 | H13: =Inputs!$Q$88 -> 0.0010087869 | I13: =B13*(1+C13)^($N$6-BaseYr) -> 3190.5342 | J13: =$F$6*$B$6*F13 -> 2.244 | K13: =$G$6*$C$6*G13 -> 0 | L13: =MIN($D$6,$B$6)*$F$6*F13+MIN($D$6,$C$6)*$G$6*G13 -> 0 | M13: =IF(E13>0,(J13+K13-L13)/E13,0) -> 0.0059052632 | N13: =I13*(1+M13)^EpsQ6 -> 3183.0288 | O13: =N13*F13/1000 -> 0.35713584 | P13: =N13*G13/1000 -> 0 | Q13: =O13*($H$6-1) -> -0.01738781 | R13: =-P13*(1-EXP(-H13*($G$6*$C$6+$E$6))) -> 0 | S13: =O13+Q13 -> 0.33974803 | T13: =P13+R13 -> 0 | U13: =S13+T13 -> 0.33974803 | V13: =(O13+P13)*(1-(1+M13)^(-EpsQ6)) -> -0.00084210264 | W13: =P13*(1-(1+M13)^(-EpsQ6)) -> 0 | X13: =IF(G13>0,1,0) -> 0 | Y13: =S13*$F$6*$B$6 -> 6.7949605 | Z13: =(P13*X13+R13)*$G$6*$C$6 -> 0 | AA13: =Y13+Z13 -> 6.7949605 | AB13: =L13*N13/1000 -> 0 | AC13: =IF(N13>0,U13*1000/N13,0) -> 0.10673734 | AD13: =IF(N13>0,AA13*1000/N13-L13,0) -> 2.1347468 | AE13: =MAX(0,$I$6*$J$6*AC13-$K$6*MAX(0,AD13)) -> 3.0420141 | AF13: =MAX(0,$L$6*$J$6*AC13-MAX(0,AD13)) -> 3.0420141 | AG13: =MAX(0,$M$6*$J$6*AC13-MAX(0,AD13)) -> 8.5389871 | AH13: =IF(B13>0,D13*N13/B13*AE13/1000,0) -> 5.5330393 | AI13: =D13*(1+C13)^($N$6-BaseYr)*$I$6*$J$6*(F13+G13)/1000 -> 9.9211029 | AJ13: =D13*$I$6*$J$6*(F13+G13) -> 8706.72 | AK13: =D13*$L$6*$J$6*(F13+G13) -> 8706.72 | AL13: =D13*$M$6*$J$6*(F13+G13) -> 17952 | AM13: =D13*AE13 -> 4867.2226 | AN13: =D13*AF13 -> 4867.2226 | AO13: =D13*AG13 -> 13662.379 | AP13: =IF(N13>0,D13*U13/N13,0) -> 0.17077974 | AQ13: =IF(N13>0,D13*(O13+P13)/N13,0) -> 0.17952 | AR13: =IF(N13>0,D13*AS13/N13,0) -> 0.17952 | AS13: =O13*IF($F$6>0,1,0)+P13*X13*IF($G$6>0,1,0) -> 0.35713584 | AT13: =I13*(F13+G13)/1000 -> 0.35797794 | AU13: =I13*F13/1000 -> 0.35797794 | AV13: =I13*G13/1000 -> 0
A14: =Inputs!$A$89 -> Ammonium nitrate | B14: =Inputs!$B$89 -> 600 | C14: =Inputs!$C$89 -> 0.022 | D14: =Inputs!$D$89 -> 80 | E14: =Inputs!$E$89 -> 320 | F14: =Inputs!$J$89 -> 0.1122 | G14: =Inputs!$K$89 -> 0.9944125 | H14: =Inputs!$Q$89 -> 0.0078858436 | I14: =B14*(1+C14)^($N$6-BaseYr) -> 683.6859 | J14: =$F$6*$B$6*F14 -> 2.244 | K14: =$G$6*$C$6*G14 -> 19.88825 | L14: =MIN($D$6,$B$6)*$F$6*F14+MIN($D$6,$C$6)*$G$6*G14 -> 0 | M14: =IF(E14>0,(J14+K14-L14)/E14,0) -> 0.069163281 | N14: =I14*(1+M14)^EpsQ7 -> 665.63939 | O14: =N14*F14/1000 -> 0.074684739 | P14: =N14*G14/1000 -> 0.66192013 | Q14: =O14*($H$6-1) -> -0.0036361628 | R14: =-P14*(1-EXP(-H14*($G$6*$C$6+$E$6))) -> -0.09657973 | S14: =O14+Q14 -> 0.071048576 | T14: =P14+R14 -> 0.5653404 | U14: =S14+T14 -> 0.63638897 | V14: =(O14+P14)*(1-(1+M14)^(-EpsQ7)) -> -0.019970502 | W14: =P14*(1-(1+M14)^(-EpsQ7)) -> -0.017945682 | X14: =IF(G14>0,1,0) -> 1 | Y14: =S14*$F$6*$B$6 -> 1.4209715 | Z14: =(P14*X14+R14)*$G$6*$C$6 -> 11.306808 | AA14: =Y14+Z14 -> 12.727779 | AB14: =L14*N14/1000 -> 0 | AC14: =IF(N14>0,U14*1000/N14,0) -> 0.95605667 | AD14: =IF(N14>0,AA14*1000/N14-L14,0) -> 19.121133 | AE14: =MAX(0,$I$6*$J$6*AC14-$K$6*MAX(0,AD14)) -> 27.247615 | AF14: =MAX(0,$L$6*$J$6*AC14-MAX(0,AD14)) -> 27.247615 | AG14: =MAX(0,$M$6*$J$6*AC14-MAX(0,AD14)) -> 76.484533 | AH14: =IF(B14>0,D14*N14/B14*AE14/1000,0) -> 2.4182781 | AI14: =D14*(1+C14)^($N$6-BaseYr)*$I$6*$J$6*(F14+G14)/1000 -> 4.8925207 | AJ14: =D14*$I$6*$J$6*(F14+G14) -> 4293.6565 | AK14: =D14*$L$6*$J$6*(F14+G14) -> 4293.6565 | AL14: =D14*$M$6*$J$6*(F14+G14) -> 8852.9 | AM14: =D14*AE14 -> 2179.8092 | AN14: =D14*AF14 -> 2179.8092 | AO14: =D14*AG14 -> 6118.7627 | AP14: =IF(N14>0,D14*U14/N14,0) -> 0.076484533 | AQ14: =IF(N14>0,D14*(O14+P14)/N14,0) -> 0.088529 | AR14: =IF(N14>0,D14*AS14/N14,0) -> 0.088529 | AS14: =O14*IF($F$6>0,1,0)+P14*X14*IF($G$6>0,1,0) -> 0.73660486 | AT14: =I14*(F14+G14)/1000 -> 0.75657537 | AU14: =I14*F14/1000 -> 0.076709558 | AV14: =I14*G14/1000 -> 0.67986581
A15: =Inputs!$A$90 -> Aluminium | B15: =Inputs!$B$90 -> 300 | C15: =Inputs!$C$90 -> 0.055 | D15: =Inputs!$D$90 -> 167 | E15: =Inputs!$E$90 -> 2400 | F15: =Inputs!$J$90 -> 0.12342 | G15: =Inputs!$K$90 -> 2.397493 | H15: =Inputs!$Q$90 -> 0.0019988245 | I15: =B15*(1+C15)^($N$6-BaseYr) -> 413.65284 | J15: =$F$6*$B$6*F15 -> 2.4684 | K15: =$G$6*$C$6*G15 -> 47.949861 | L15: =MIN($D$6,$B$6)*$F$6*F15+MIN($D$6,$C$6)*$G$6*G15 -> 0 | M15: =IF(E15>0,(J15+K15-L15)/E15,0) -> 0.021007609 | N15: =I15*(1+M15)^EpsQ8 -> 409.37519 | O15: =N15*F15/1000 -> 0.050525086 | P15: =N15*G15/1000 -> 0.98147418 | Q15: =O15*($H$6-1) -> -0.002459906 | R15: =-P15*(1-EXP(-H15*($G$6*$C$6+$E$6))) -> -0.038461984 | S15: =O15+Q15 -> 0.04806518 | T15: =P15+R15 -> 0.94301219 | U15: =S15+T15 -> 0.99107738 | V15: =(O15+P15)*(1-(1+M15)^(-EpsQ8)) -> -0.010783578 | W15: =P15*(1-(1+M15)^(-EpsQ8)) -> -0.010255631 | X15: =IF(G15>0,1,0) -> 1 | Y15: =S15*$F$6*$B$6 -> 0.96130361 | Z15: =(P15*X15+R15)*$G$6*$C$6 -> 18.860244 | AA15: =Y15+Z15 -> 19.821548 | AB15: =L15*N15/1000 -> 0 | AC15: =IF(N15>0,U15*1000/N15,0) -> 2.4209512 | AD15: =IF(N15>0,AA15*1000/N15-L15,0) -> 48.419024 | AE15: =MAX(0,$I$6*$J$6*AC15-$K$6*MAX(0,AD15)) -> 68.99711 | AF15: =MAX(0,$L$6*$J$6*AC15-MAX(0,AD15)) -> 68.99711 | AG15: =MAX(0,$M$6*$J$6*AC15-MAX(0,AD15)) -> 193.6761 | AH15: =IF(B15>0,D15*N15/B15*AE15/1000,0) -> 15.723443 | AI15: =D15*(1+C15)^($N$6-BaseYr)*$I$6*$J$6*(F15+G15)/1000 -> 28.153399 | AJ15: =D15*$I$6*$J$6*(F15+G15) -> 20418.135 | AK15: =D15*$L$6*$J$6*(F15+G15) -> 20418.135 | AL15: =D15*$M$6*$J$6*(F15+G15) -> 42099.248 | AM15: =D15*AE15 -> 11522.517 | AN15: =D15*AF15 -> 11522.517 | AO15: =D15*AG15 -> 32343.908 | AP15: =IF(N15>0,D15*U15/N15,0) -> 0.40429885 | AQ15: =IF(N15>0,D15*(O15+P15)/N15,0) -> 0.42099248 | AR15: =IF(N15>0,D15*AS15/N15,0) -> 0.42099248 | AS15: =O15*IF($F$6>0,1,0)+P15*X15*IF($G$6>0,1,0) -> 1.0319993 | AT15: =I15*(F15+G15)/1000 -> 1.0427828 | AU15: =I15*F15/1000 -> 0.051053034 | AV15: =I15*G15/1000 -> 0.99172981
A16: Total | I16: =SUM(I8:I15) -> 79893.956 | N16: =SUM(N8:N15) -> 78880.541 | O16: =SUM(O8:O15) -> 27.169331 | P16: =SUM(P8:P15) -> 34.325582 | Q16: =SUM(Q8:Q15) -> -1.3227885 | R16: =SUM(R8:R15) -> -2.2424276 | S16: =SUM(S8:S15) -> 25.846543 | T16: =SUM(T8:T15) -> 32.083154 | U16: =SUM(U8:U15) -> 57.929697 | ... W16: =SUM(W8:W15) -> -0.49590352 | Y16: =SUM(Y8:Y15) -> 516.93086 | Z16: =SUM(Z8:Z15) -> 641.66309 | AA16: =SUM(AA8:AA15) -> 1158.5939 | AB16: =SUM(AB8:AB15) -> 0 | AH16: =SUM(AH8:AH15) -> 65.861639 | AI16: =SUM(AI8:AI15) -> 120.01558 | AJ16: =SUM(AJ8:AJ15) -> 96335.511 | AK16: =SUM(AK8:AK15) -> 96335.511 | AL16: =SUM(AL8:AL15) -> 198629.92 | AM16: =SUM(AM8:AM15) -> 53539.775 | AN16: =SUM(AN8:AN15) -> 53539.775 | AO16: =SUM(AO8:AO15) -> 150287.09 | ... AV16: =SUM(AV8:AV15) -> 34.821485
A20: Bundle 2A - Economy-wide fuel levy (EG1), process not priced.
A21: Bundle | B21: tau: carbon price | C21: tau_p: process price | D21: obrrb: OBR rebate rate | E21: fundsp: fund shadow price | F21: incl_f | G21: incl_p | H21: xf: fuel-intensity factor | I21: CBF (selected conv.) | J21: P_EU | K21: S (selected conv.) | L21: CBF (FULL) | M21: CBF (NOPHASE) | N21: Year | O21: CPAT scenario | P21: b_f | Q21: beta set | R21: Mode
A22: 2A | B22: =INDEX(BT_Tau,MATCH($A$22,BT_Code,0)) -> 20 | C22: =B22*INDEX(BT_Flag,MATCH($A$22,BT_Code,0)) -> 0 | D22: =INDEX(BT_Theta,MATCH($A$22,BT_Code,0))*B22 -> 0 | E22: =INDEX(BT_Phi,MATCH($A$22,BT_Code,0))*SigmaEff -> 0 | F22: 1 | G22: =INDEX(BT_Flag,MATCH($A$22,BT_Code,0)) -> 0 | H22: =IF(Mode="PROTOTYPE",1,EXP(Bf*(F22*B22+E22))) -> 0.95131318 | I22: =CBFsel -> 0.485 | J22: =PEU -> 100 | K22: =Ssel -> 1 | L22: =CBFyr -> 0.485 | M22: 1 | N22: =Yr -> 2030 | O22: =INDEX(BT_Scen,MATCH($A$22,BT_Code,0)) -> EG1 | P22: =Bf -> -0.0024955979 | Q22: =BetaSet -> IPCC_CENTRAL | R22: =Mode -> REBUILD
A23: Product | B23: Q0 (kt) | C23: g | D23: X exports (kt) | E23: P ($/t) | F23: F (tCO2/t) | G23: G (tCO2e/t) | H23: beta | I23: Qb: baseline output | J23: kf: fuel cost $/t | K23: kp: process cost $/t | L23: m: rebate $/t | M23: dp: cost/price | N23: Q: output | O23: Ef: fuel emis. | P23: Ep: process emis. | Q23: ER_f: fuel-int. resp. | R23: ER_p: process-int. resp. | S23: post fuel | T23: post process | U23: post total | V23: emrq_i: output ch. | W23: emrq_proc_i | X23: J_i: process>0 | Y23: revf_i $m | Z23: revp_i $m | AA23: rev_i $m | AB23: rebate_i $m | AC23: EI: tCO2/t | AD23: d: net price paid $/t | AE23: obl (sel.) $/t | AF23: obl (FULL) $/t | AG23: obl (NOPHASE) $/t | AH23: cbobl_i $m | AI23: cbobl0_i $m | AJ23: w_den sel | AK23: w_den FULL | AL23: w_den NOPHASE | AM23: w_num sel | AN23: w_num FULL | AO23: w_num NOPHASE | AP23: X*post/Q | AQ23: X*(Ef+Ep)/Q | AR23: X*covered/Q | AS23: covered_i | AT23: Ebase_i | AU23: Efbase_i | AV23: Epbase_i
A24: =Inputs!$A$83 -> DRI-EAF steel | B24: =Inputs!$B$83 -> 5100 | C24: =Inputs!$C$83 -> 0.044 | D24: =Inputs!$D$83 -> 580 | E24: =Inputs!$E$83 -> 750 | F24: =Inputs!$J$83 -> 0.57099077 | G24: =Inputs!$K$83 -> 0.03790102 | H24: =Inputs!$Q$83 -> 0.0034469507 | I24: =B24*(1+C24)^($N$22-BaseYr) -> 6603.4846 | J24: =$F$22*$B$22*F24 -> 11.419815 | K24: =$G$22*$C$22*G24 -> 0 | L24: =MIN($D$22,$B$22)*$F$22*F24+MIN($D$22,$C$22)*$G$22*G24 -> 0 | M24: =IF(E24>0,(J24+K24-L24)/E24,0) -> 0.015226421 | N24: =I24*(1+M24)^EpsQ1 -> 6563.6891 | O24: =N24*F24/1000 -> 3.7478059 | P24: =N24*G24/1000 -> 0.24877051 | Q24: =O24*($H$22-1) -> -0.18246877 | R24: =-P24*(1-EXP(-H24*($G$22*$C$22+$E$22))) -> 0 | S24: =O24+Q24 -> 3.5653371 | T24: =P24+R24 -> 0.24877051 | U24: =S24+T24 -> 3.8141077 | V24: =(O24+P24)*(1-(1+M24)^(-EpsQ1)) -> -0.024231126 | W24: =P24*(1-(1+M24)^(-EpsQ1)) -> -0.0015082883 | X24: =IF(G24>0,1,0) -> 1 | Y24: =S24*$F$22*$B$22 -> 71.306743 | Z24: =(P24*X24+R24)*$G$22*$C$22 -> 0 | AA24: =Y24+Z24 -> 71.306743 | AB24: =L24*N24/1000 -> 0 | AC24: =IF(N24>0,U24*1000/N24,0) -> 0.58109206 | AD24: =IF(N24>0,AA24*1000/N24-L24,0) -> 10.863821 | AE24: =MAX(0,$I$22*$J$22*AC24-$K$22*MAX(0,AD24)) -> 17.319144 | AF24: =MAX(0,$L$22*$J$22*AC24-MAX(0,AD24)) -> 17.319144 | AG24: =MAX(0,$M$22*$J$22*AC24-MAX(0,AD24)) -> 47.245385 | AH24: =IF(B24>0,D24*N24/B24*AE24/1000,0) -> 12.928027 | AI24: =D24*(1+C24)^($N$22-BaseYr)*$I$22*$J$22*(F24+G24)/1000 -> 22.177513 | AJ24: =D24*$I$22*$J$22*(F24+G24) -> 17128.126 | AK24: =D24*$L$22*$J$22*(F24+G24) -> 17128.126 | AL24: =D24*$M$22*$J$22*(F24+G24) -> 35315.724 | AM24: =D24*AE24 -> 10045.104 | AN24: =D24*AF24 -> 10045.104 | AO24: =D24*AG24 -> 27402.324 | AP24: =IF(N24>0,D24*U24/N24,0) -> 0.3370334 | AQ24: =IF(N24>0,D24*(O24+P24)/N24,0) -> 0.35315724 | AR24: =IF(N24>0,D24*AS24/N24,0) -> 0.33117465 | AS24: =O24*IF($F$22>0,1,0)+P24*X24*IF($G$22>0,1,0) -> 3.7478059 | AT24: =I24*(F24+G24)/1000 -> 4.0208075 | AU24: =I24*F24/1000 -> 3.7705287 | AV24: =I24*G24/1000 -> 0.2502788
A25: =Inputs!$A$84 -> Scrap-EAF steel | B25: =Inputs!$B$84 -> 4800 | C25: =Inputs!$C$84 -> 0.044 | D25: =Inputs!$D$84 -> 300 | E25: =Inputs!$E$84 -> 680 | F25: =Inputs!$J$84 -> 0.04488 | G25: =Inputs!$K$84 -> 0.04398115 | H25: =Inputs!$Q$84 -> 0.0016366491 | I25: =B25*(1+C25)^($N$22-BaseYr) -> 6215.0443 | J25: =$F$22*$B$22*F25 -> 0.8976 | K25: =$G$22*$C$22*G25 -> 0 | L25: =MIN($D$22,$B$22)*$F$22*F25+MIN($D$22,$C$22)*$G$22*G25 -> 0 | M25: =IF(E25>0,(J25+K25-L25)/E25,0) -> 0.00132 | N25: =I25*(1+M25)^EpsQ2 -> 6211.7658 | O25: =N25*F25/1000 -> 0.27878405 | P25: =N25*G25/1000 -> 0.2732006 | Q25: =O25*($H$22-1) -> -0.01357311 | R25: =-P25*(1-EXP(-H25*($G$22*$C$22+$E$22))) -> 0 | S25: =O25+Q25 -> 0.26521094 | T25: =P25+R25 -> 0.2732006 | U25: =S25+T25 -> 0.53841154 | V25: =(O25+P25)*(1-(1+M25)^(-EpsQ2)) -> -0.00029133256 | W25: =P25*(1-(1+M25)^(-EpsQ2)) -> -0.00014419284 | X25: =IF(G25>0,1,0) -> 1 | Y25: =S25*$F$22*$B$22 -> 5.3042188 | Z25: =(P25*X25+R25)*$G$22*$C$22 -> 0 | AA25: =Y25+Z25 -> 5.3042188 | AB25: =L25*N25/1000 -> 0 | AC25: =IF(N25>0,U25*1000/N25,0) -> 0.086676085 | AD25: =IF(N25>0,AA25*1000/N25-L25,0) -> 0.85389871 | AE25: =MAX(0,$I$22*$J$22*AC25-$K$22*MAX(0,AD25)) -> 3.3498914 | AF25: =MAX(0,$L$22*$J$22*AC25-MAX(0,AD25)) -> 3.3498914 | AG25: =MAX(0,$M$22*$J$22*AC25-MAX(0,AD25)) -> 7.8137098 | AH25: =IF(B25>0,D25*N25/B25*AE25/1000,0) -> 1.3005463 | AI25: =D25*(1+C25)^($N$22-BaseYr)*$I$22*$J$22*(F25+G25)/1000 -> 1.6740866 | AJ25: =D25*$I$22*$J$22*(F25+G25) -> 1292.9297 | AK25: =D25*$L$22*$J$22*(F25+G25) -> 1292.9297 | AL25: =D25*$M$22*$J$22*(F25+G25) -> 2665.8345 | AM25: =D25*AE25 -> 1004.9674 | AN25: =D25*AF25 -> 1004.9674 | AO25: =D25*AG25 -> 2344.1129 | AP25: =IF(N25>0,D25*U25/N25,0) -> 0.026002826 | AQ25: =IF(N25>0,D25*(O25+P25)/N25,0) -> 0.026658345 | AR25: =IF(N25>0,D25*AS25/N25,0) -> 0.013464 | AS25: =O25*IF($F$22>0,1,0)+P25*X25*IF($G$22>0,1,0) -> 0.27878405 | AT25: =I25*(F25+G25)/1000 -> 0.55227598 | AU25: =I25*F25/1000 -> 0.27893119 | AV25: =I25*G25/1000 -> 0.2733448
A26: =Inputs!$A$85 -> BF-BOF steel | B26: =Inputs!$B$85 -> 0 | C26: =Inputs!$C$85 -> 0 | D26: =Inputs!$D$85 -> 0 | E26: =Inputs!$E$85 -> 620 | F26: =Inputs!$J$85 -> 1.4249803 | G26: =Inputs!$K$85 -> 0.05276542 | H26: =Inputs!$Q$85 -> 0.0026960723 | I26: =B26*(1+C26)^($N$22-BaseYr) -> 0 | J26: =$F$22*$B$22*F26 -> 28.499605 | K26: =$G$22*$C$22*G26 -> 0 | L26: =MIN($D$22,$B$22)*$F$22*F26+MIN($D$22,$C$22)*$G$22*G26 -> 0 | M26: =IF(E26>0,(J26+K26-L26)/E26,0) -> 0.045967105 | N26: =I26*(1+M26)^EpsQ3 -> 0 | O26: =N26*F26/1000 -> 0 | P26: =N26*G26/1000 -> 0 | Q26: =O26*($H$22-1) -> 0 | R26: =-P26*(1-EXP(-H26*($G$22*$C$22+$E$22))) -> 0 | S26: =O26+Q26 -> 0 | T26: =P26+R26 -> 0 | U26: =S26+T26 -> 0 | V26: =(O26+P26)*(1-(1+M26)^(-EpsQ3)) -> 0 | W26: =P26*(1-(1+M26)^(-EpsQ3)) -> 0 | X26: =IF(G26>0,1,0) -> 1 | Y26: =S26*$F$22*$B$22 -> 0 | Z26: =(P26*X26+R26)*$G$22*$C$22 -> 0 | AA26: =Y26+Z26 -> 0 | AB26: =L26*N26/1000 -> 0 | AC26: =IF(N26>0,U26*1000/N26,0) -> 0 | AD26: =IF(N26>0,AA26*1000/N26-L26,0) -> 0 | AE26: =MAX(0,$I$22*$J$22*AC26-$K$22*MAX(0,AD26)) -> 0 | AF26: =MAX(0,$L$22*$J$22*AC26-MAX(0,AD26)) -> 0 | AG26: =MAX(0,$M$22*$J$22*AC26-MAX(0,AD26)) -> 0 | AH26: =IF(B26>0,D26*N26/B26*AE26/1000,0) -> 0 | AI26: =D26*(1+C26)^($N$22-BaseYr)*$I$22*$J$22*(F26+G26)/1000 -> 0 | AJ26: =D26*$I$22*$J$22*(F26+G26) -> 0 | AK26: =D26*$L$22*$J$22*(F26+G26) -> 0 | AL26: =D26*$M$22*$J$22*(F26+G26) -> 0 | AM26: =D26*AE26 -> 0 | AN26: =D26*AF26 -> 0 | AO26: =D26*AG26 -> 0 | AP26: =IF(N26>0,D26*U26/N26,0) -> 0 | AQ26: =IF(N26>0,D26*(O26+P26)/N26,0) -> 0 | AR26: =IF(N26>0,D26*AS26/N26,0) -> 0 | AS26: =O26*IF($F$22>0,1,0)+P26*X26*IF($G$22>0,1,0) -> 0 | AT26: =I26*(F26+G26)/1000 -> 0 | AU26: =I26*F26/1000 -> 0 | AV26: =I26*G26/1000 -> 0
A27: =Inputs!$A$86 -> Clinker | B27: =Inputs!$B$86 -> 50000 | C27: =Inputs!$C$86 -> 0.033 | D27: =Inputs!$D$86 -> 800 | E27: =Inputs!$E$86 -> 110 | F27: =Inputs!$J$86 -> 0.3135685 | G27: =Inputs!$K$86 -> 0.53702616 | H27: =Inputs!$Q$86 -> 0.0033464675 | I27: =B27*(1+C27)^($N$22-BaseYr) -> 60753.588 | J27: =$F$22*$B$22*F27 -> 6.27137 | K27: =$G$22*$C$22*G27 -> 0 | L27: =MIN($D$22,$B$22)*$F$22*F27+MIN($D$22,$C$22)*$G$22*G27 -> 0 | M27: =IF(E27>0,(J27+K27-L27)/E27,0) -> 0.057012455 | N27: =I27*(1+M27)^EpsQ4 -> 60417.663 | O27: =N27*F27/1000 -> 18.945076 | P27: =N27*G27/1000 -> 32.445866 | Q27: =O27*($H$22-1) -> -0.92237559 | R27: =-P27*(1-EXP(-H27*($G$22*$C$22+$E$22))) -> 0 | S27: =O27+Q27 -> 18.0227 | T27: =P27+R27 -> 32.445866 | U27: =S27+T27 -> 50.468566 | V27: =(O27+P27)*(1-(1+M27)^(-EpsQ4)) -> -0.28573615 | W27: =P27*(1-(1+M27)^(-EpsQ4)) -> -0.1804006 | X27: =IF(G27>0,1,0) -> 1 | Y27: =S27*$F$22*$B$22 -> 360.45401 | Z27: =(P27*X27+R27)*$G$22*$C$22 -> 0 | AA27: =Y27+Z27 -> 360.45401 | AB27: =L27*N27/1000 -> 0 | AC27: =IF(N27>0,U27*1000/N27,0) -> 0.83532801 | AD27: =IF(N27>0,AA27*1000/N27-L27,0) -> 5.9660369 | AE27: =MAX(0,$I$22*$J$22*AC27-$K$22*MAX(0,AD27)) -> 34.547371 | AF27: =MAX(0,$L$22*$J$22*AC27-MAX(0,AD27)) -> 34.547371 | AG27: =MAX(0,$M$22*$J$22*AC27-MAX(0,AD27)) -> 77.566764 | AH27: =IF(B27>0,D27*N27/B27*AE27/1000,0) -> 33.396343 | AI27: =D27*(1+C27)^($N$22-BaseYr)*$I$22*$J$22*(F27+G27)/1000 -> 40.101102 | AJ27: =D27*$I$22*$J$22*(F27+G27) -> 33003.073 | AK27: =D27*$L$22*$J$22*(F27+G27) -> 33003.073 | AL27: =D27*$M$22*$J$22*(F27+G27) -> 68047.573 | AM27: =D27*AE27 -> 27637.897 | AN27: =D27*AF27 -> 27637.897 | AO27: =D27*AG27 -> 62053.411 | AP27: =IF(N27>0,D27*U27/N27,0) -> 0.6682624 | AQ27: =IF(N27>0,D27*(O27+P27)/N27,0) -> 0.68047573 | AR27: =IF(N27>0,D27*AS27/N27,0) -> 0.2508548 | AS27: =O27*IF($F$22>0,1,0)+P27*X27*IF($G$22>0,1,0) -> 18.945076 | AT27: =I27*(F27+G27)/1000 -> 51.676678 | AU27: =I27*F27/1000 -> 19.050412 | AV27: =I27*G27/1000 -> 32.626266
A28: =Inputs!$A$87 -> Ammonia | B28: =Inputs!$B$87 -> 1785 | C28: =Inputs!$C$87 -> 0.022 | D28: =Inputs!$D$87 -> 120 | E28: =Inputs!$E$87 -> 450 | F28: =Inputs!$J$87 -> 1.97472 | G28: =Inputs!$K$87 -> 0 | H28: =Inputs!$Q$87 -> 0.0028931766 | I28: =B28*(1+C28)^($N$22-BaseYr) -> 2033.9656 | J28: =$F$22*$B$22*F28 -> 39.4944 | K28: =$G$22*$C$22*G28 -> 0 | L28: =MIN($D$22,$B$22)*$F$22*F28+MIN($D$22,$C$22)*$G$22*G28 -> 0 | M28: =IF(E28>0,(J28+K28-L28)/E28,0) -> 0.087765333 | N28: =I28*(1+M28)^EpsQ5 -> 1966.661 | O28: =N28*F28/1000 -> 3.8836048 | P28: =N28*G28/1000 -> 0 | Q28: =O28*($H$22-1) -> -0.18908039 | R28: =-P28*(1-EXP(-H28*($G$22*$C$22+$E$22))) -> 0 | S28: =O28+Q28 -> 3.6945245 | T28: =P28+R28 -> 0 | U28: =S28+T28 -> 3.6945245 | V28: =(O28+P28)*(1-(1+M28)^(-EpsQ5)) -> -0.13290763 | W28: =P28*(1-(1+M28)^(-EpsQ5)) -> 0 | X28: =IF(G28>0,1,0) -> 0 | Y28: =S28*$F$22*$B$22 -> 73.890489 | Z28: =(P28*X28+R28)*$G$22*$C$22 -> 0 | AA28: =Y28+Z28 -> 73.890489 | AB28: =L28*N28/1000 -> 0 | AC28: =IF(N28>0,U28*1000/N28,0) -> 1.8785772 | AD28: =IF(N28>0,AA28*1000/N28-L28,0) -> 37.571543 | AE28: =MAX(0,$I$22*$J$22*AC28-$K$22*MAX(0,AD28)) -> 53.539449 | AF28: =MAX(0,$L$22*$J$22*AC28-MAX(0,AD28)) -> 53.539449 | AG28: =MAX(0,$M$22*$J$22*AC28-MAX(0,AD28)) -> 150.28617 | AH28: =IF(B28>0,D28*N28/B28*AE28/1000,0) -> 7.0785847 | AI28: =D28*(1+C28)^($N$22-BaseYr)*$I$22*$J$22*(F28+G28)/1000 -> 13.095856 | AJ28: =D28*$I$22*$J$22*(F28+G28) -> 11492.87 | AK28: =D28*$L$22*$J$22*(F28+G28) -> 11492.87 | AL28: =D28*$M$22*$J$22*(F28+G28) -> 23696.64 | AM28: =D28*AE28 -> 6424.7339 | AN28: =D28*AF28 -> 6424.7339 | AO28: =D28*AG28 -> 18034.341 | AP28: =IF(N28>0,D28*U28/N28,0) -> 0.22542926 | AQ28: =IF(N28>0,D28*(O28+P28)/N28,0) -> 0.2369664 | AR28: =IF(N28>0,D28*AS28/N28,0) -> 0.2369664 | AS28: =O28*IF($F$22>0,1,0)+P28*X28*IF($G$22>0,1,0) -> 3.8836048 | AT28: =I28*(F28+G28)/1000 -> 4.0165125 | AU28: =I28*F28/1000 -> 4.0165125 | AV28: =I28*G28/1000 -> 0
A29: =Inputs!$A$88 -> Urea | B29: =Inputs!$B$88 -> 2800 | C29: =Inputs!$C$88 -> 0.022 | D29: =Inputs!$D$88 -> 1600 | E29: =Inputs!$E$88 -> 380 | F29: =Inputs!$J$88 -> 0.1122 | G29: =Inputs!$K$88 -> 0 | H29: =Inputs!$Q$88 -> 0.0010087869 | I29: =B29*(1+C29)^($N$22-BaseYr) -> 3190.5342 | J29: =$F$22*$B$22*F29 -> 2.244 | K29: =$G$22*$C$22*G29 -> 0 | L29: =MIN($D$22,$B$22)*$F$22*F29+MIN($D$22,$C$22)*$G$22*G29 -> 0 | M29: =IF(E29>0,(J29+K29-L29)/E29,0) -> 0.0059052632 | N29: =I29*(1+M29)^EpsQ6 -> 3183.0288 | O29: =N29*F29/1000 -> 0.35713584 | P29: =N29*G29/1000 -> 0 | Q29: =O29*($H$22-1) -> -0.01738781 | R29: =-P29*(1-EXP(-H29*($G$22*$C$22+$E$22))) -> 0 | S29: =O29+Q29 -> 0.33974803 | T29: =P29+R29 -> 0 | U29: =S29+T29 -> 0.33974803 | V29: =(O29+P29)*(1-(1+M29)^(-EpsQ6)) -> -0.00084210264 | W29: =P29*(1-(1+M29)^(-EpsQ6)) -> 0 | X29: =IF(G29>0,1,0) -> 0 | Y29: =S29*$F$22*$B$22 -> 6.7949605 | Z29: =(P29*X29+R29)*$G$22*$C$22 -> 0 | AA29: =Y29+Z29 -> 6.7949605 | AB29: =L29*N29/1000 -> 0 | AC29: =IF(N29>0,U29*1000/N29,0) -> 0.10673734 | AD29: =IF(N29>0,AA29*1000/N29-L29,0) -> 2.1347468 | AE29: =MAX(0,$I$22*$J$22*AC29-$K$22*MAX(0,AD29)) -> 3.0420141 | AF29: =MAX(0,$L$22*$J$22*AC29-MAX(0,AD29)) -> 3.0420141 | AG29: =MAX(0,$M$22*$J$22*AC29-MAX(0,AD29)) -> 8.5389871 | AH29: =IF(B29>0,D29*N29/B29*AE29/1000,0) -> 5.5330393 | AI29: =D29*(1+C29)^($N$22-BaseYr)*$I$22*$J$22*(F29+G29)/1000 -> 9.9211029 | AJ29: =D29*$I$22*$J$22*(F29+G29) -> 8706.72 | AK29: =D29*$L$22*$J$22*(F29+G29) -> 8706.72 | AL29: =D29*$M$22*$J$22*(F29+G29) -> 17952 | AM29: =D29*AE29 -> 4867.2226 | AN29: =D29*AF29 -> 4867.2226 | AO29: =D29*AG29 -> 13662.379 | AP29: =IF(N29>0,D29*U29/N29,0) -> 0.17077974 | AQ29: =IF(N29>0,D29*(O29+P29)/N29,0) -> 0.17952 | AR29: =IF(N29>0,D29*AS29/N29,0) -> 0.17952 | AS29: =O29*IF($F$22>0,1,0)+P29*X29*IF($G$22>0,1,0) -> 0.35713584 | AT29: =I29*(F29+G29)/1000 -> 0.35797794 | AU29: =I29*F29/1000 -> 0.35797794 | AV29: =I29*G29/1000 -> 0
A30: =Inputs!$A$89 -> Ammonium nitrate | B30: =Inputs!$B$89 -> 600 | C30: =Inputs!$C$89 -> 0.022 | D30: =Inputs!$D$89 -> 80 | E30: =Inputs!$E$89 -> 320 | F30: =Inputs!$J$89 -> 0.1122 | G30: =Inputs!$K$89 -> 0.9944125 | H30: =Inputs!$Q$89 -> 0.0078858436 | I30: =B30*(1+C30)^($N$22-BaseYr) -> 683.6859 | J30: =$F$22*$B$22*F30 -> 2.244 | K30: =$G$22*$C$22*G30 -> 0 | L30: =MIN($D$22,$B$22)*$F$22*F30+MIN($D$22,$C$22)*$G$22*G30 -> 0 | M30: =IF(E30>0,(J30+K30-L30)/E30,0) -> 0.0070125 | N30: =I30*(1+M30)^EpsQ7 -> 681.77753 | O30: =N30*F30/1000 -> 0.076495438 | P30: =N30*G30/1000 -> 0.67796809 | Q30: =O30*($H$22-1) -> -0.00372432 | R30: =-P30*(1-EXP(-H30*($G$22*$C$22+$E$22))) -> 0 | S30: =O30+Q30 -> 0.072771118 | T30: =P30+R30 -> 0.67796809 | U30: =S30+T30 -> 0.75073921 | V30: =(O30+P30)*(1-(1+M30)^(-EpsQ7)) -> -0.0021118347 | W30: =P30*(1-(1+M30)^(-EpsQ7)) -> -0.0018977147 | X30: =IF(G30>0,1,0) -> 1 | Y30: =S30*$F$22*$B$22 -> 1.4554224 | Z30: =(P30*X30+R30)*$G$22*$C$22 -> 0 | AA30: =Y30+Z30 -> 1.4554224 | AB30: =L30*N30/1000 -> 0 | AC30: =IF(N30>0,U30*1000/N30,0) -> 1.1011498 | AD30: =IF(N30>0,AA30*1000/N30-L30,0) -> 2.1347468 | AE30: =MAX(0,$I$22*$J$22*AC30-$K$22*MAX(0,AD30)) -> 51.27102 | AF30: =MAX(0,$L$22*$J$22*AC30-MAX(0,AD30)) -> 51.27102 | AG30: =MAX(0,$M$22*$J$22*AC30-MAX(0,AD30)) -> 107.98024 | AH30: =IF(B30>0,D30*N30/B30*AE30/1000,0) -> 4.6607239 | AI30: =D30*(1+C30)^($N$22-BaseYr)*$I$22*$J$22*(F30+G30)/1000 -> 4.8925207 | AJ30: =D30*$I$22*$J$22*(F30+G30) -> 4293.6565 | AK30: =D30*$L$22*$J$22*(F30+G30) -> 4293.6565 | AL30: =D30*$M$22*$J$22*(F30+G30) -> 8852.9 | AM30: =D30*AE30 -> 4101.6816 | AN30: =D30*AF30 -> 4101.6816 | AO30: =D30*AG30 -> 8638.419 | AP30: =IF(N30>0,D30*U30/N30,0) -> 0.088091987 | AQ30: =IF(N30>0,D30*(O30+P30)/N30,0) -> 0.088529 | AR30: =IF(N30>0,D30*AS30/N30,0) -> 0.008976 | AS30: =O30*IF($F$22>0,1,0)+P30*X30*IF($G$22>0,1,0) -> 0.076495438 | AT30: =I30*(F30+G30)/1000 -> 0.75657537 | AU30: =I30*F30/1000 -> 0.076709558 | AV30: =I30*G30/1000 -> 0.67986581
A31: =Inputs!$A$90 -> Aluminium | B31: =Inputs!$B$90 -> 300 | C31: =Inputs!$C$90 -> 0.055 | D31: =Inputs!$D$90 -> 167 | E31: =Inputs!$E$90 -> 2400 | F31: =Inputs!$J$90 -> 0.12342 | G31: =Inputs!$K$90 -> 2.397493 | H31: =Inputs!$Q$90 -> 0.0019988245 | I31: =B31*(1+C31)^($N$22-BaseYr) -> 413.65284 | J31: =$F$22*$B$22*F31 -> 2.4684 | K31: =$G$22*$C$22*G31 -> 0 | L31: =MIN($D$22,$B$22)*$F$22*F31+MIN($D$22,$C$22)*$G$22*G31 -> 0 | M31: =IF(E31>0,(J31+K31-L31)/E31,0) -> 0.0010285 | N31: =I31*(1+M31)^EpsQ8 -> 413.44029 | O31: =N31*F31/1000 -> 0.0510268 | P31: =N31*G31/1000 -> 0.99122021 | Q31: =O31*($H$22-1) -> -0.0024843328 | R31: =-P31*(1-EXP(-H31*($G$22*$C$22+$E$22))) -> 0 | S31: =O31+Q31 -> 0.048542467 | T31: =P31+R31 -> 0.99122021 | U31: =S31+T31 -> 1.0397627 | V31: =(O31+P31)*(1-(1+M31)^(-EpsQ8)) -> -0.00053583778 | W31: =P31*(1-(1+M31)^(-EpsQ8)) -> -0.00050960399 | X31: =IF(G31>0,1,0) -> 1 | Y31: =S31*$F$22*$B$22 -> 0.97084934 | Z31: =(P31*X31+R31)*$G$22*$C$22 -> 0 | AA31: =Y31+Z31 -> 0.97084934 | AB31: =L31*N31/1000 -> 0 | AC31: =IF(N31>0,U31*1000/N31,0) -> 2.5149041 | AD31: =IF(N31>0,AA31*1000/N31-L31,0) -> 2.3482214 | AE31: =MAX(0,$I$22*$J$22*AC31-$K$22*MAX(0,AD31)) -> 119.62463 | AF31: =MAX(0,$L$22*$J$22*AC31-MAX(0,AD31)) -> 119.62463 | AG31: =MAX(0,$M$22*$J$22*AC31-MAX(0,AD31)) -> 249.14219 | AH31: =IF(B31>0,D31*N31/B31*AE31/1000,0) -> 27.53142 | AI31: =D31*(1+C31)^($N$22-BaseYr)*$I$22*$J$22*(F31+G31)/1000 -> 28.153399 | AJ31: =D31*$I$22*$J$22*(F31+G31) -> 20418.135 | AK31: =D31*$L$22*$J$22*(F31+G31) -> 20418.135 | AL31: =D31*$M$22*$J$22*(F31+G31) -> 42099.248 | AM31: =D31*AE31 -> 19977.313 | AN31: =D31*AF31 -> 19977.313 | AO31: =D31*AG31 -> 41606.746 | AP31: =IF(N31>0,D31*U31/N31,0) -> 0.41998899 | AQ31: =IF(N31>0,D31*(O31+P31)/N31,0) -> 0.42099248 | AR31: =IF(N31>0,D31*AS31/N31,0) -> 0.02061114 | AS31: =O31*IF($F$22>0,1,0)+P31*X31*IF($G$22>0,1,0) -> 0.0510268 | AT31: =I31*(F31+G31)/1000 -> 1.0427828 | AU31: =I31*F31/1000 -> 0.051053034 | AV31: =I31*G31/1000 -> 0.99172981
A32: Total | I32: =SUM(I24:I31) -> 79893.956 | N32: =SUM(N24:N31) -> 79438.026 | O32: =SUM(O24:O31) -> 27.339929 | P32: =SUM(P24:P31) -> 34.637025 | Q32: =SUM(Q24:Q31) -> -1.3310943 | R32: =SUM(R24:R31) -> 0 | S32: =SUM(S24:S31) -> 26.008835 | T32: =SUM(T24:T31) -> 34.637025 | U32: =SUM(U24:U31) -> 60.64586 | ... W32: =SUM(W24:W31) -> -0.1844604 | Y32: =SUM(Y24:Y31) -> 520.17669 | Z32: =SUM(Z24:Z31) -> 0 | AA32: =SUM(AA24:AA31) -> 520.17669 | AB32: =SUM(AB24:AB31) -> 0 | AH32: =SUM(AH24:AH31) -> 92.428684 | AI32: =SUM(AI24:AI31) -> 120.01558 | AJ32: =SUM(AJ24:AJ31) -> 96335.511 | AK32: =SUM(AK24:AK31) -> 96335.511 | AL32: =SUM(AL24:AL31) -> 198629.92 | AM32: =SUM(AM24:AM31) -> 74058.919 | AN32: =SUM(AN24:AN31) -> 74058.919 | AO32: =SUM(AO24:AO31) -> 173741.73 | ... AV32: =SUM(AV24:AV31) -> 34.821485
A36: Bundle 2B - As 2A with household transfers (EG2).
A37: Bundle | B37: tau: carbon price | C37: tau_p: process price | D37: obrrb: OBR rebate rate | E37: fundsp: fund shadow price | F37: incl_f | G37: incl_p | H37: xf: fuel-intensity factor | I37: CBF (selected conv.) | J37: P_EU | K37: S (selected conv.) | L37: CBF (FULL) | M37: CBF (NOPHASE) | N37: Year | O37: CPAT scenario | P37: b_f | Q37: beta set | R37: Mode
A38: 2B | B38: =INDEX(BT_Tau,MATCH($A$38,BT_Code,0)) -> 20 | C38: =B38*INDEX(BT_Flag,MATCH($A$38,BT_Code,0)) -> 0 | D38: =INDEX(BT_Theta,MATCH($A$38,BT_Code,0))*B38 -> 0 | E38: =INDEX(BT_Phi,MATCH($A$38,BT_Code,0))*SigmaEff -> 0 | F38: 1 | G38: =INDEX(BT_Flag,MATCH($A$38,BT_Code,0)) -> 0 | H38: =IF(Mode="PROTOTYPE",1,EXP(Bf*(F38*B38+E38))) -> 0.95131318 | I38: =CBFsel -> 0.485 | J38: =PEU -> 100 | K38: =Ssel -> 1 | L38: =CBFyr -> 0.485 | M38: 1 | N38: =Yr -> 2030 | O38: =INDEX(BT_Scen,MATCH($A$38,BT_Code,0)) -> EG2 | P38: =Bf -> -0.0024955979 | Q38: =BetaSet -> IPCC_CENTRAL | R38: =Mode -> REBUILD
A39: Product | B39: Q0 (kt) | C39: g | D39: X exports (kt) | E39: P ($/t) | F39: F (tCO2/t) | G39: G (tCO2e/t) | H39: beta | I39: Qb: baseline output | J39: kf: fuel cost $/t | K39: kp: process cost $/t | L39: m: rebate $/t | M39: dp: cost/price | N39: Q: output | O39: Ef: fuel emis. | P39: Ep: process emis. | Q39: ER_f: fuel-int. resp. | R39: ER_p: process-int. resp. | S39: post fuel | T39: post process | U39: post total | V39: emrq_i: output ch. | W39: emrq_proc_i | X39: J_i: process>0 | Y39: revf_i $m | Z39: revp_i $m | AA39: rev_i $m | AB39: rebate_i $m | AC39: EI: tCO2/t | AD39: d: net price paid $/t | AE39: obl (sel.) $/t | AF39: obl (FULL) $/t | AG39: obl (NOPHASE) $/t | AH39: cbobl_i $m | AI39: cbobl0_i $m | AJ39: w_den sel | AK39: w_den FULL | AL39: w_den NOPHASE | AM39: w_num sel | AN39: w_num FULL | AO39: w_num NOPHASE | AP39: X*post/Q | AQ39: X*(Ef+Ep)/Q | AR39: X*covered/Q | AS39: covered_i | AT39: Ebase_i | AU39: Efbase_i | AV39: Epbase_i
