Workbook
Name al_anode_ash: Egypt_Inputs!$D$52
Name al_anode_co2: Derivation!$D$58
Name al_anode_net: Egypt_Inputs!$D$50
Name al_anode_s: Egypt_Inputs!$D$51
Name al_bake_np: Egypt_Inputs!$D$53
Name al_c2f6: Egypt_Inputs!$D$56
Name al_cf4: Egypt_Inputs!$D$55
Name al_ng_total: Egypt_Inputs!$D$54
Name an_fuel: Egypt_Inputs!$D$46
Name an_hno3_in: Egypt_Inputs!$D$47
Name an_nh3_in: Egypt_Inputs!$D$48
Name bf_coke: Egypt_Inputs!$D$16
Name bf_flux: Egypt_Inputs!$D$21
Name bf_pci: Egypt_Inputs!$D$17
Name bof_other_fuel: Egypt_Inputs!$D$20
Name c_to_co2: Factors!$D$35
Name cc_charge_carbon: Factors!$D$46
Name cc_coke: Factors!$D$50
Name cc_dri: Factors!$D$47
Name cc_electrode: Factors!$D$45
Name cc_pci_coal: Factors!$D$51
Name cc_pig_iron: Factors!$D$49
Name cc_steel: Factors!$D$48
Name clk_af_fossil: Egypt_Inputs!$D$29
Name clk_cao: Egypt_Inputs!$D$30
Name clk_cement_memo: Derivation!$D$34
Name clk_ckd: Egypt_Inputs!$D$32
Name clk_ef_mix: Derivation!$D$29
Name clk_mgo: Egypt_Inputs!$D$31
Name clk_ratio: Egypt_Inputs!$D$33
Name clk_sh_af: Egypt_Inputs!$D$28
Name clk_sh_coal: Egypt_Inputs!$D$24
Name clk_sh_hfo: Egypt_Inputs!$D$27
Name clk_sh_ng: Egypt_Inputs!$D$26
Name clk_sh_petcoke: Egypt_Inputs!$D$25
Name clk_thermal: Egypt_Inputs!$D$23
Name co2_per_urea: Factors!$D$39
Name dri_c_retained: Derivation!$D$7
Name dri_check: Derivation!$D$12
Name dri_co2_total: Derivation!$D$6
Name dri_feed_share: Egypt_Inputs!$D$7
Name dri_ng_total: Egypt_Inputs!$D$6
Name dri_per_steel: Egypt_Inputs!$D$8
Name eaf_charge_c_dri: Egypt_Inputs!$D$12
Name eaf_charge_c_scrap: Egypt_Inputs!$D$13
Name eaf_electrode: Egypt_Inputs!$D$11
Name eaf_limestone: Egypt_Inputs!$D$14
Name eaf_ng_dri: Egypt_Inputs!$D$9
Name eaf_ng_scrap: Egypt_Inputs!$D$10
Name ef_af_fossil: Factors!$D$13
Name ef_al_fc: Derivation!$D$60
Name ef_al_fp: Derivation!$D$61
Name ef_al_no: Derivation!$D$62
Name ef_al_np: Derivation!$D$59
Name ef_an_fc: Derivation!$D$53
Name ef_an_fp: Derivation!$D$54
Name ef_an_no: Derivation!$D$56
Name ef_an_np: Derivation!$D$55
Name ef_bof_fc: Derivation!$D$25
Name ef_bof_fp: Derivation!$D$24

Sheet ReadMe
A1: Egypt CBAM goods - direct emission factors, four-way split (v0.1)
A2: Auditable derivation of Scope 1 emission factors (tCO2e per t product) for the eight CBAM goods carried in CPAT_Industry_Kernel_Egypt ('Manual inputs' H30:K37). Methodology: EGY_CBAM_EF_Methodology_v0.1.md.
A4: Component | B4: Definition | C4: IPCC 2006 category | D4: CBAM IR 2023/1773 source stream
A5: fc | B5: Fuel combustion CO2: fuel burned for heat (kilns, reformer burners, EAF burners, boilers, baking furnaces). | C5: 1A2 Energy - manufacturing | D5: Combustion emissions (Annex III B.3)
A6: fp | B6: Fuel-based process CO2: fuel carbon entering the process as reductant or feedstock (NG reformer feed in DRI and ammonia, coke/PCI in a blast furnace), incl. carbon carried in DRI to the EAF. | C6: 2C1 (iron & steel), 2B1 (ammonia) | D6: Process emissions - mass balance (Annex III B.3.2 / B.4)
A7: np | B7: Non-fuel process CO2: carbonate decomposition (clinker, flux), carbon anodes, EAF electrodes and charge carbon; CO2 bound in urea under the IPCC netting convention (negative). | C7: 2A1 (cement), 2C3 (aluminium), 2C1 (electrodes/flux) | D7: Process emissions (Annex III B.3.2)
A8: no | B8: Non-CO2 process gases in CO2e: N2O from nitric acid (precursor of AN), CF4 and C2F6 from aluminium electrolysis. | C8: 2B2 (nitric acid), 2C3 (PFC) | D8: N2O (Annex III B.9.3), PFC (Annex III B.7)
A10: Sheet | B10: Content
A11: Sources | B11: Register of every source used (SourceID S01..). Every input row cites one or more SourceIDs.
A12: Settings | B12: Conventions: GWP set (CBAM/AR5 vs AR6); treatment of CO2 bound in urea (CBAM vs IPCC netting).
A13: Factors | B13: Standard factors: fuel EFs, GWPs, molar masses, stoichiometric factors, carbon contents, IPCC Tier 1 reference values. Each row = a defined name (column B).
A14: Egypt_Inputs | B14: Egypt-specific technology / activity parameters per process with value, range, tier (A plant data .. D international default), SourceID and note. Green cells are the only inputs.
A15: Derivation | B15: Step-by-step formulas per process (P1 DRI .. P10 aluminium). Column G shows the live formula text; outputs ef_<process>_<component> are defined names.
A16: Products | B16: Roll-up to the eight kernel goods: own-process EF by component, precursor (chain) EF by component, totals, comparison with kernel v0.12 and EU default / benchmark.
A17: Summary | B17: The deliverable table: four EFs per good (own process, as used by the kernel) plus chain totals, confidence grade and one-line derivation.
A18: Checks | B18: Balance, range and reconciliation checks; all must show OK.
A20: Colour | B20: Meaning
A21: green EBF1DE | B21: input (change only here)
A22: blue DCE6F1 | B22: code / defined name
... A26: no fill | B26: calculation
A28: Version log
A29: v0.1 | B29: 2026-10-02 | C29: Initial derivation; inputs are tier C/D estimates pending collection of Egyptian plant data (see Egypt_Inputs notes marked VERIFY).

Sheet Sources
A1: Sources register
A2: Every input in Factors and Egypt_Inputs cites a SourceID from this list. Type: Authoritative (official statistic / regulation / IPCC), Estimate (technology literature, to be replaced by Egyptian plant data), Proxy (non-Egypt data standing in), Internal (repo file).
A4: SourceID | B4: Short reference | C4: Full reference | D4: URL | E4: Type
A5: S01 | B5: IPCC 2006 Vol.2 Ch.1-2 | C5: IPCC (2006) Guidelines for National GHG Inventories, Vol. 2 Energy, Ch. 1-2 (Table 1.2 NCV, Table 2.2 p. 2.16 default CO2 emission factors for stationary combustion; verified from PDF: NG 56.1, other bituminous coal 94.6, residual fuel oil 77.4, petroleum coke 97.5, coke oven coke 107 tCO2/TJ) | D5: https://www.ipcc-nggip.iges.or.jp/public/2006gl/pdf/2_Volume2/V2_2_Ch2_Stationary_Combustion.pdf | E5: Authoritative
A6: S02 | B6: CBAM IR 2023/1773 Annex VIII / Guidance Doc 3 Tables 4-7..4-12 | C6: Commission Implementing Regulation (EU) 2023/1773, Annex VIII standard factors; EC CBAM Guidance Document 3 (Methodology), Tables 4-7 to 4-12 (fuel EFs, carbonate stoichiometric factors, carbon contents of process materials, GWPs) | D6: https://taxation-customs.ec.europa.eu/carbon-border-adjustment-mechanism_en | E6: Authoritative
A7: S03 | B7: IPCC 2006 Vol.3 Ch.2 (2A1 cement) | C7: IPCC (2006) Vol. 3 IPPU, Ch. 2 Mineral industry: Eq. 2.4 (p. 2.12) Tier 1 clinker EF 0.52 tCO2/t (0.51 at 65% CaO x CKD correction 1.02); Table 2.4 (p. 2.22) stoichiometric 0.785 tCO2/t CaO. NOTE: the MgO factor 1.092 is NOT printed in IPCC; it is the derived molar ratio 44.01/40.30 used by GCCA/CSI and EU ETS (computed here from molar masses). | D7: https://www.ipcc-nggip.iges.or.jp/public/2006gl/pdf/3_Volume3/V3_2_Ch2_Mineral_Industry.pdf | E7: Authoritative
A8: S04 | B8: IPCC 2006 Vol.3 Ch.3 (2B1 ammonia, 2B2 nitric acid) | C8: IPCC (2006) Vol. 3 Ch. 3 Chemical industry: Table 3.1 (p. 3.15) ammonia total fuel requirement and EF (modern conventional/autothermal reforming NG 30.2 GJ/t, 1.694 tCO2/t; European average, mix of modern and older NG plants 37.5 GJ/t, 2.104 tCO2/t; CCF 15.3 kgC/GJ); Table 3.3 (p. 3.23) nitric acid N2O defaults (kg N2O/t HNO3). Verified from PDF. | D8: https://www.ipcc-nggip.iges.or.jp/public/2006gl/pdf/3_Volume3/V3_3_Ch3_Chemical_Industry.pdf | E8: Authoritative
A9: S05 | B9: IPCC 2006 Vol.3 Ch.4 (2C1 iron & steel, 2C3 aluminium) | C9: IPCC (2006) Vol. 3 Ch. 4 Metal industry: Table 4.1 iron & steel Tier 1 EFs; Table 4.10 anode CO2 (prebake 1.6, Soderberg 1.7 tCO2/t Al); Table 4.15 Tier 1 PFC EFs by cell technology (CWPB 0.4 kg CF4/t, 0.04 kg C2F6/t) | D9: https://www.ipcc-nggip.iges.or.jp/public/2006gl/pdf/3_Volume3/V3_4_Ch4_Metal_Industry.pdf | E9: Authoritative
A10: S06 | B10: IPCC AR6 WGI Ch.7 Table 7.SM.7 | C10: IPCC (2021) AR6 WGI, GWP100: N2O 273, CF4 7380, C2F6 12400 | D10: https://www.ipcc.ch/report/ar6/wg1/ | E10: Authoritative
A11: S07 | B11: Midrex process energy | C11: Midrex Technologies, process descriptions / World DRI Statistics: natural-gas Midrex plants consume about 10-11 GJ NG per t DRI (approx. 2.5 Gcal/t), of which the larger part is reformed to reducing gas and the remainder fired in the reformer burners together with recycled top gas | D11: https://www.midrex.com/ | E11: Estimate
A12: S08 | B12: World Steel Association | C12: worldsteel annual crude steel production (Egypt: 2020 8.2, 2021 10.3, 2022 9.8, 2023 10.4, 2024 10.7 Mt; read via secondary aggregation, verify against World Steel in Figures). Route: 100% EAF assumed; EISCO Helwan BF closure (2021) is widely reported but NOT yet confirmed from a citable primary source - VERIFY | D12: https://worldsteel.org/data/annual-production-steel-data/ | E12: Estimate
A13: S08b | B13: Ezz Steel (EZDK) corporate | C13: Ezz Steel plant pages: integrated route = direct reduction plants (three Midrex, one HYL/Energiron at Suez) feeding EAFs; charge ~80% DRI + scrap; ~5 Mt DRI/yr (2017 figure) | D13: https://www.ezzsteel.com/ezz-steel-plants | E13: Authoritative
A14: S09 | B14: GCCA GNR / IEA cement | C14: GCCA Getting the Numbers Right (GNR) database and IEA cement tracking: thermal energy intensity 3.3-3.7 GJ/t clinker for dry preheater/precalciner kilns; Egypt fuel switch to coal/petcoke after the 2014 authorisation | D14: https://gccassociation.org/sustainability-innovation/gnr-gcca-in-numbers/ | E14: Estimate
A15: S10 | B15: IFA / EFMA BAT ammonia | C15: Fertilizers Europe (EFMA) BAT booklet No. 1 (ammonia) and IFA energy benchmarking: NG feedstock about 22-24 GJ/t NH3, fuel 7-14 GJ/t NH3 depending on plant vintage; stoichiometric minimum about 20.9 GJ/t | D15: https://www.fertilizerseurope.com/ | E15: Estimate
... A18: S13 | B18: Kernel v0.12 Manual inputs | C18: CPAT_Industry_Kernel_Egypt_v0.12.xlsx, sheet 'Manual inputs' rows 30-37 (EF block unchanged since v0.6) (current EF values, EU default values and benchmarks as recorded there; EU values to be re-verified against the Official Journal) | D18: cpat_excel_new/standalone_working_version/ | E18: Internal
A19: S14 | B19: Egypt plant structure (analyst) | C19: Analyst assessment of Egypt's plant fleet: steel = NG-based Midrex DRI + EAF (Ezz, Suez Steel, Beshay) and scrap-EAF mills; cement = dry kilns, coal/petcoke-fired since 2014-16; ammonia = NG SMR (Abu Qir, MOPCO, EFC, Helwan, KIMA, El Nasr, Alexfert); aluminium = Egyptalum Nag Hammadi prebake. To be replaced by cited plant data as collected. | E19: Estimate
A20: S15 | B20: Stoichiometry | C20: Molar masses (IUPAC) and reaction stoichiometry: CO2/C = 44.009/12.011; CaO, MgO carbonate factors; urea CO(NH2)2 = 60.056; NH3 = 17.031; HNO3 = 63.012; NH4NO3 = 80.043 | E20: Authoritative

Sheet Settings
A1: Settings - conventions
A2: Switches read by the derivation (tan cells). Change here only.
A4: Code | B4: Setting | C4: Value | D4: Allowed | E4: Note
A5: gwp_set | B5: GWP set for N2O and PFCs | C5: CBAM | D5: CBAM | AR6 | E5: CBAM = Implementing Regulation 2023/1773 Annex VIII (AR5 values, used by EU ETS/CBAM). AR6 for inventory-style reporting.
A6: urea_conv | B6: Treatment of CO2 chemically bound in urea | C6: CBAM | D6: CBAM | IPCC | E6: CBAM: CO2 consumed in urea is counted as emitted at the ammonia plant and NOT deducted (Guidance 5c s.3.1.1); urea np = 0. IPCC: inventory netting - bound CO2 deducted at the urea plant (np = -0.733) and released on soil application (AFOLU 3C3). Kernel v0.12 uses IPCC.
A7: ref_year | B7: Reference year of the Egypt inputs | C7: 2022 | D7: year | E7: Base year of the kernel (Settings!B6).

Sheet Factors
A1: Standard factors
A2: Fuel emission factors, GWPs, stoichiometry and carbon contents. Column B is the defined name used in Derivation. Formulas (no fill) derive stoichiometric factors from molar masses.
B4: Code | C4: Description | D4: Value | E4: Unit | F4: Source | G4: Note
A5: Fuel CO2 emission factors (net calorific value basis), oxidation factor 1
B6: ef_ng | C6: Natural gas | D6: 0.0561 | E6: tCO2/GJ | F6: S01;S02 | G6: 56.1 tCO2/TJ
B7: ef_coal | C7: Other bituminous coal (steam coal) | D7: 0.0946 | E7: tCO2/GJ | F7: S01;S02 | G7: 94.6 tCO2/TJ
B8: ef_petcoke | C8: Petroleum coke | D8: 0.0975 | E8: tCO2/GJ | F8: S01;S02 | G8: 97.5 tCO2/TJ
B9: ef_hfo | C9: Residual fuel oil (mazut) | D9: 0.0774 | E9: tCO2/GJ | F9: S01;S02 | G9: 77.4 tCO2/TJ
B10: ef_diesel | C10: Gas/diesel oil | D10: 0.0741 | E10: tCO2/GJ | F10: S01;S02 | G10: 74.1 tCO2/TJ
B11: ef_coke | C11: Coke oven coke | D11: 0.107 | E11: tCO2/GJ | F11: S01;S02 | G11: 107 tCO2/TJ
B12: ef_cog | C12: Coke oven gas | D12: 0.0444 | E12: tCO2/GJ | F12: S01;S02 | G12: 44.4 tCO2/TJ
B13: ef_af_fossil | C13: Fossil fraction of waste-derived fuels (RDF, tyres) | D13: 0.0917 | E13: tCO2/GJ | F13: S01;S02 | G13: IPCC MSW fossil fraction 91.7 tCO2/TJ; biogenic fraction counted as zero
B14: oxf | C14: Oxidation factor | D14: 1 | E14: - | F14: S01;S02 | G14: IPCC / CBAM default
A15: Global warming potentials (GWP100), tCO2e per t gas
B16: gwp_n2o_cbam | C16: N2O - CBAM / EU MRR (AR5) | D16: 265 | E16: tCO2e/t | F16: S02
B17: gwp_cf4_cbam | C17: CF4 - CBAM / EU MRR (AR5) | D17: 6630 | E17: tCO2e/t | F17: S02
B18: gwp_c2f6_cbam | C18: C2F6 - CBAM / EU MRR (AR5) | D18: 11100 | E18: tCO2e/t | F18: S02
B19: gwp_n2o_ar6 | C19: N2O - IPCC AR6 | D19: 273 | E19: tCO2e/t | F19: S06
B20: gwp_cf4_ar6 | C20: CF4 - IPCC AR6 | D20: 7380 | E20: tCO2e/t | F20: S06
B21: gwp_c2f6_ar6 | C21: C2F6 - IPCC AR6 | D21: 12400 | E21: tCO2e/t | F21: S06
B22: gwp_n2o | C22: N2O - selected set (Settings!gwp_set) | D22: =IF(gwp_set="AR6",gwp_n2o_ar6,gwp_n2o_cbam) -> 265 | E22: tCO2e/t | F22: calc
B23: gwp_cf4 | C23: CF4 - selected set | D23: =IF(gwp_set="AR6",gwp_cf4_ar6,gwp_cf4_cbam) -> 6630 | E23: tCO2e/t | F23: calc
B24: gwp_c2f6 | C24: C2F6 - selected set | D24: =IF(gwp_set="AR6",gwp_c2f6_ar6,gwp_c2f6_cbam) -> 11100 | E24: tCO2e/t | F24: calc
A25: Molar masses and stoichiometric factors
B26: m_c | C26: Carbon | D26: 12.011 | E26: g/mol | F26: S15
B27: m_co2 | C27: CO2 | D27: 44.009 | E27: g/mol | F27: S15
B28: m_cao | C28: CaO | D28: 56.077 | E28: g/mol | F28: S15
B29: m_mgo | C29: MgO | D29: 40.304 | E29: g/mol | F29: S15
B30: m_nh3 | C30: NH3 | D30: 17.031 | E30: g/mol | F30: S15
B31: m_urea | C31: Urea CO(NH2)2 | D31: 60.056 | E31: g/mol | F31: S15
B32: m_hno3 | C32: HNO3 | D32: 63.012 | E32: g/mol | F32: S15
B33: m_an | C33: NH4NO3 | D33: 80.043 | E33: g/mol | F33: S15
B34: m_caco3 | C34: CaCO3 | D34: 100.086 | E34: g/mol | F34: S15
B35: c_to_co2 | C35: tCO2 per t carbon | D35: =m_co2/m_c -> 3.6640579 | E35: t/t | F35: calc | G35: 3.664
B36: ef_caco3 | C36: tCO2 per t CaCO3 (limestone) calcined (CBAM Method A) | D36: =m_co2/m_caco3 -> 0.43971185 | E36: t/t | F36: calc;S02 | G36: 0.440
B37: ef_cao | C37: tCO2 per t CaO from CaCO3 (CBAM Method B) | D37: =m_co2/m_cao -> 0.78479591 | E37: t/t | F37: calc;S02 | G37: 0.785
B38: ef_mgo | C38: tCO2 per t MgO from MgCO3 (CBAM Method B) | D38: =m_co2/m_mgo -> 1.0919264 | E38: t/t | F38: calc;S02 | G38: 1.092
B39: co2_per_urea | C39: CO2 chemically bound per t urea | D39: =m_co2/m_urea -> 0.73279939 | E39: t/t | F39: calc | G39: 0.733
B40: nh3_per_urea_st | C40: NH3 per t urea (stoichiometric) | D40: =2*m_nh3/m_urea -> 0.56717064 | E40: t/t | F40: calc | G40: 0.567
B41: hno3_per_an_st | C41: HNO3 (100%) per t AN (stoichiometric) | D41: =m_hno3/m_an -> 0.78722687 | E41: t/t | F41: calc | G41: 0.787
...

Sheet Egypt_Inputs
A1: Egypt-specific inputs
A2: One row per technology / activity parameter. Tier: A = Egyptian plant data, B = Egyptian sector statistic, C = technology default calibrated to Egypt's plant fleet, D = international / IPCC default. Low/High give the plausible range (used for sensitivity in Checks). Rows marked VERIFY are the priority for data collection.
B4: Code | C4: Description | D4: Value | E4: Unit | F4: Low | G4: High | H4: Tier | I4: Source | J4: Note
A5: STEEL - DRI (Midrex, natural gas) and EAF
B6: dri_ng_total | C6: Natural gas use of the DRI plant, total (reformer feed + burner fuel) | D6: 10.5 | E6: GJ/t DRI | F6: 9.6 | G6: 11.5 | H6: C | I6: S07;S14 | J6: Midrex NG plants ~2.5 Gcal/t DRI; Egypt plants are Midrex (Ezz, Suez, Beshay).
B7: dri_feed_share | C7: Share of DRI natural gas that is reformed to reducing gas (reductant / feedstock) | D7: 0.75 | E7: share | F7: 0.7 | G7: 0.8 | H7: C | I7: S07 | J7: Remainder is fired in the reformer burners (with recycled top gas) = fc.
B8: dri_per_steel | C8: DRI charged per t crude steel on the DRI-EAF route | D8: 0.98 | E8: t DRI/t steel | F8: 0.9 | G8: 1.1 | H8: C | I8: S14 | J8: ~85% DRI / 15% scrap charge, ~1.15 t metallics per t liquid steel.
B9: eaf_ng_dri | C9: EAF meltshop natural gas (burners, ladle furnace, preheating), DRI-EAF route | D9: 0.6 | E9: GJ/t steel | F9: 0.3 | G9: 1.2 | H9: C | I9: S14 | J9: Crude-steel boundary: reheating furnaces for rolling excluded.
B10: eaf_ng_scrap | C10: EAF meltshop natural gas, scrap-EAF route | D10: 0.8 | E10: GJ/t steel | F10: 0.4 | G10: 1.5 | H10: C | I10: S14 | J10: Scrap melting uses more oxy-fuel burner energy than hot/warm DRI charging.
B11: eaf_electrode | C11: Graphite electrode consumption | D11: 2.5 | E11: kg/t steel | F11: 1.5 | G11: 3.5 | H11: C | I11: S14
B12: eaf_charge_c_dri | C12: Charge / injection carbon, DRI-EAF route | D12: 10 | E12: kg/t steel | F12: 5 | G12: 20 | H12: C | I12: S14 | J12: Slag foaming carbon; DRI carbon (cc_dri) supplies part of the carbon need.
B13: eaf_charge_c_scrap | C13: Charge / injection carbon, scrap-EAF route | D13: 12 | E13: kg/t steel | F13: 5 | G13: 20 | H13: C | I13: S14
B14: eaf_limestone | C14: Limestone / dolomite charged directly (not pre-burnt lime) | D14: 0 | E14: kg/t steel | F14: 0 | G14: 30 | H14: C | I14: S14 | J14: Egypt EAFs charge purchased lime; its CO2 is emitted at the lime kiln (outside the steel boundary).
A15: STEEL - BF-BOF (reference route only; no Egyptian production since 2021)
B16: bf_coke | C16: Coke rate | D16: 0.35 | E16: t/t hot metal | F16: 0.3 | G16: 0.45 | H16: D | I16: S05;S08 | J16: Global average ~ 350 kg/t HM
B17: bf_pci | C17: Pulverised coal injection | D17: 0.15 | E17: t/t hot metal | F17: 0.1 | G17: 0.2 | H17: D | I17: S05;S08
B18: hm_c | C18: Carbon content of hot metal | D18: 0.045 | E18: tC/t HM | F18: 0.04 | G18: 0.048 | H18: D | I18: S02
B19: hm_per_steel | C19: Hot metal per t crude steel (BOF) | D19: 0.95 | E19: t HM/t steel | F19: 0.85 | G19: 1 | H19: D | I19: S08
B20: bof_other_fuel | C20: Other fuels burned per t steel (coke ovens, sinter, stoves net of BF gas, BOF) | D20: 3 | E20: GJ/t steel | F20: 2 | G20: 5 | H20: D | I20: S08 | J20: Works gases are derived from the coke/coal carbon counted in fp; this row is for purchased NG/oil only.
B21: bf_flux | C21: Limestone + dolomite flux (sinter plant, BF, BOF) | D21: 0.12 | E21: t/t steel | F21: 0.08 | G21: 0.2 | H21: D | I21: S05
A22: CEMENT - grey clinker, dry process
B23: clk_thermal | C23: Kiln thermal energy | D23: 3.5 | E23: GJ/t clinker | F23: 3.2 | G23: 3.9 | H23: C | I23: S09;S14 | J23: Dry 4-5 stage preheater kilns; Egyptian kilns burning coal/petcoke tend to the upper half of the range.
B24: clk_sh_coal | C24: Fuel share - coal | D24: 0.45 | E24: share of GJ | F24: 0.3 | G24: 0.6 | H24: C | I24: S09;S14 | J24: Post-2014 fuel switch.
B25: clk_sh_petcoke | C25: Fuel share - petroleum coke | D25: 0.4 | E25: share of GJ | F25: 0.25 | G25: 0.55 | H25: C | I25: S09;S14
B26: clk_sh_ng | C26: Fuel share - natural gas | D26: 0.05 | E26: share of GJ | F26: 0 | G26: 0.2 | H26: C | I26: S09;S14
B27: clk_sh_hfo | C27: Fuel share - heavy fuel oil | D27: 0.02 | E27: share of GJ | F27: 0 | G27: 0.1 | H27: C | I27: S09;S14
B28: clk_sh_af | C28: Fuel share - alternative fuels (RDF, tyres, biomass) | D28: 0.08 | E28: share of GJ | F28: 0.03 | G28: 0.15 | H28: C | I28: S09;S14 | J28: Shares must sum to 1 (Checks).
B29: clk_af_fossil | C29: Fossil fraction of alternative fuels (energy basis) | D29: 0.5 | E29: share | F29: 0.3 | G29: 0.7 | H29: D | I29: S01
B30: clk_cao | C30: CaO content of clinker | D30: 0.65 | E30: t/t clinker | F30: 0.63 | G30: 0.67 | H30: C | I30: S03;S14 | J30: Typical Portland clinker.
B31: clk_mgo | C31: MgO content of clinker (from carbonate) | D31: 0.015 | E31: t/t clinker | F31: 0.01 | G31: 0.03 | H31: C | I31: S03;S14
B32: clk_ckd | C32: Cement kiln dust / bypass dust correction factor | D32: 1.02 | E32: - | F32: 1 | G32: 1.05 | H32: D | I32: S03 | J32: IPCC Tier 1 default; Egyptian kilns with chlorine bypass may be higher.
B33: clk_ratio | C33: Clinker-to-cement ratio (memo, for cement EF) | D33: 0.85 | E33: t clinker/t cement | F33: 0.75 | G33: 0.92 | H33: C | I33: S09;S14 | J33: Egypt produces mostly CEM I / CEM II with high clinker factor.
A34: AMMONIA - steam methane reforming + Haber-Bosch
B35: nh3_ng_total | C35: Natural gas use of the ammonia plant, total (feedstock + fuel) | D35: 35.2 | E35: GJ/t NH3 | F35: 30.2 | G35: 37.5 | H35: D | I35: S04;S10;S14 | J35: VERIFY. Egypt fleet of Uhde/KBR plants (1979-2019 vintage): analyst mid-point between IPCC Table 3.1 modern plants (30.2 GJ/t) and European average of mixed vintage (37.5 GJ/t), used until plant data are collected. The kernel's EU Egypt default 2.05 tCO2/t implies ~36.5 GJ/t.
B36: nh3_ng_feed | C36: Natural gas used as feedstock (reformer feed -> H2 + process CO2) | D36: 22.5 | E36: GJ/t NH3 | F36: 21 | G36: 24 | H36: C | I36: S10 | J36: Yields the concentrated process-CO2 stream (~1.2-1.3 tCO2/t NH3).
A37: UREA - synthesis from NH3 and process CO2
B38: urea_fuel | C38: Natural gas for steam attributable to the urea plant | D38: 2 | E38: GJ/t urea | F38: 1.5 | G38: 3 | H38: C | I38: S10;S14 | J38: Steam usually from the ammonia complex; attributed to urea per CBAM measurable-heat rules.
B39: urea_nh3_in | C39: Ammonia input per t urea | D39: 0.57 | E39: t NH3/t urea | F39: 0.567 | G39: 0.58 | H39: C | I39: S15 | J39: Stoich. 0.567 + losses
A40: NITRIC ACID (precursor of AN) - Ostwald process
B41: hno3_n2o_unab | C41: N2O generation, unabated medium-pressure plant | D41: 7 | E41: kg N2O/t HNO3 | F41: 4 | G41: 10 | H41: D | I41: S04 | J41: IPCC Table 3.3
...

Sheet Derivation
A1: Derivation - step by step
A2: Each process block computes the four components from named inputs. Column D holds the formula, column G its live text (FORMULATEXT). Rows with an ef_ code are the outputs (yellow) and become defined names used in Products.
B4: Step / output code | C4: Description | D4: Value | E4: Unit | F4: Component | G4: Formula | H4: Note
A5: P1 DRI - direct reduced iron (per t DRI)
B6: dri_co2_total | C6: Total CO2 from natural gas carbon entering the DRI plant | D6: =dri_ng_total*ef_ng*oxf -> 0.58905 | E6: tCO2/t DRI | G6: =_xlfn.FORMULATEXT(D6) -> =dri_ng_total*ef_ng*oxf | H6: All NG carbon ends as CO2 except the carbon retained in the DRI.
B7: dri_c_retained | C7: CO2-equivalent of carbon retained in the DRI (released later in the EAF) | D7: =cc_dri*c_to_co2 -> 0.069983507 | E7: tCO2/t DRI | G7: =_xlfn.FORMULATEXT(D7) -> =cc_dri*c_to_co2 | H7: CBAM Table 4-11 carbon content 1.91%
B8: ef_dri_fp | C8: fp: reformer feed gas carbon (reductant), net of carbon retained in DRI | D8: =dri_ng_total*dri_feed_share*ef_ng*oxf-dri_c_retained -> 0.37180399 | E8: tCO2/t DRI | F8: fp | G8: =_xlfn.FORMULATEXT(D8) -> =dri_ng_total*dri_feed_share*ef_ng*oxf-dri_c_retained | H8: Reductant carbon: CO in the reducing gas oxidised to CO2 in the shaft; top gas then burned.
B9: ef_dri_fc | C9: fc: reformer burner fuel gas | D9: =dri_ng_total*(1-dri_feed_share)*ef_ng*oxf -> 0.1472625 | E9: tCO2/t DRI | F9: fc | G9: =_xlfn.FORMULATEXT(D9) -> =dri_ng_total*(1-dri_feed_share)*ef_ng*oxf | H9: Natural gas fired directly in the reformer burners (recycled top gas is already counted in fp).
B10: ef_dri_np | C10: np: none | D10: =0 -> 0 | E10: tCO2/t DRI | F10: np | G10: =_xlfn.FORMULATEXT(D10) -> =0 | H10: No carbonate flux in the shaft furnace.
B11: ef_dri_no | C11: no: none | D11: =0 -> 0 | E11: tCO2e/t DRI | F11: no | G11: =_xlfn.FORMULATEXT(D11) -> =0
B12: dri_check | C12: Check: fc + fp + retained = total | D12: =ef_dri_fc+ef_dri_fp+dri_c_retained-dri_co2_total -> 0 | E12: tCO2/t DRI | G12: =_xlfn.FORMULATEXT(D12) -> =ef_dri_fc+ef_dri_fp+dri_c_retained-dri_co2_total | H12: Must be 0
A13: P2 EAF on the DRI route (per t crude steel, meltshop only)
B14: ef_eafd_fc | C14: fc: natural gas burners / ladle furnace | D14: =eaf_ng_dri*ef_ng*oxf -> 0.03366 | E14: tCO2/t steel | F14: fc | G14: =_xlfn.FORMULATEXT(D14) -> =eaf_ng_dri*ef_ng*oxf
B15: ef_eafd_fp | C15: fp: carbon carried in the DRI, oxidised in the EAF, net of carbon in steel | D15: =dri_per_steel*dri_c_retained-cc_steel*c_to_co2 -> 0.028645605 | E15: tCO2/t steel | F15: fp | G15: =_xlfn.FORMULATEXT(D15) -> =dri_per_steel*dri_c_retained-cc_steel*c_to_co2 | H15: Reductant-derived carbon; completes the DRI carbon balance.
B16: ef_eafd_np | C16: np: electrodes + charge carbon + direct limestone | D16: =(eaf_electrode*cc_electrode+eaf_charge_c_dri*cc_charge_carbon)/1000*c_to_co2+eaf_limestone/1000*ef_caco3 -> 0.037901015 | E16: tCO2/t steel | F16: np | G16: =_xlfn.FORMULATEXT(D16) -> =(eaf_electrode*cc_electrode+eaf_charge_c_dri*cc_charge_carbon)/1000*c_to_co2+eaf_limestone/1000*ef_caco3 | H16: 0.44 tCO2/t CaCO3 (CBAM Table 4-9). Non-fuel process materials.
B17: ef_eafd_no | C17: no: none | D17: =0 -> 0 | E17: tCO2e/t steel | F17: no | G17: =_xlfn.FORMULATEXT(D17) -> =0
A18: P3 EAF on the scrap route (per t crude steel)
B19: ef_eafs_fc | C19: fc: natural gas burners / ladle furnace | D19: =eaf_ng_scrap*ef_ng*oxf -> 0.04488 | E19: tCO2/t steel | F19: fc | G19: =_xlfn.FORMULATEXT(D19) -> =eaf_ng_scrap*ef_ng*oxf
B20: ef_eafs_fp | C20: fp: none (no reductant) | D20: =0 -> 0 | E20: tCO2/t steel | F20: fp | G20: =_xlfn.FORMULATEXT(D20) -> =0 | H20: Scrap carbon (1.1%) ~ carbon in product.
B21: ef_eafs_np | C21: np: electrodes + charge carbon + direct limestone | D21: =(eaf_electrode*cc_electrode+eaf_charge_c_scrap*cc_charge_carbon)/1000*c_to_co2+eaf_limestone/1000*ef_caco3 -> 0.043981153 | E21: tCO2/t steel | F21: np | G21: =_xlfn.FORMULATEXT(D21) -> =(eaf_electrode*cc_electrode+eaf_charge_c_scrap*cc_charge_carbon)/1000*c_to_co2+eaf_limestone/1000*ef_caco3
B22: ef_eafs_no | C22: no: none | D22: =0 -> 0 | E22: tCO2e/t steel | F22: no | G22: =_xlfn.FORMULATEXT(D22) -> =0
A23: P4 BF-BOF reference route (per t crude steel) - no Egyptian production
B24: ef_bof_fp | C24: fp: coke + PCI carbon into the blast furnace, net of carbon in hot metal and steel | D24: =((bf_coke*cc_coke+bf_pci*cc_pci_coal-hm_c)*hm_per_steel-cc_steel)*c_to_co2 -> 1.2566803 | E24: tCO2/t steel | F24: fp | G24: =_xlfn.FORMULATEXT(D24) -> =((bf_coke*cc_coke+bf_pci*cc_pci_coal-hm_c)*hm_per_steel-cc_steel)*c_to_co2 | H24: Includes CO2 from BF gas burned in stoves / power plant (carbon entered as reductant).
B25: ef_bof_fc | C25: fc: other purchased fuels | D25: =bof_other_fuel*ef_ng*oxf -> 0.1683 | E25: tCO2/t steel | F25: fc | G25: =_xlfn.FORMULATEXT(D25) -> =bof_other_fuel*ef_ng*oxf | H25: Assumed natural gas; coal for coke ovens is in cc_coke via coke rate (simplification).
B26: ef_bof_np | C26: np: limestone / dolomite flux | D26: =bf_flux*ef_caco3 -> 0.052765422 | E26: tCO2/t steel | F26: np | G26: =_xlfn.FORMULATEXT(D26) -> =bf_flux*ef_caco3 | H26: limestone basis
B27: ef_bof_no | C27: no: none | D27: =0 -> 0 | E27: tCO2e/t steel | F27: no | G27: =_xlfn.FORMULATEXT(D27) -> =0
A28: P5 Clinker (per t clinker)
B29: clk_ef_mix | C29: Weighted fuel EF of the kiln fuel mix | D29: =clk_sh_coal*ef_coal+clk_sh_petcoke*ef_petcoke+clk_sh_ng*ef_ng+clk_sh_hfo*ef_hfo+clk_sh_af*clk_af_fossil*ef_af_fossil -> 0.089591 | E29: tCO2/GJ | G29: =_xlfn.FORMULATEXT(D29) -> =clk_sh_coal*ef_coal+clk_sh_petcoke*ef_petcoke+clk_sh_ng*ef_ng+clk_sh_hfo*ef_hfo+clk_sh_af*clk_af_fossil*ef_af_fossil | H29: Biogenic share of alternative fuels counted as zero.
B30: ef_clk_fc | C30: fc: kiln fuel combustion | D30: =clk_thermal*clk_ef_mix*oxf -> 0.3135685 | E30: tCO2/t clinker | F30: fc | G30: =_xlfn.FORMULATEXT(D30) -> =clk_thermal*clk_ef_mix*oxf
B31: ef_clk_fp | C31: fp: none | D31: =0 -> 0 | E31: tCO2/t clinker | F31: fp | G31: =_xlfn.FORMULATEXT(D31) -> =0
B32: ef_clk_np | C32: np: calcination of CaCO3 and MgCO3, corrected for kiln dust | D32: =(clk_cao*ef_cao+clk_mgo*ef_mgo)*clk_ckd -> 0.53702616 | E32: tCO2/t clinker | F32: np | G32: =_xlfn.FORMULATEXT(D32) -> =(clk_cao*ef_cao+clk_mgo*ef_mgo)*clk_ckd | H32: CBAM Method B / IPCC Tier 2
B33: ef_clk_no | C33: no: none | D33: =0 -> 0 | E33: tCO2e/t clinker | F33: no | G33: =_xlfn.FORMULATEXT(D33) -> =0
B34: clk_cement_memo | C34: Memo: direct EF per t cement (clinker share only; grinding is electricity) | D34: =(ef_clk_fc+ef_clk_np)*clk_ratio -> 0.72300546 | E34: tCO2/t cement | G34: =_xlfn.FORMULATEXT(D34) -> =(ef_clk_fc+ef_clk_np)*clk_ratio | H34: Not a CBAM EF row; shown for reference.
A35: P6 Ammonia (per t NH3)
B36: nh3_ng_fuel | C36: Natural gas burned as fuel (total - feedstock) | D36: =nh3_ng_total-nh3_ng_feed -> 12.7 | E36: GJ/t NH3 | G36: =_xlfn.FORMULATEXT(D36) -> =nh3_ng_total-nh3_ng_feed
B37: ef_nh3_fp | C37: fp: feedstock carbon -> process CO2 stream (all counted as emitted; see urea_conv) | D37: =nh3_ng_feed*ef_ng*oxf -> 1.26225 | E37: tCO2/t NH3 | F37: fp | G37: =_xlfn.FORMULATEXT(D37) -> =nh3_ng_feed*ef_ng*oxf | H37: Under the CBAM convention CO2 transferred to urea remains an emission of the ammonia plant.
B38: ef_nh3_fc | C38: fc: reformer and auxiliary boiler fuel | D38: =nh3_ng_fuel*ef_ng*oxf -> 0.71247 | E38: tCO2/t NH3 | F38: fc | G38: =_xlfn.FORMULATEXT(D38) -> =nh3_ng_fuel*ef_ng*oxf
B39: ef_nh3_np | C39: np: none | D39: =0 -> 0 | E39: tCO2/t NH3 | F39: np | G39: =_xlfn.FORMULATEXT(D39) -> =0
B40: ef_nh3_no | C40: no: none | D40: =0 -> 0 | E40: tCO2e/t NH3 | F40: no | G40: =_xlfn.FORMULATEXT(D40) -> =0
A41: P7 Urea synthesis (per t urea, own process)
...

Sheet Products
A1: Products - roll-up to the kernel goods
A2: Own-process EF = sum of the process steps of the route. Precursor (chain) EF = precursor quantity x precursor EF, component by component (so fuel carbon in ammonia stays fp when embedded in urea). Kernel v0.12 and EU values are hard-coded references (S13).
A4: Product | B4: Unit | C4: Kernel row | D4: Own fc | E4: Own fp | F4: Own np | G4: Own no | H4: Own total | I4: Precursors | J4: Chain fc | K4: Chain fp | L4: Chain np | M4: Chain no | N4: Chain total | O4: Kernel fc | P4: Kernel fp | Q4: Kernel np | R4: Kernel no | S4: Kernel embed NH3 | T4: Kernel total | U4: Own - kernel own | V4: EU default base | W4: Own total / EU default | X4: EU benchmark
A5: DRI-EAF steel | B5: t crude steel | C5: 'Manual inputs'!30 | D5: =dri_per_steel*ef_dri_fc+1*ef_eafd_fc -> 0.17797725 | E5: =dri_per_steel*ef_dri_fp+1*ef_eafd_fp -> 0.39301352 | F5: =dri_per_steel*ef_dri_np+1*ef_eafd_np -> 0.037901015 | G5: =dri_per_steel*ef_dri_no+1*ef_eafd_no -> 0 | H5: =SUM(D5:G5) -> 0.60889178 | I5: - | J5: =0 -> 0 | K5: =0 -> 0 | L5: =0 -> 0 | M5: =0 -> 0 | N5: =H5+SUM(J5:M5) -> 0.60889178 | O5: 0.12903 | P5: 0.561 | Q5: 0.04 | R5: 0 | S5: 0 | T5: =SUM(O5:S5) -> 0.73003 | U5: =H5-SUM(O5:R5) -> -0.12113822 | V5: 1.82 | W5: =IF(V5>0,N5/V5,"") -> 0.33455593 | X5: 0.481
A6: Scrap-EAF steel | B6: t crude steel | C6: 'Manual inputs'!31 | D6: =1*ef_eafs_fc -> 0.04488 | E6: =1*ef_eafs_fp -> 0 | F6: =1*ef_eafs_np -> 0.043981153 | G6: =1*ef_eafs_no -> 0 | H6: =SUM(D6:G6) -> 0.088861153 | I6: - | J6: =0 -> 0 | K6: =0 -> 0 | L6: =0 -> 0 | M6: =0 -> 0 | N6: =H6+SUM(J6:M6) -> 0.088861153 | O6: 0.14025 | P6: 0 | Q6: 0.015 | R6: 0 | S6: 0 | T6: =SUM(O6:S6) -> 0.15525 | U6: =H6-SUM(O6:R6) -> -0.066388847 | V6: 0.72 | W6: =IF(V6>0,N6/V6,"") -> 0.12341827 | X6: 0.072
A7: BF-BOF steel (reference) | B7: t crude steel | C7: 'Manual inputs'!32 | D7: =1*ef_bof_fc -> 0.1683 | E7: =1*ef_bof_fp -> 1.2566803 | F7: =1*ef_bof_np -> 0.052765422 | G7: =1*ef_bof_no -> 0 | H7: =SUM(D7:G7) -> 1.4777457 | I7: - | J7: =0 -> 0 | K7: =0 -> 0 | L7: =0 -> 0 | M7: =0 -> 0 | N7: =H7+SUM(J7:M7) -> 1.4777457 | O7: 0.3844 | P7: 1.5376 | Q7: 0.25 | R7: 0 | S7: 0 | T7: =SUM(O7:S7) -> 2.172 | U7: =H7-SUM(O7:R7) -> -0.6942543 | V7: 2.8 | W7: =IF(V7>0,N7/V7,"") -> 0.52776632 | X7: 1.37
A8: Grey clinker (dry-process) | B8: t clinker | C8: 'Manual inputs'!33 | D8: =1*ef_clk_fc -> 0.3135685 | E8: =1*ef_clk_fp -> 0 | F8: =1*ef_clk_np -> 0.53702616 | G8: =1*ef_clk_no -> 0 | H8: =SUM(D8:G8) -> 0.85059466 | I8: - | J8: =0 -> 0 | K8: =0 -> 0 | L8: =0 -> 0 | M8: =0 -> 0 | N8: =H8+SUM(J8:M8) -> 0.85059466 | O8: 0.2883 | P8: 0 | Q8: 0.526 | R8: 0 | S8: 0 | T8: =SUM(O8:S8) -> 0.8143 | U8: =H8-SUM(O8:R8) -> 0.036294659 | V8: 1.58 | W8: =IF(V8>0,N8/V8,"") -> 0.53835105 | X8: 0.666
A9: Ammonia (net merchant) | B9: t NH3 | C9: 'Manual inputs'!34 | D9: =1*ef_nh3_fc -> 0.71247 | E9: =1*ef_nh3_fp -> 1.26225 | F9: =1*ef_nh3_np -> 0 | G9: =1*ef_nh3_no -> 0 | H9: =SUM(D9:G9) -> 1.97472 | I9: - | J9: =0 -> 0 | K9: =0 -> 0 | L9: =0 -> 0 | M9: =0 -> 0 | N9: =H9+SUM(J9:M9) -> 1.97472 | O9: 0.3927 | P9: 1.4586 | Q9: 0 | R9: 0 | S9: 0 | T9: =SUM(O9:S9) -> 1.8513 | U9: =H9-SUM(O9:R9) -> 0.12342 | V9: 2.05 | W9: =IF(V9>0,N9/V9,"") -> 0.96327805 | X9: 1.484
A10: Urea | B10: t urea | C10: 'Manual inputs'!35 | D10: =1*ef_urea_fc -> 0.1122 | E10: =1*ef_urea_fp -> 0 | F10: =1*ef_urea_np -> 0 | G10: =1*ef_urea_no -> 0 | H10: =SUM(D10:G10) -> 0.1122 | I10: Ammonia x urea_nh3_in | J10: =urea_nh3_in*ef_nh3_fc -> 0.4061079 | K10: =urea_nh3_in*ef_nh3_fp -> 0.7194825 | L10: =urea_nh3_in*ef_nh3_np -> 0 | M10: =urea_nh3_in*ef_nh3_no -> 0 | N10: =H10+SUM(J10:M10) -> 1.2377904 | O10: 0.1122 | P10: 0 | Q10: -0.733 | R10: 0 | S10: 1.0709496 | T10: =SUM(O10:S10) -> 0.4501496 | U10: =H10-SUM(O10:R10) -> 0.733 | V10: 1.39 | W10: =IF(V10>0,N10/V10,"") -> 0.89049669 | X10: 0.902
A11: Ammonium nitrate | B11: t AN | C11: 'Manual inputs'!36 | D11: =1*ef_an_fc -> 0.1122 | E11: =1*ef_an_fp -> 0 | F11: =1*ef_an_np -> 0 | G11: =1*ef_an_no -> 0 | H11: =SUM(D11:G11) -> 0.1122 | I11: Nitric acid x an_hno3_in; Ammonia (neutralisation) x an_nh3_in; Ammonia (via nitric acid) x an_hno3_in*nh3_per_hno3_st | J11: =an_hno3_in*ef_hno3_fc+an_nh3_in*ef_nh3_fc+an_hno3_in*nh3_per_hno3_st*ef_nh3_fc -> 0.30530954 | K11: =an_hno3_in*ef_hno3_fp+an_nh3_in*ef_nh3_fp+an_hno3_in*nh3_per_hno3_st*ef_nh3_fp -> 0.54090273 | L11: =an_hno3_in*ef_hno3_np+an_nh3_in*ef_nh3_np+an_hno3_in*nh3_per_hno3_st*ef_nh3_np -> 0 | M11: =an_hno3_in*ef_hno3_no+an_nh3_in*ef_nh3_no+an_hno3_in*nh3_per_hno3_st*ef_nh3_no -> 0.9944125 | N11: =H11+SUM(J11:M11) -> 1.9528248 | O11: 0.1122 | P11: 0 | Q11: 0 | R11: 0.97 | S11: 0.40137 | T11: =SUM(O11:S11) -> 1.48357 | U11: =H11-SUM(O11:R11) -> -0.97 | V11: 2.64 | W11: =IF(V11>0,N11/V11,"") -> 0.73970635 | X11: 0.302
A12: Primary aluminium | B12: t Al | C12: 'Manual inputs'!37 | D12: =1*ef_al_fc -> 0.12342 | E12: =1*ef_al_fp -> 0 | F12: =1*ef_al_np -> 1.623493 | G12: =1*ef_al_no -> 0.774 | H12: =SUM(D12:G12) -> 2.520913 | I12: - | J12: =0 -> 0 | K12: =0 -> 0 | L12: =0 -> 0 | M12: =0 -> 0 | N12: =H12+SUM(J12:M12) -> 2.520913 | O12: 0.156 | P12: 0 | Q12: 1.5 | R12: 0.85 | S12: 0 | T12: =SUM(O12:S12) -> 2.506 | U12: =H12-SUM(O12:R12) -> 0.014913045 | V12: 2.06 | W12: =IF(V12>0,N12/V12,"") -> 1.2237442 | X12: 1.423
A14: Chain total for urea / AN embeds the ammonia (and nitric acid) direct emissions, i.e. the CBAM 'embedded emissions incl. precursors' view. Own total is the plant-level view used by the kernel's H:K columns; the kernel carries the ammonia precursor separately in column M.

Sheet Summary
A1: Summary - Egypt direct emission factors for CBAM goods (tCO2e per t product)
A2: Own-process values (columns D:G) are the four kernel inputs ('Manual inputs' H:K). Chain total adds precursor emissions for urea and AN. Confidence: A plant data, B sector statistic, C calibrated technology default, D international default (lowest tier among the inputs that drive the value).
A4: Product | B4: Unit | C4: Route | D4: fc | E4: fp | F4: np | G4: no | H4: Total own | I4: Total chain | J4: Confidence | K4: Derivation in one line
A5: DRI-EAF steel | B5: t crude steel | C5: Midrex NG DRI + EAF | D5: =Products!D5 -> 0.17797725 | E5: =Products!E5 -> 0.39301352 | F5: =Products!F5 -> 0.037901015 | G5: =Products!G5 -> 0 | H5: =Products!H5 -> 0.60889178 | I5: =Products!N5 -> 0.60889178 | J5: C | K5: fp = 75% of DRI gas (reformer feed, 10.5 GJ/t DRI) x 56.1 kg/GJ incl. DRI carbon; fc = reformer burner gas + EAF gas; np = electrodes + charge carbon.
A6: Scrap-EAF steel | B6: t crude steel | C6: Scrap EAF | D6: =Products!D6 -> 0.04488 | E6: =Products!E6 -> 0 | F6: =Products!F6 -> 0.043981153 | G6: =Products!G6 -> 0 | H6: =Products!H6 -> 0.088861153 | I6: =Products!N6 -> 0.088861153 | J6: C | K6: fc = EAF natural gas; np = electrodes + charge carbon; no reductant.
A7: BF-BOF steel (reference) | B7: t crude steel | C7: BF-BOF, reference only | D7: =Products!D7 -> 0.1683 | E7: =Products!E7 -> 1.2566803 | F7: =Products!F7 -> 0.052765422 | G7: =Products!G7 -> 0 | H7: =Products!H7 -> 1.4777457 | I7: =Products!N7 -> 1.4777457 | J7: D | K7: fp = coke + PCI carbon net of hot-metal carbon; fc = purchased fuels; np = flux.
A8: Grey clinker (dry-process) | B8: t clinker | C8: Dry kiln, coal/petcoke | D8: =Products!D8 -> 0.3135685 | E8: =Products!E8 -> 0 | F8: =Products!F8 -> 0.53702616 | G8: =Products!G8 -> 0 | H8: =Products!H8 -> 0.85059466 | I8: =Products!N8 -> 0.85059466 | J8: C | K8: fc = 3.5 GJ/t x fuel-mix EF (coal 45%, petcoke 40%); np = CaO 65% x 0.785 + MgO x 1.092, x1.02 CKD.
A9: Ammonia (net merchant) | B9: t NH3 | C9: NG SMR + Haber-Bosch | D9: =Products!D9 -> 0.71247 | E9: =Products!E9 -> 1.26225 | F9: =Products!F9 -> 0 | G9: =Products!G9 -> 0 | H9: =Products!H9 -> 1.97472 | I9: =Products!N9 -> 1.97472 | J9: C | K9: fp = feedstock 22.5 GJ/t x 56.1; fc = fuel (35.2 - 22.5) GJ/t x 56.1.
A10: Urea | B10: t urea | C10: NH3 + CO2 synthesis | D10: =Products!D10 -> 0.1122 | E10: =Products!E10 -> 0 | F10: =Products!F10 -> 0 | G10: =Products!G10 -> 0 | H10: =Products!H10 -> 0.1122 | I10: =Products!N10 -> 1.2377904 | J10: C | K10: fc = steam fuel 2 GJ/t; np = 0 (CBAM) or -0.733 (IPCC netting); chain adds 0.57 t NH3.
A11: Ammonium nitrate | B11: t AN | C11: HNO3 + NH3 neutralisation | D11: =Products!D11 -> 0.1122 | E11: =Products!E11 -> 0 | F11: =Products!F11 -> 0 | G11: =Products!G11 -> 0 | H11: =Products!H11 -> 0.1122 | I11: =Products!N11 -> 1.9528248 | J11: C | K11: fc = 2 GJ/t finishing fuel; chain adds 0.79 t HNO3 (N2O: weighted 4.75 kg/t x GWP) and 0.43 t NH3.
A12: Primary aluminium | B12: t Al | C12: Prebake Hall-Heroult | D12: =Products!D12 -> 0.12342 | E12: =Products!E12 -> 0 | F12: =Products!F12 -> 1.623493 | G12: =Products!G12 -> 0.774 | H12: =Products!H12 -> 2.520913 | I12: =Products!N12 -> 2.520913 | J12: C | K12: np = 0.44 t anode x 97.6% C x 3.664 + baking; fc = 2.2 GJ/t gas; no = CF4 0.10 + C2F6 0.01 kg/t x GWP.
A14: Conventions in force: | C14: ="GWP set: "&gwp_set&"; urea bound CO2: "&urea_conv&"; reference year: "&ref_year -> GWP set: CBAM; urea bound CO2: CBAM; reference year: 2022
A15: Memo: cement | C15: =clk_cement_memo -> 0.72300546 | D15: ="tCO2/t cement at clinker ratio "&TEXT(clk_ratio,"0.00")&" (fc + np of clinker only)" -> tCO2/t cement at clinker ratio 0.85 (fc + np of clinker only)

Sheet Checks
A1: Checks
A2: All rows must read OK. Tolerance 1e-9 for balances.
A4: # | B4: Check | C4: Value | D4: Result | E4: Note
A5: 1 | B5: DRI carbon balance: fc + fp + retained - total = 0 | C5: =dri_check -> 0 | D5: =IF(ABS(C5)<0.000000001,"OK","FAIL") -> OK
A6: 2 | B6: Clinker fuel shares sum to 1 | C6: =clk_sh_coal+clk_sh_petcoke+clk_sh_ng+clk_sh_hfo+clk_sh_af -> 1 | D6: =IF(ABS(C6-1)<0.000000001,"OK","FAIL") -> OK
A7: 3 | B7: Ammonia feedstock <= total gas | C7: =nh3_ng_total-nh3_ng_feed -> 12.7 | D7: =IF(C7>=0,"OK","FAIL") -> OK | E7: fuel GJ/t
A8: 4 | B8: DRI feed share within [0,1] | C8: =dri_feed_share -> 0.75 | D8: =IF(AND(C8>=0,C8<=1),"OK","FAIL") -> OK
A9: 5 | B9: Settings: GWP set valid | C9: =gwp_set -> CBAM | D9: =IF(OR(C9="CBAM",C9="AR6"),"OK","FAIL") -> OK
A10: 6 | B10: Settings: urea convention valid | C10: =urea_conv -> CBAM | D10: =IF(OR(C10="CBAM",C10="IPCC"),"OK","FAIL") -> OK
A11: 7 | B11: Products: own total = sum of components (all rows) | C11: =SUMPRODUCT(ABS(Products!H5:H12-Products!D5:D12-Products!E5:E12-Products!F5:F12-Products!G5:G12)) -> 4.7878368e-16 | D11: =IF(C11<0.000000001,"OK","FAIL") -> OK
A12: 8 | B12: No negative component except urea np under IPCC netting | C12: =MIN(Products!D5:G12)+IF(urea_conv="IPCC",co2_per_urea,0) -> 0 | D12: =IF(C12>=-0.000000001,"OK","FAIL") -> OK
A13: 9 | B13: Ammonia own total within IPCC Table 3.1 band (modern 1.694 .. European average 2.104) | C13: =Products!H9 -> 1.97472 | D13: =IF(AND(C13>=ipcc_nh3_conv*0.95,C13<=ipcc_nh3_euavg*1.05),"OK","REVIEW") -> OK | E13: Range check, not a failure
A14: 10 | B14: Clinker np within 0.50-0.55 (IPCC Tier 1 0.52) | C14: =ef_clk_np -> 0.53702616 | D14: =IF(AND(C14>=0.5,C14<=0.55),"OK","REVIEW") -> OK
A15: 11 | B15: Aluminium np within 1.45-1.75 (IPCC Tier 1 1.6 + baking) | C15: =ef_al_np -> 1.623493 | D15: =IF(AND(C15>=1.45,C15<=1.75),"OK","REVIEW") -> OK
A16: 12 | B16: DRI total (fc+fp per t DRI, incl. retained C) vs IPCC Tier 1 0.70: ratio | C16: =dri_co2_total/ipcc_dri_t1 -> 0.8415 | D16: =IF(AND(C16>=0.7,C16<=1.1),"OK","REVIEW") -> OK | E16: IPCC Tier 1 is a global default
A17: 13 | B17: Own totals vs EU default base: ratio range (excl. BF-BOF reference) | C17: =MAX(Products!W5:W6,Products!W8:W12)&" max; "&MIN(Products!W5:W6,Products!W8:W12)&" min" -> 1.22374419646069 max; 0.123418268277227 min | D17: ="INFO" -> INFO | E17: Egypt own totals are expected below EU third-country defaults (which carry mark-ups).
A18: 14 | B18: Reconciliation memo: implied national direct emissions of the eight goods (MtCO2e, own process) | C18: =(prod_steel_dri*Products!H5+prod_steel_scrap*Products!H6+prod_clinker*Products!H8+prod_nh3*Products!H9+prod_urea*Products!H10+prod_an*Products!H11+prod_al*Products!H12)/1000 -> 50.724244 | D18: ="INFO" -> INFO | E18: Compare with Egypt's inventory (1A2 + 2A1 + 2B1 + 2B2 + 2C1 + 2C3) once BTR1 figures are entered.
B20: Overall | D20: =IF(COUNTIF(D5:D18,"FAIL")=0,"OK","FAIL") -> OK
